Workbook

Sheet Hoja1
A3: COD_FABRICANTE | B3: COD_MARCA | C3: MARCA | D3: SOCIEDAD | E3: CENTRO | F3: LOCALIDAD
A4: F0001 | B4: 060 | C4: DONG FENG (DFCV) | D4: MACO Tattersall | E4: VA00 | F4: Quilicura
E5: VA01 | F5: Calama
E6: VA02 | F6: Antofagasta
E7: VA03 | F7: Curico
E8: VA04 | F8: Talcahuano
E9: VA05 | F9: Temuco
E10: VA06 | F10: Puerto Montt
A11: F0006 | B11: 110 | C11: INTERNATIONAL | D11: MACO Tattersall | E11: VA00 | F11: Quilicura
E12: VA01 | F12: Calama
E13: VA02 | F13: Antofagasta
E14: VA03 | F14: Curico
E15: VA04 | F15: Talcahuano
E16: VA05 | F16: Temuco
E17: VA06 | F17: Puerto Montt
A18: F0010 | B18: 180 | C18: MAXIMAL | D18: Tattersall Industrial | E18: VE00 | F18: Antofagasta
F19: Calama
F20: Coquimbo
F21: Curico
F22: Osorno
F23: Puerto Montt
F24: Quilicura
F25: Talcahuano
D26: Tattersall Maquinarias | E26: VC00 | F26: Quilicura
E27: VC01 | F27: Calama
E28: VC02 | F28: Antofagasta
E29: VC03 | F29: Coquimbo
E30: VC04 | F30: Curico
E31: VC05 | F31: Talcahuano
E32: VC06 | F32: Puerto Montt
E33: VC07 | F33: Osorno
A34: F0012 | B34: 100 | C34: HYSTER | D34: Tattersall Maquinarias | E34: VC00 | F34: Quilicura
E35: VC01 | F35: Calama
E36: VC02 | F36: Antofagasta
E37: VC03 | F37: Coquimbo
E38: VC04 | F38: Curico
E39: VC05 | F39: Talcahuano
E40: VC06 | F40: Puerto Montt
E41: VC07 | F41: Osorno
A42: F0014 | B42: 090 | C42: HMK | D42: Tattersall Maquinarias | E42: VC00 | F42: Quilicura
...

Sheet cebe
A1: SOCIEDAD | B1: COD_SOCIEDAD | C1: AREA_LINEA_NEGOCIO | D1: LOCALIDAD | E1: CENTRO | F1: MARCA | G1: COD_MARCA | H1: COD_FABRICANTE | I1: COD_CEBE | J1: NOM_CODIGO_CEBE | K1: NOM_CORTO_CEBE
A2: Tattersall Automotriz | B2: =_xlfn.XLOOKUP(Tabla1[[#This Row],[SOCIEDAD]],centros!D:D,centros!E:E) -> VF00 | C2: Vta. Unidades Nuevas | D2: La Dehesa | E2: =IFERROR(INDEX(centros!$H$2:$H$45,MATCH(TRIM(Tabla1[[#This Row],[SOCIEDAD]])&"|"&TRIM(Tabla1[[#This Row],[LOCALIDAD]]),centros!$G$2:$G$45,0)),"REVISAR") -> VF07 | F2: LYNK CO | G2: =_xlfn.XLOOKUP(Tabla1[[#This Row],[MARCA]],MARCAS!E:E,MARCAS!F:F) -> 170 | H2: =_xlfn.XLOOKUP(Tabla1[[#This Row],[MARCA]],MARCAS!C:C,MARCAS!A:A) -> F0027 | I2: VFLN01DHLC | J2: Vta.Un/La Dehesa/LYNK CO | K2: VTAUND/DEHSA/LYNKO
A3: Tattersall Automotriz | B3: =_xlfn.XLOOKUP(Tabla1[[#This Row],[SOCIEDAD]],centros!D:D,centros!E:E) -> VF00 | C3: Vta. Unidades Nuevas | D3: Lira (motos) | E3: =IFERROR(INDEX(centros!$H$2:$H$45,MATCH(TRIM(Tabla1[[#This Row],[SOCIEDAD]])&"|"&TRIM(Tabla1[[#This Row],[LOCALIDAD]]),centros!$G$2:$G$45,0)),"REVISAR") -> VF03 | F3: LIFAN | G3: =_xlfn.XLOOKUP(Tabla1[[#This Row],[MARCA]],MARCAS!E:E,MARCAS!F:F) -> 140 | H3: =_xlfn.XLOOKUP(Tabla1[[#This Row],[MARCA]],MARCAS!C:C,MARCAS!A:A) -> F0021 | I3: VFLN01LILF | J3: Vta.Un/Lira (motos)/LIFAN | K3: VTAUND/LIRA/LIFAN
A4: Tattersall Automotriz | B4: =_xlfn.XLOOKUP(Tabla1[[#This Row],[SOCIEDAD]],centros!D:D,centros!E:E) -> VF00 | C4: Vta. Unidades Nuevas | D4: Lira (motos) | E4: =IFERROR(INDEX(centros!$H$2:$H$45,MATCH(TRIM(Tabla1[[#This Row],[SOCIEDAD]])&"|"&TRIM(Tabla1[[#This Row],[LOCALIDAD]]),centros!$G$2:$G$45,0)),"REVISAR") -> VF03 | F4: TODAS/OTRAS MARCAS | G4: =_xlfn.XLOOKUP(Tabla1[[#This Row],[MARCA]],MARCAS!E:E,MARCAS!F:F) -> 280 | H4: =_xlfn.XLOOKUP(Tabla1[[#This Row],[MARCA]],MARCAS!C:C,MARCAS!A:A) -> F9999 | I4: VFLN01LIOO | J4: Vta.Un/Lira (motos)/TODAS/OTRAS MARCAS | K4: VTAUND/LIRA/TODAS
A5: Tattersall Automotriz | B5: =_xlfn.XLOOKUP(Tabla1[[#This Row],[SOCIEDAD]],centros!D:D,centros!E:E) -> VF00 | C5: Vta. Unidades Nuevas | D5: Movicenter LynkCo | E5: =IFERROR(INDEX(centros!$H$2:$H$45,MATCH(TRIM(Tabla1[[#This Row],[SOCIEDAD]])&"|"&TRIM(Tabla1[[#This Row],[LOCALIDAD]]),centros!$G$2:$G$45,0)),"REVISAR") -> VF01 | F5: LYNK CO | G5: =_xlfn.XLOOKUP(Tabla1[[#This Row],[MARCA]],MARCAS!E:E,MARCAS!F:F) -> 170 | H5: =_xlfn.XLOOKUP(Tabla1[[#This Row],[MARCA]],MARCAS!C:C,MARCAS!A:A) -> F0027 | I5: VFLN01M1LC | J5: Vta.Un/Movicenter LynkCo/LYNK CO | K5: VTAUND/MOV.L&C/LYNKO
A6: Tattersall Automotriz | B6: =_xlfn.XLOOKUP(Tabla1[[#This Row],[SOCIEDAD]],centros!D:D,centros!E:E) -> VF00 | C6: Vta. Unidades Nuevas | D6: Movicenter Multimarca | E6: =IFERROR(INDEX(centros!$H$2:$H$45,MATCH(TRIM(Tabla1[[#This Row],[SOCIEDAD]])&"|"&TRIM(Tabla1[[#This Row],[LOCALIDAD]]),centros!$G$2:$G$45,0)),"REVISAR") -> VF01 | F6: DONG FENG (DFAC) | G6: =_xlfn.XLOOKUP(Tabla1[[#This Row],[MARCA]],MARCAS!E:E,MARCAS!F:F) -> 060 | H6: =_xlfn.XLOOKUP(Tabla1[[#This Row],[MARCA]],MARCAS!C:C,MARCAS!A:A) -> F0022 | I6: VFLN01M0DC | J6: Vta.Un/Movictr Multimrc/DONG FENG (DFAC) | K6: VTAUND/MOV.MM/DFAC
A7: Tattersall Automotriz | B7: =_xlfn.XLOOKUP(Tabla1[[#This Row],[SOCIEDAD]],centros!D:D,centros!E:E) -> VF00 | C7: Vta. Unidades Nuevas | D7: Movicenter Multimarca | E7: =IFERROR(INDEX(centros!$H$2:$H$45,MATCH(TRIM(Tabla1[[#This Row],[SOCIEDAD]])&"|"&TRIM(Tabla1[[#This Row],[LOCALIDAD]]),centros!$G$2:$G$45,0)),"REVISAR") -> VF01 | F7: FAW | G7: =_xlfn.XLOOKUP(Tabla1[[#This Row],[MARCA]],MARCAS!E:E,MARCAS!F:F) -> 080 | H7: =_xlfn.XLOOKUP(Tabla1[[#This Row],[MARCA]],MARCAS!C:C,MARCAS!A:A) -> F0028 | I7: VFLN01M0FW | J7: Vta.Un/Movicenter Multimarca/FAW | K7: VTAUND/MOV.MM/FAW
A8: Tattersall Automotriz | B8: =_xlfn.XLOOKUP(Tabla1[[#This Row],[SOCIEDAD]],centros!D:D,centros!E:E) -> VF00 | C8: Vta. Unidades Nuevas | D8: Movicenter Multimarca | E8: =IFERROR(INDEX(centros!$H$2:$H$45,MATCH(TRIM(Tabla1[[#This Row],[SOCIEDAD]])&"|"&TRIM(Tabla1[[#This Row],[LOCALIDAD]]),centros!$G$2:$G$45,0)),"REVISAR") -> VF01 | F8: KYC | G8: =_xlfn.XLOOKUP(Tabla1[[#This Row],[MARCA]],MARCAS!E:E,MARCAS!F:F) -> 130 | H8: =_xlfn.XLOOKUP(Tabla1[[#This Row],[MARCA]],MARCAS!C:C,MARCAS!A:A) -> F0019 | I8: VFLN01M0KC | J8: Vta.Un/Movicenter Multimarca/KYC | K8: VTAUND/MOV.MM/KYC
A9: Tattersall Automotriz | B9: =_xlfn.XLOOKUP(Tabla1[[#This Row],[SOCIEDAD]],centros!D:D,centros!E:E) -> VF00 | C9: Vta. Unidades Nuevas | D9: Movicenter Multimarca | E9: =IFERROR(INDEX(centros!$H$2:$H$45,MATCH(TRIM(Tabla1[[#This Row],[SOCIEDAD]])&"|"&TRIM(Tabla1[[#This Row],[LOCALIDAD]]),centros!$G$2:$G$45,0)),"REVISAR") -> VF01 | F9: LIVAN | G9: =_xlfn.XLOOKUP(Tabla1[[#This Row],[MARCA]],MARCAS!E:E,MARCAS!F:F) -> 160 | H9: =_xlfn.XLOOKUP(Tabla1[[#This Row],[MARCA]],MARCAS!C:C,MARCAS!A:A) -> F0023 | I9: VFLN01M0LV | J9: Vta.Un/Movicenter Multimarca/LIVAN | K9: VTAUND/MOV.MM/LIVAN
A10: Tattersall Automotriz | B10: =_xlfn.XLOOKUP(Tabla1[[#This Row],[SOCIEDAD]],centros!D:D,centros!E:E) -> VF00 | C10: Vta. Unidades Nuevas | D10: Movicenter Multimarca | E10: =IFERROR(INDEX(centros!$H$2:$H$45,MATCH(TRIM(Tabla1[[#This Row],[SOCIEDAD]])&"|"&TRIM(Tabla1[[#This Row],[LOCALIDAD]]),centros!$G$2:$G$45,0)),"REVISAR") -> VF01 | F10: TODAS/OTRAS MARCAS | G10: =_xlfn.XLOOKUP(Tabla1[[#This Row],[MARCA]],MARCAS!E:E,MARCAS!F:F) -> 280 | H10: =_xlfn.XLOOKUP(Tabla1[[#This Row],[MARCA]],MARCAS!C:C,MARCAS!A:A) -> F9999 | I10: VFLN01M0OO | J10: Vta.Un/Movictr Multimrc/TODASOTRAS MRCAS | K10: VTAUND/MOV.MM/TODAS
A11: Tattersall Automotriz | B11: =_xlfn.XLOOKUP(Tabla1[[#This Row],[SOCIEDAD]],centros!D:D,centros!E:E) -> VF00 | C11: Vta. Unidades Nuevas | D11: Movicenter Multimarca | E11: =IFERROR(INDEX(centros!$H$2:$H$45,MATCH(TRIM(Tabla1[[#This Row],[SOCIEDAD]])&"|"&TRIM(Tabla1[[#This Row],[LOCALIDAD]]),centros!$G$2:$G$45,0)),"REVISAR") -> VF01 | F11: ZXAUTO | G11: =_xlfn.XLOOKUP(Tabla1[[#This Row],[MARCA]],MARCAS!E:E,MARCAS!F:F) -> 260 | H11: =_xlfn.XLOOKUP(Tabla1[[#This Row],[MARCA]],MARCAS!C:C,MARCAS!A:A) -> F0020 | I11: VFLN01M0ZX | J11: Vta.Un/Movicenter Multimarca/ZXAUTO | K11: VTAUND/MOV.MM/ZXAUTO
A12: Tattersall Automotriz | B12: =_xlfn.XLOOKUP(Tabla1[[#This Row],[SOCIEDAD]],centros!D:D,centros!E:E) -> VF00 | C12: Vta. Unidades Nuevas | D12: Operador Logístico | E12: =IFERROR(INDEX(centros!$H$2:$H$45,MATCH(TRIM(Tabla1[[#This Row],[SOCIEDAD]])&"|"&TRIM(Tabla1[[#This Row],[LOCALIDAD]]),centros!$G$2:$G$45,0)),"REVISAR") -> VF04 | F12: DONG FENG (DFAC) | G12: =_xlfn.XLOOKUP(Tabla1[[#This Row],[MARCA]],MARCAS!E:E,MARCAS!F:F) -> 060 | H12: =_xlfn.XLOOKUP(Tabla1[[#This Row],[MARCA]],MARCAS!C:C,MARCAS!A:A) -> F0022 | I12: VFLN01OLDC | J12: Vta.Un/Op. Logístico/DONG FENG (DFAC) | K12: VTAUND/OP.LOG/DFAC
A13: Tattersall Automotriz | B13: =_xlfn.XLOOKUP(Tabla1[[#This Row],[SOCIEDAD]],centros!D:D,centros!E:E) -> VF00 | C13: Vta. Unidades Nuevas | D13: Operador Logístico | E13: =IFERROR(INDEX(centros!$H$2:$H$45,MATCH(TRIM(Tabla1[[#This Row],[SOCIEDAD]])&"|"&TRIM(Tabla1[[#This Row],[LOCALIDAD]]),centros!$G$2:$G$45,0)),"REVISAR") -> VF04 | F13: FAW | G13: =_xlfn.XLOOKUP(Tabla1[[#This Row],[MARCA]],MARCAS!E:E,MARCAS!F:F) -> 080 | H13: =_xlfn.XLOOKUP(Tabla1[[#This Row],[MARCA]],MARCAS!C:C,MARCAS!A:A) -> F0028 | I13: VFLN01OLFW | J13: Vta.Un/Operador Logístico/FAW | K13: VTAUND/OP.LOG/FAW
A14: Tattersall Automotriz | B14: =_xlfn.XLOOKUP(Tabla1[[#This Row],[SOCIEDAD]],centros!D:D,centros!E:E) -> VF00 | C14: Vta. Unidades Nuevas | D14: Operador Logístico | E14: =IFERROR(INDEX(centros!$H$2:$H$45,MATCH(TRIM(Tabla1[[#This Row],[SOCIEDAD]])&"|"&TRIM(Tabla1[[#This Row],[LOCALIDAD]]),centros!$G$2:$G$45,0)),"REVISAR") -> VF04 | F14: JETOUR | G14: =_xlfn.XLOOKUP(Tabla1[[#This Row],[MARCA]],MARCAS!E:E,MARCAS!F:F) -> 120 | H14: F0029 | I14: VFLN01OLJT | J14: Vta.Un/Operador Logístico/JETOUR | K14: VTAUND/OP.LOG/JETOUR
A15: Tattersall Automotriz | B15: =_xlfn.XLOOKUP(Tabla1[[#This Row],[SOCIEDAD]],centros!D:D,centros!E:E) -> VF00 | C15: Vta. Unidades Nuevas | D15: Operador Logístico | E15: =IFERROR(INDEX(centros!$H$2:$H$45,MATCH(TRIM(Tabla1[[#This Row],[SOCIEDAD]])&"|"&TRIM(Tabla1[[#This Row],[LOCALIDAD]]),centros!$G$2:$G$45,0)),"REVISAR") -> VF04 | F15: KYC | G15: =_xlfn.XLOOKUP(Tabla1[[#This Row],[MARCA]],MARCAS!E:E,MARCAS!F:F) -> 130 | H15: =_xlfn.XLOOKUP(Tabla1[[#This Row],[MARCA]],MARCAS!C:C,MARCAS!A:A) -> F0019 | I15: VFLN01OLKC | J15: Vta.Un/Operador Logístico/KYC | K15: VTAUND/OP.LOG/KYC
A16: Tattersall Automotriz | B16: =_xlfn.XLOOKUP(Tabla1[[#This Row],[SOCIEDAD]],centros!D:D,centros!E:E) -> VF00 | C16: Vta. Unidades Nuevas | D16: Operador Logístico | E16: =IFERROR(INDEX(centros!$H$2:$H$45,MATCH(TRIM(Tabla1[[#This Row],[SOCIEDAD]])&"|"&TRIM(Tabla1[[#This Row],[LOCALIDAD]]),centros!$G$2:$G$45,0)),"REVISAR") -> VF04 | F16: LIFAN | G16: =_xlfn.XLOOKUP(Tabla1[[#This Row],[MARCA]],MARCAS!E:E,MARCAS!F:F) -> 140 | H16: =_xlfn.XLOOKUP(Tabla1[[#This Row],[MARCA]],MARCAS!C:C,MARCAS!A:A) -> F0021 | I16: VFLN01OLLF | J16: Vta.Un/Operador Logístico/LIFAN | K16: VTAUND/OP.LOG/LIFAN
A17: Tattersall Automotriz | B17: =_xlfn.XLOOKUP(Tabla1[[#This Row],[SOCIEDAD]],centros!D:D,centros!E:E) -> VF00 | C17: Vta. Unidades Nuevas | D17: Operador Logístico | E17: =IFERROR(INDEX(centros!$H$2:$H$45,MATCH(TRIM(Tabla1[[#This Row],[SOCIEDAD]])&"|"&TRIM(Tabla1[[#This Row],[LOCALIDAD]]),centros!$G$2:$G$45,0)),"REVISAR") -> VF04 | F17: LIVAN | G17: =_xlfn.XLOOKUP(Tabla1[[#This Row],[MARCA]],MARCAS!E:E,MARCAS!F:F) -> 160 | H17: =_xlfn.XLOOKUP(Tabla1[[#This Row],[MARCA]],MARCAS!C:C,MARCAS!A:A) -> F0023 | I17: VFLN01OLLV | J17: Vta.Un/Operador Logístico/LIVAN | K17: VTAUND/OP.LOG/LIVAN
A18: Tattersall Automotriz | B18: =_xlfn.XLOOKUP(Tabla1[[#This Row],[SOCIEDAD]],centros!D:D,centros!E:E) -> VF00 | C18: Vta. Unidades Nuevas | D18: Operador Logístico | E18: =IFERROR(INDEX(centros!$H$2:$H$45,MATCH(TRIM(Tabla1[[#This Row],[SOCIEDAD]])&"|"&TRIM(Tabla1[[#This Row],[LOCALIDAD]]),centros!$G$2:$G$45,0)),"REVISAR") -> VF04 | F18: LYNK CO | G18: =_xlfn.XLOOKUP(Tabla1[[#This Row],[MARCA]],MARCAS!E:E,MARCAS!F:F) -> 170 | H18: =_xlfn.XLOOKUP(Tabla1[[#This Row],[MARCA]],MARCAS!C:C,MARCAS!A:A) -> F0027 | I18: VFLN01OLLC | J18: Vta.Un/Operador Logístico/LYNK CO | K18: VTAUND/OP.LOG/LYNKO
A19: Tattersall Automotriz | B19: =_xlfn.XLOOKUP(Tabla1[[#This Row],[SOCIEDAD]],centros!D:D,centros!E:E) -> VF00 | C19: Vta. Unidades Nuevas | D19: Operador Logístico | E19: =IFERROR(INDEX(centros!$H$2:$H$45,MATCH(TRIM(Tabla1[[#This Row],[SOCIEDAD]])&"|"&TRIM(Tabla1[[#This Row],[LOCALIDAD]]),centros!$G$2:$G$45,0)),"REVISAR") -> VF04 | F19: TODAS/OTRAS MARCAS | G19: =_xlfn.XLOOKUP(Tabla1[[#This Row],[MARCA]],MARCAS!E:E,MARCAS!F:F) -> 280 | H19: =_xlfn.XLOOKUP(Tabla1[[#This Row],[MARCA]],MARCAS!C:C,MARCAS!A:A) -> F9999 | I19: VFLN01OLOO | J19: Vta.Un/Op. Logístico/TODAS/OTRAS MARCAS | K19: VTAUND/OP.LOG/TODAS
A20: Tattersall Automotriz | B20: =_xlfn.XLOOKUP(Tabla1[[#This Row],[SOCIEDAD]],centros!D:D,centros!E:E) -> VF00 | C20: Vta. Unidades Nuevas | D20: Operador Logístico | E20: =IFERROR(INDEX(centros!$H$2:$H$45,MATCH(TRIM(Tabla1[[#This Row],[SOCIEDAD]])&"|"&TRIM(Tabla1[[#This Row],[LOCALIDAD]]),centros!$G$2:$G$45,0)),"REVISAR") -> VF04 | F20: ZXAUTO | G20: =_xlfn.XLOOKUP(Tabla1[[#This Row],[MARCA]],MARCAS!E:E,MARCAS!F:F) -> 260 | H20: =_xlfn.XLOOKUP(Tabla1[[#This Row],[MARCA]],MARCAS!C:C,MARCAS!A:A) -> F0020 | I20: VFLN01OLZX | J20: Vta.Un/Operador Logístico/ZXAUTO | K20: VTAUND/OP.LOG/ZXAUTO
A21: Tattersall Automotriz | B21: =_xlfn.XLOOKUP(Tabla1[[#This Row],[SOCIEDAD]],centros!D:D,centros!E:E) -> VF00 | C21: Vta. Unidades Nuevas | D21: Plaza Oeste | E21: =IFERROR(INDEX(centros!$H$2:$H$45,MATCH(TRIM(Tabla1[[#This Row],[SOCIEDAD]])&"|"&TRIM(Tabla1[[#This Row],[LOCALIDAD]]),centros!$G$2:$G$45,0)),"REVISAR") -> VF06 | F21: DONG FENG (DFAC) | G21: =_xlfn.XLOOKUP(Tabla1[[#This Row],[MARCA]],MARCAS!E:E,MARCAS!F:F) -> 060 | H21: =_xlfn.XLOOKUP(Tabla1[[#This Row],[MARCA]],MARCAS!C:C,MARCAS!A:A) -> F0022 | I21: VFLN01PODC | J21: Vta.Un/Plaza Oeste/DONG FENG (DFAC) | K21: VTAUND/POESTE/DFAC
A22: Tattersall Automotriz | B22: =_xlfn.XLOOKUP(Tabla1[[#This Row],[SOCIEDAD]],centros!D:D,centros!E:E) -> VF00 | C22: Vta. Unidades Nuevas | D22: Plaza Oeste | E22: =IFERROR(INDEX(centros!$H$2:$H$45,MATCH(TRIM(Tabla1[[#This Row],[SOCIEDAD]])&"|"&TRIM(Tabla1[[#This Row],[LOCALIDAD]]),centros!$G$2:$G$45,0)),"REVISAR") -> VF06 | F22: FAW | G22: =_xlfn.XLOOKUP(Tabla1[[#This Row],[MARCA]],MARCAS!E:E,MARCAS!F:F) -> 080 | H22: =_xlfn.XLOOKUP(Tabla1[[#This Row],[MARCA]],MARCAS!C:C,MARCAS!A:A) -> F0028 | I22: VFLN01POFW | J22: Vta.Un/Plaza Oeste/FAW | K22: VTAUND/POESTE/FAW
A23: Tattersall Automotriz | B23: =_xlfn.XLOOKUP(Tabla1[[#This Row],[SOCIEDAD]],centros!D:D,centros!E:E) -> VF00 | C23: Vta. Unidades Nuevas | D23: Plaza Oeste | E23: =IFERROR(INDEX(centros!$H$2:$H$45,MATCH(TRIM(Tabla1[[#This Row],[SOCIEDAD]])&"|"&TRIM(Tabla1[[#This Row],[LOCALIDAD]]),centros!$G$2:$G$45,0)),"REVISAR") -> VF06 | F23: KYC | G23: =_xlfn.XLOOKUP(Tabla1[[#This Row],[MARCA]],MARCAS!E:E,MARCAS!F:F) -> 130 | H23: =_xlfn.XLOOKUP(Tabla1[[#This Row],[MARCA]],MARCAS!C:C,MARCAS!A:A) -> F0019 | I23: VFLN01POKC | J23: Vta.Un/Plaza Oeste/KYC | K23: VTAUND/POESTE/KYC
A24: Tattersall Automotriz | B24: =_xlfn.XLOOKUP(Tabla1[[#This Row],[SOCIEDAD]],centros!D:D,centros!E:E) -> VF00 | C24: Vta. Unidades Nuevas | D24: Plaza Oeste | E24: =IFERROR(INDEX(centros!$H$2:$H$45,MATCH(TRIM(Tabla1[[#This Row],[SOCIEDAD]])&"|"&TRIM(Tabla1[[#This Row],[LOCALIDAD]]),centros!$G$2:$G$45,0)),"REVISAR") -> VF06 | F24: LIVAN | G24: =_xlfn.XLOOKUP(Tabla1[[#This Row],[MARCA]],MARCAS!E:E,MARCAS!F:F) -> 160 | H24: =_xlfn.XLOOKUP(Tabla1[[#This Row],[MARCA]],MARCAS!C:C,MARCAS!A:A) -> F0023 | I24: VFLN01POLV | J24: Vta.Un/Plaza Oeste/LIVAN | K24: VTAUND/POESTE/LIVAN
A25: Tattersall Automotriz | B25: =_xlfn.XLOOKUP(Tabla1[[#This Row],[SOCIEDAD]],centros!D:D,centros!E:E) -> VF00 | C25: Vta. Unidades Nuevas | D25: Plaza Oeste | E25: =IFERROR(INDEX(centros!$H$2:$H$45,MATCH(TRIM(Tabla1[[#This Row],[SOCIEDAD]])&"|"&TRIM(Tabla1[[#This Row],[LOCALIDAD]]),centros!$G$2:$G$45,0)),"REVISAR") -> VF06 | F25: LYNK CO | G25: =_xlfn.XLOOKUP(Tabla1[[#This Row],[MARCA]],MARCAS!E:E,MARCAS!F:F) -> 170 | H25: =_xlfn.XLOOKUP(Tabla1[[#This Row],[MARCA]],MARCAS!C:C,MARCAS!A:A) -> F0027 | I25: VFLN01POLC | J25: Vta.Un/Plaza Oeste/LYNK CO | K25: VTAUND/POESTE/LYNKO
A26: Tattersall Automotriz | B26: =_xlfn.XLOOKUP(Tabla1[[#This Row],[SOCIEDAD]],centros!D:D,centros!E:E) -> VF00 | C26: Vta. Unidades Nuevas | D26: Plaza Oeste | E26: =IFERROR(INDEX(centros!$H$2:$H$45,MATCH(TRIM(Tabla1[[#This Row],[SOCIEDAD]])&"|"&TRIM(Tabla1[[#This Row],[LOCALIDAD]]),centros!$G$2:$G$45,0)),"REVISAR") -> VF06 | F26: TODAS/OTRAS MARCAS | G26: =_xlfn.XLOOKUP(Tabla1[[#This Row],[MARCA]],MARCAS!E:E,MARCAS!F:F) -> 280 | H26: =_xlfn.XLOOKUP(Tabla1[[#This Row],[MARCA]],MARCAS!C:C,MARCAS!A:A) -> F9999 | I26: VFLN01POOO | J26: Vta.Un/Plaza Oeste/TODAS/OTRAS MARCAS | K26: VTAUND/POESTE/TODAS
... A39: Tattersall Automotriz | B39: =_xlfn.XLOOKUP(Tabla1[[#This Row],[SOCIEDAD]],centros!D:D,centros!E:E) -> VF00 | C39: Vta. Electromovilidad Unidades Nuevas | D39: Movicenter Multimarca | E39: =IFERROR(INDEX(centros!$H$2:$H$45,MATCH(TRIM(Tabla1[[#This Row],[SOCIEDAD]])&"|"&TRIM(Tabla1[[#This Row],[LOCALIDAD]]),centros!$G$2:$G$45,0)),"REVISAR") -> VF01 | F39: LIVAN | G39: =_xlfn.XLOOKUP(Tabla1[[#This Row],[MARCA]],MARCAS!E:E,MARCAS!F:F) -> 160 | H39: =_xlfn.XLOOKUP(Tabla1[[#This Row],[MARCA]],MARCAS!C:C,MARCAS!A:A) -> F0023 | I39: VFLN02M0LV | J39: Electromov/Movicenter Multimarca/LIVAN | K39: ELECTM/MOV.MM/LIVAN
A40: Tattersall Automotriz | B40: =_xlfn.XLOOKUP(Tabla1[[#This Row],[SOCIEDAD]],centros!D:D,centros!E:E) -> VF00 | C40: Vta. Electromovilidad Unidades Nuevas | D40: Movicenter Multimarca | E40: =IFERROR(INDEX(centros!$H$2:$H$45,MATCH(TRIM(Tabla1[[#This Row],[SOCIEDAD]])&"|"&TRIM(Tabla1[[#This Row],[LOCALIDAD]]),centros!$G$2:$G$45,0)),"REVISAR") -> VF01 | F40: RIDDARA | G40: =_xlfn.XLOOKUP(Tabla1[[#This Row],[MARCA]],MARCAS!E:E,MARCAS!F:F) -> 220 | H40: F0025 | I40: VFLN02M0RD | J40: Electromov/Movicenter Multimarca/RIDDARA | K40: ELECTM/MOV.MM/RIDDA
A41: Tattersall Automotriz | B41: =_xlfn.XLOOKUP(Tabla1[[#This Row],[SOCIEDAD]],centros!D:D,centros!E:E) -> VF00 | C41: Vta. Electromovilidad Unidades Nuevas | D41: Operador Logístico | E41: =IFERROR(INDEX(centros!$H$2:$H$45,MATCH(TRIM(Tabla1[[#This Row],[SOCIEDAD]])&"|"&TRIM(Tabla1[[#This Row],[LOCALIDAD]]),centros!$G$2:$G$45,0)),"REVISAR") -> VF04 | F41: LIVAN | G41: =_xlfn.XLOOKUP(Tabla1[[#This Row],[MARCA]],MARCAS!E:E,MARCAS!F:F) -> 160 | H41: =_xlfn.XLOOKUP(Tabla1[[#This Row],[MARCA]],MARCAS!C:C,MARCAS!A:A) -> F0023 | I41: VFLN02OLLV | J41: Electromov/Operador Logístico/LIVAN | K41: ELECTM/OP.LOG/LIVAN
A42: Tattersall Automotriz | B42: =_xlfn.XLOOKUP(Tabla1[[#This Row],[SOCIEDAD]],centros!D:D,centros!E:E) -> VF00 | C42: Vta. Electromovilidad Unidades Nuevas | D42: Operador Logístico | E42: =IFERROR(INDEX(centros!$H$2:$H$45,MATCH(TRIM(Tabla1[[#This Row],[SOCIEDAD]])&"|"&TRIM(Tabla1[[#This Row],[LOCALIDAD]]),centros!$G$2:$G$45,0)),"REVISAR") -> VF04 | F42: LYNK CO | G42: =_xlfn.XLOOKUP(Tabla1[[#This Row],[MARCA]],MARCAS!E:E,MARCAS!F:F) -> 170 | H42: =_xlfn.XLOOKUP(Tabla1[[#This Row],[MARCA]],MARCAS!C:C,MARCAS!A:A) -> F0027 | I42: VFLN02OLLC | J42: Electromov/Operador Logístico/LYNK CO | K42: ELECTM/OP.LOG/LYNKO
A43: Tattersall Automotriz | B43: =_xlfn.XLOOKUP(Tabla1[[#This Row],[SOCIEDAD]],centros!D:D,centros!E:E) -> VF00 | C43: Vta. Electromovilidad Unidades Nuevas | D43: Operador Logístico | E43: =IFERROR(INDEX(centros!$H$2:$H$45,MATCH(TRIM(Tabla1[[#This Row],[SOCIEDAD]])&"|"&TRIM(Tabla1[[#This Row],[LOCALIDAD]]),centros!$G$2:$G$45,0)),"REVISAR") -> VF04 | F43: RIDDARA | G43: =_xlfn.XLOOKUP(Tabla1[[#This Row],[MARCA]],MARCAS!E:E,MARCAS!F:F) -> 220 | H43: F0025 | I43: VFLN02OLRD | J43: Electromov/Operador Logístico/RIDDARA | K43: ELECTM/OP.LOG/RIDDA
A44: Tattersall Automotriz | B44: =_xlfn.XLOOKUP(Tabla1[[#This Row],[SOCIEDAD]],centros!D:D,centros!E:E) -> VF00 | C44: Vta. Electromovilidad Unidades Nuevas | D44: Plaza Oeste | E44: =IFERROR(INDEX(centros!$H$2:$H$45,MATCH(TRIM(Tabla1[[#This Row],[SOCIEDAD]])&"|"&TRIM(Tabla1[[#This Row],[LOCALIDAD]]),centros!$G$2:$G$45,0)),"REVISAR") -> VF06 | F44: LIVAN | G44: =_xlfn.XLOOKUP(Tabla1[[#This Row],[MARCA]],MARCAS!E:E,MARCAS!F:F) -> 160 | H44: =_xlfn.XLOOKUP(Tabla1[[#This Row],[MARCA]],MARCAS!C:C,MARCAS!A:A) -> F0023 | I44: VFLN02POLV | J44: Electromovilidad/Plaza Oeste/LIVAN | K44: ELECTM/POESTE/LIVAN
A45: Tattersall Automotriz | B45: =_xlfn.XLOOKUP(Tabla1[[#This Row],[SOCIEDAD]],centros!D:D,centros!E:E) -> VF00 | C45: Vta. Electromovilidad Unidades Nuevas | D45: Plaza Oeste | E45: =IFERROR(INDEX(centros!$H$2:$H$45,MATCH(TRIM(Tabla1[[#This Row],[SOCIEDAD]])&"|"&TRIM(Tabla1[[#This Row],[LOCALIDAD]]),centros!$G$2:$G$45,0)),"REVISAR") -> VF06 | F45: LYNK CO | G45: =_xlfn.XLOOKUP(Tabla1[[#This Row],[MARCA]],MARCAS!E:E,MARCAS!F:F) -> 170 | H45: =_xlfn.XLOOKUP(Tabla1[[#This Row],[MARCA]],MARCAS!C:C,MARCAS!A:A) -> F0027 | I45: VFLN02POLC | J45: Electromovilidad/Plaza Oeste/LYNK CO | K45: ELECTM/POESTE/LYNKO
A46: Tattersall Automotriz | B46: =_xlfn.XLOOKUP(Tabla1[[#This Row],[SOCIEDAD]],centros!D:D,centros!E:E) -> VF00 | C46: Vta. Electromovilidad Unidades Nuevas | D46: Plaza Oeste | E46: =IFERROR(INDEX(centros!$H$2:$H$45,MATCH(TRIM(Tabla1[[#This Row],[SOCIEDAD]])&"|"&TRIM(Tabla1[[#This Row],[LOCALIDAD]]),centros!$G$2:$G$45,0)),"REVISAR") -> VF06 | F46: RIDDARA | G46: =_xlfn.XLOOKUP(Tabla1[[#This Row],[MARCA]],MARCAS!E:E,MARCAS!F:F) -> 220 | H46: F0025 | I46: VFLN02PORD | J46: Electromovilidad/Plaza Oeste/RIDDARA | K46: ELECTM/POESTE/RIDDA
A47: Tattersall Automotriz | B47: =_xlfn.XLOOKUP(Tabla1[[#This Row],[SOCIEDAD]],centros!D:D,centros!E:E) -> VF00 | C47: Vta. Electromovilidad Unidades Nuevas | D47: Quilicura | E47: =IFERROR(INDEX(centros!$H$2:$H$45,MATCH(TRIM(Tabla1[[#This Row],[SOCIEDAD]])&"|"&TRIM(Tabla1[[#This Row],[LOCALIDAD]]),centros!$G$2:$G$45,0)),"REVISAR") -> VF00 | F47: LIVAN | G47: =_xlfn.XLOOKUP(Tabla1[[#This Row],[MARCA]],MARCAS!E:E,MARCAS!F:F) -> 160 | H47: =_xlfn.XLOOKUP(Tabla1[[#This Row],[MARCA]],MARCAS!C:C,MARCAS!A:A) -> F0023 | I47: VFLN02QCLV | J47: Electromovilidad/Quilicura/LIVAN | K47: ELECTM/QUILI/LIVAN
A48: Tattersall Automotriz | B48: =_xlfn.XLOOKUP(Tabla1[[#This Row],[SOCIEDAD]],centros!D:D,centros!E:E) -> VF00 | C48: Vta. Electromovilidad Unidades Nuevas | D48: Quilicura | E48: =IFERROR(INDEX(centros!$H$2:$H$45,MATCH(TRIM(Tabla1[[#This Row],[SOCIEDAD]])&"|"&TRIM(Tabla1[[#This Row],[LOCALIDAD]]),centros!$G$2:$G$45,0)),"REVISAR") -> VF00 | F48: LYNK CO | G48: =_xlfn.XLOOKUP(Tabla1[[#This Row],[MARCA]],MARCAS!E:E,MARCAS!F:F) -> 170 | H48: =_xlfn.XLOOKUP(Tabla1[[#This Row],[MARCA]],MARCAS!C:C,MARCAS!A:A) -> F0027 | I48: VFLN02QCLC | J48: Electromovilidad/Quilicura/LYNK CO | K48: ELECTM/QUILI/LYNKO
A49: Tattersall Automotriz | B49: =_xlfn.XLOOKUP(Tabla1[[#This Row],[SOCIEDAD]],centros!D:D,centros!E:E) -> VF00 | C49: Vta. Electromovilidad Unidades Nuevas | D49: Quilicura | E49: =IFERROR(INDEX(centros!$H$2:$H$45,MATCH(TRIM(Tabla1[[#This Row],[SOCIEDAD]])&"|"&TRIM(Tabla1[[#This Row],[LOCALIDAD]]),centros!$G$2:$G$45,0)),"REVISAR") -> VF00 | F49: RIDDARA | G49: =_xlfn.XLOOKUP(Tabla1[[#This Row],[MARCA]],MARCAS!E:E,MARCAS!F:F) -> 220 | H49: F0025 | I49: VFLN02QCRD | J49: Electromovilidad/Quilicura/RIDDARA | K49: ELECTM/QUILI/RIDDA
A50: Tattersall Automotriz | B50: =_xlfn.XLOOKUP(Tabla1[[#This Row],[SOCIEDAD]],centros!D:D,centros!E:E) -> VF00 | C50: Vta. Electromovilidad Unidades Nuevas | D50: Vitacura | E50: =IFERROR(INDEX(centros!$H$2:$H$45,MATCH(TRIM(Tabla1[[#This Row],[SOCIEDAD]])&"|"&TRIM(Tabla1[[#This Row],[LOCALIDAD]]),centros!$G$2:$G$45,0)),"REVISAR") -> VF05 | F50: LYNK CO | G50: =_xlfn.XLOOKUP(Tabla1[[#This Row],[MARCA]],MARCAS!E:E,MARCAS!F:F) -> 170 | H50: =_xlfn.XLOOKUP(Tabla1[[#This Row],[MARCA]],MARCAS!C:C,MARCAS!A:A) -> F0027 | I50: VFLN02VILC | J50: Electromovilidad/Vitacura/LYNK CO | K50: ELECTM/VITAC/LYNKO
A51: Tattersall Automotriz | B51: =_xlfn.XLOOKUP(Tabla1[[#This Row],[SOCIEDAD]],centros!D:D,centros!E:E) -> VF00 | C51: Venta Repuesto | D51: Lira (motos) | E51: =IFERROR(INDEX(centros!$H$2:$H$45,MATCH(TRIM(Tabla1[[#This Row],[SOCIEDAD]])&"|"&TRIM(Tabla1[[#This Row],[LOCALIDAD]]),centros!$G$2:$G$45,0)),"REVISAR") -> VF03 | F51: LIFAN | G51: =_xlfn.XLOOKUP(Tabla1[[#This Row],[MARCA]],MARCAS!E:E,MARCAS!F:F) -> 140 | H51: =_xlfn.XLOOKUP(Tabla1[[#This Row],[MARCA]],MARCAS!C:C,MARCAS!A:A) -> F0021 | I51: VFLN03LILF | J51: Rpto./Lira (motos)/LIFAN | K51: RPTO/LIRA/LIFAN
A52: Tattersall Automotriz | B52: =_xlfn.XLOOKUP(Tabla1[[#This Row],[SOCIEDAD]],centros!D:D,centros!E:E) -> VF00 | C52: Venta Repuesto | D52: Lira (motos) | E52: =IFERROR(INDEX(centros!$H$2:$H$45,MATCH(TRIM(Tabla1[[#This Row],[SOCIEDAD]])&"|"&TRIM(Tabla1[[#This Row],[LOCALIDAD]]),centros!$G$2:$G$45,0)),"REVISAR") -> VF03 | F52: TODAS/OTRAS MARCAS | G52: =_xlfn.XLOOKUP(Tabla1[[#This Row],[MARCA]],MARCAS!E:E,MARCAS!F:F) -> 280 | H52: =_xlfn.XLOOKUP(Tabla1[[#This Row],[MARCA]],MARCAS!C:C,MARCAS!A:A) -> F9999 | I52: VFLN03LIOO | J52: Rpto./Lira (motos)/TODAS/OTRAS MARCAS | K52: RPTO/LIRA/TODAS
...

Sheet Unidades
A1: C/F | B1: Fabricante | C1: F0001 | D1: F0006 | E1: F0010 | F1: F0012 | G1: F0014 | H1: F0015 | I1: F0016 | J1: F0019 | K1: F0020 | L1: F0021 | M1: F0022 | N1: F0023 | O1: F0025 | P1: F0027 | Q1: F0028 | R1: F0029 | S1: F0030 | T1: F9999
A2: Centro | B2: Descripcion | C2: =_xlfn.XLOOKUP(C1,MARCAS!$A:$A,MARCAS!$C:$C) -> DFCV | D2: =_xlfn.XLOOKUP(D1,MARCAS!$A:$A,MARCAS!$C:$C) -> INT | E2: =_xlfn.XLOOKUP(E1,MARCAS!$A:$A,MARCAS!$C:$C) -> MXML | F2: =_xlfn.XLOOKUP(F1,MARCAS!$A:$A,MARCAS!$C:$C) -> HYST | G2: =_xlfn.XLOOKUP(G1,MARCAS!$A:$A,MARCAS!$C:$C) -> HMK | H2: =_xlfn.XLOOKUP(H1,MARCAS!$A:$A,MARCAS!$C:$C) -> TERB | I2: =_xlfn.XLOOKUP(I1,MARCAS!$A:$A,MARCAS!$C:$C) -> LIUG | J2: =_xlfn.XLOOKUP(J1,MARCAS!$A:$A,MARCAS!$C:$C) -> KYC | ... T2: =_xlfn.XLOOKUP(T1,MARCAS!$A:$A,MARCAS!$C:$C) -> OTRO
A3: VA00 | B3: MTT QUILICURA | C3: 1 | D3: 1 | E3: 0 | F3: 0 | G3: 0 | H3: 0 | I3: 0 | J3: 0 | K3: 0 | L3: 0 | M3: 1 | N3: 0 | O3: 0 | P3: 0 | Q3: 1 | R3: 0 | S3: 0 | T3: 1
A4: VA01 | B4: MTT CALAMA | C4: 1 | D4: 1 | E4: 0 | F4: 0 | G4: 0 | H4: 0 | I4: 0 | J4: 0 | K4: 0 | L4: 0 | M4: 1 | N4: 0 | O4: 0 | P4: 0 | Q4: 1 | R4: 0 | S4: 0 | T4: 1
A5: VA02 | B5: MTT ANTOFAGASTA | C5: 1 | D5: 1 | E5: 0 | F5: 0 | G5: 0 | H5: 0 | I5: 0 | J5: 1 | K5: 0 | L5: 0 | M5: 1 | N5: 0 | O5: 1 | P5: 0 | Q5: 1 | R5: 0 | S5: 0 | T5: 1
A6: VA03 | B6: MTT CURICO | C6: 1 | D6: 1 | E6: 0 | F6: 0 | G6: 0 | H6: 0 | I6: 0 | J6: 0 | K6: 0 | L6: 0 | M6: 1 | N6: 0 | O6: 0 | P6: 0 | Q6: 1 | R6: 0 | S6: 0 | T6: 1
A7: VA04 | B7: MTT TALCAHUANO | C7: 1 | D7: 1 | E7: 0 | F7: 0 | G7: 0 | H7: 0 | I7: 0 | J7: 1 | K7: 0 | L7: 0 | M7: 1 | N7: 0 | O7: 1 | P7: 0 | Q7: 1 | R7: 0 | S7: 0 | T7: 1
A8: VA05 | B8: MTT TEMUCO | C8: 1 | D8: 1 | E8: 0 | F8: 0 | G8: 0 | H8: 0 | I8: 0 | J8: 0 | K8: 0 | L8: 0 | M8: 1 | N8: 0 | O8: 0 | P8: 0 | Q8: 1 | R8: 0 | S8: 0 | T8: 1
A9: VA06 | B9: MTT PUERTO MONTT | C9: 1 | D9: 1 | E9: 0 | F9: 0 | G9: 0 | H9: 0 | I9: 0 | J9: 1 | K9: 0 | L9: 0 | M9: 1 | N9: 0 | O9: 1 | P9: 0 | Q9: 1 | R9: 0 | S9: 0 | T9: 1
A10: VA07 | B10: MTT IMPORTACIONES | C10: 1 | D10: 1 | E10: 0 | F10: 0 | G10: 0 | H10: 0 | I10: 0 | J10: 0 | K10: 0 | L10: 0 | M10: 1 | N10: 0 | O10: 0 | P10: 0 | Q10: 1 | R10: 0 | S10: 0 | T10: 1
A11: VC00 | B11: TTM QUILICURA | C11: 0 | D11: 0 | E11: 1 | F11: 1 | G11: 1 | H11: 1 | I11: 0 | J11: 0 | K11: 0 | L11: 0 | M11: 0 | N11: 0 | O11: 0 | P11: 0 | Q11: 0 | R11: 0 | S11: 0 | T11: 1
A12: VC01 | B12: TTM CALAMA | C12: 0 | D12: 0 | E12: 1 | F12: 1 | G12: 1 | H12: 1 | I12: 0 | J12: 0 | K12: 0 | L12: 0 | M12: 0 | N12: 0 | O12: 0 | P12: 0 | Q12: 0 | R12: 0 | S12: 0 | T12: 1
A13: VC02 | B13: TTM ANTOFAGASTA | C13: 0 | D13: 0 | E13: 1 | F13: 1 | G13: 1 | H13: 1 | I13: 0 | J13: 0 | K13: 0 | L13: 0 | M13: 0 | N13: 0 | O13: 0 | P13: 0 | Q13: 0 | R13: 0 | S13: 0 | T13: 1
A14: VC04 | B14: TTM CURICO | C14: 0 | D14: 0 | E14: 1 | F14: 1 | G14: 1 | H14: 1 | I14: 0 | J14: 0 | K14: 0 | L14: 0 | M14: 0 | N14: 0 | O14: 0 | P14: 0 | Q14: 0 | R14: 0 | S14: 0 | T14: 1
... A35: VF08 | B35: TAU IMPORTACIONES | C35: 0 | D35: 0 | E35: 0 | F35: 0 | G35: 0 | H35: 0 | I35: 0 | J35: 1 | K35: 1 | L35: 1 | M35: 1 | N35: 1 | O35: 1 | P35: 1 | Q35: 0 | R35: 0 | S35: 1 | T35: 1
B36: Centros | C36: {=_xlfn.TEXTJOIN(", ",TRUE,IF(C$3:C$35=1,$A$3:$A$35,""))} -> VA00, VA01, VA02, VA03, VA04, VA05, VA06, VA07 | D36: {=_xlfn.TEXTJOIN(", ",TRUE,IF(D$3:D$35=1,$A$3:$A$35,""))} -> VA00, VA01, VA02, VA03, VA04, VA05, VA06, VA07 | E36: {=_xlfn.TEXTJOIN(", ",TRUE,IF(E$3:E$35=1,$A$3:$A$35,""))} -> VC00, VC01, VC02, VC04, VC05, VC06, VC07, VE00, VE01 | F36: {=_xlfn.TEXTJOIN(", ",TRUE,IF(F$3:F$35=1,$A$3:$A$35,""))} -> VC00, VC01, VC02, VC04, VC05, VC06, VC07, VC08 | G36: {=_xlfn.TEXTJOIN(", ",TRUE,IF(G$3:G$35=1,$A$3:$A$35,""))} -> VC00, VC01, VC02, VC04, VC05, VC06, VC07, VC08 | H36: {=_xlfn.TEXTJOIN(", ",TRUE,IF(H$3:H$35=1,$A$3:$A$35,""))} -> VC00, VC01, VC02, VC04, VC05, VC06, VC07, VC08 | I36: {=_xlfn.TEXTJOIN(", ",TRUE,IF(I$3:I$35=1,$A$3:$A$35,""))} -> VD00, VD01, VD02, VD04, VD05, VD06, VD07, VD08 | J36: {=_xlfn.TEXTJOIN(", ",TRUE,IF(J$3:J$35=1,$A$3:$A$35,""))} -> VA02, VA04, VA06, VF00, VF01, VF04, VF06, VF08 | ... T36: {=_xlfn.TEXTJOIN(", ",TRUE,IF(T$3:T$35=1,$A$3:$A$35,""))} -> VA00, VA01, VA02, VA03, VA04, VA05, VA06, VA07, VC00, VC01, VC02, VC04, VC05, VC06, VC07, VC08, VF00, VF01, VF03, VF04, VF06, VF08
C37: VA00, VA01, VA02, VA03, VA04, VA05, VA06, VA07 | D37: VA00, VA01, VA02, VA03, VA04, VA05, VA06, VA07 | E37: VC00, VC01, VC02, VC04, VC05, VC06, VC07, VE00, VE01 | F37: VC00, VC01, VC02, VC04, VC05, VC06, VC07, VC08 | G37: VC00, VC01, VC02, VC04, VC05, VC06, VC07, VC08 | H37: VC00, VC01, VC02, VC04, VC05, VC06, VC07, VC08 | I37: VD00, VD01, VD02, VD04, VD05, VD06, VD07, VD08 | J37: VA02, VA04, VA06, VF00, VF01, VF04, VF06, VF08 | K37: VF00, VF01, VF04, VF06, VF08 | L37: VF00, VF01, VF03, VF04, VF06, VF08 | M37: VA00, VA01, VA02, VA03, VA04, VA05, VA06, VA07, VF00, VF01, VF04, VF06, VF08 | N37: VF00, VF01, VF04, VF06, VF08 | O37: VF00, VF01, VF04, VF05, VF06, VF08 | P37: VF00, VF01, VF04, VF05, VF06, VF08 | Q37: VA00, VA01, VA02, VA03, VA04, VA05, VA06, VA07 | R37: VF00, VF04 | S37: VF00, VF01, VF03, VF04, VF06, VF08 | T37: VC00, VC01, VC02, VC04, VC05, VC06, VC07, VC08, VF00, VF01, VF03, VF04, VF06, VF08
B38: Tau maco, validar con Fran o Joaco
B39: maco centro de osorno se va a crear (nuevo)
B40: liug con fran, lo demas con
B42: El centro VF07 no va

Sheet centros
A1: CodigoCentro | B1: DescripcionCentro | D1: SOCIEDAD | E1: COD_FILIAL | G1: CLAVE (SOCIEDAD|LOCALIDAD) | H1: CENTRO
A2: VA00 | B2: MACO Quilicura | D2: Tattersall Automotriz | E2: VF00 | G2: Tattersall Automotriz|Quilicura | H2: VF00
A3: VA01 | B3: MACO Calama | D3: MACO Tattersall | E3: VA00 | G3: Tattersall Automotriz|Movicenter LynkCo | H3: VF01
A4: VA02 | B4: MACO Antofagasta | D4: Tattersall Maquinarias | E4: VC00 | G4: Tattersall Automotriz|Movicenter Multimarca | H4: VF01
A5: VA03 | B5: MACO Curicó | D5: Tattersall Multimaq | E5: VD00 | G5: Tattersall Automotriz|Lira (motos) | H5: VF03
A6: VA04 | B6: MACO Talcahuano | D6: Tattersall Industrial | E6: VE00 | G6: Tattersall Automotriz|Operador Logístico | H6: VF04
A7: VA05 | B7: MACO Temuco | G7: Tattersall Automotriz|Vitacura | H7: VF05
A8: VA06 | B8: MACO Puerto Montt | G8: Tattersall Automotriz|Plaza Oeste | H8: VF06
A9: VA07 | B9: MACO Puerto Importaciones | G9: Tattersall Automotriz|La Dehesa | H9: VF07
A10: VB00 | B10: DFT Motors Quilicura | G10: Tattersall Automotriz| | H10: VF00
A11: VB01 | B11: DFT Motors Pto Importaciones | G11: MACO Tattersall|Quilicura | H11: VA00
A12: VC00 | B12: Maquinarias Quilicura | G12: MACO Tattersall|Calama | H12: VA01
A13: VC01 | B13: Maquinarias Calama | G13: MACO Tattersall|Antofagasta | H13: VA02
A14: VC02 | B14: Maquinarias Antofagasta | G14: MACO Tattersall|Curico | H14: VA03
A15: VC03 | B15: Maquinarias Coquimbo | G15: MACO Tattersall|Talcahuano | H15: VA04
A16: VC04 | B16: Maquinarias Curicó | G16: MACO Tattersall|Temuco | H16: VA05
A17: VC05 | B17: Maquinarias Talcahuano | G17: MACO Tattersall|Puerto Montt | H17: VA06
A18: VC06 | B18: Maquinarias Puerto Montt | G18: MACO Tattersall| | H18: VA00
... A38: VF07 | B38: Automotriz La Dehesa | G38: Tattersall Industrial| | H38: VE00
A39: VF08 | B39: Automotriz Pto Importaciones | C39: necesario? | G39: Tattersall Industrial|Antofagasta | H39: VE01
A40: VF09 | B40: Automotriz Movicenter Taller | C40: necesario? | G40: Tattersall Industrial|Calama | H40: VE01
G41: Tattersall Industrial|Coquimbo | H41: VE01
G42: Tattersall Industrial|Curico | H42: VE01
G43: Tattersall Industrial|Talcahuano | H43: VE01
G44: Tattersall Industrial|Puerto Montt | H44: VE01
G45: Tattersall Industrial|Osorno | H45: VE01

Sheet MARCAS
A1: Proveedor | B1: Nombre | C1: ; | E1: GRUPO MATERIAL | F1: CODIGO | L1: MARCA | M1: COD_MARCA | N1: COD_FABRICANTE
A2: F0001 | B2: CHINA DONG FENG MOTOR INDUSTRY IMP | C2: DFCV | E2: BASHAN | F2: 010 | H2: Texto | I2: codigo | L2: LYNK CO | M2: 170 | N2: F0027
A3: F0002 | B3: ACCURIDE WHEEL | C3: ACWHE | E3: ASILE MASTER | F3: 020 | H3: ORIGINAL | I3: 10 | L3: LIFAN | M3: 140 | N3: F0021
A4: F0003 | B4: ADQUIM | C4: ADQUI | E4: COMBILIFT | F4: 030 | H4: ALTERNATIVO | I4: 20 | L4: TODAS/OTRAS MARCAS | M4: 280 | N4: F9999
A5: F0004 | B5: ALLIANCE | C5: ALLIA | E5: CUMMINS | F5: 040 | L5: DONG FENG (DFAC) | M5: 060 | N5: F0022
A6: F0005 | B6: ANKA | C6: ANKA | E6: D&P | F6: 050 | L6: FAW | M6: 080 | N6: F0028
A7: F0006 | B7: INTERNATIONAL MOTORS, LLC | C7: INT | E7: DONGFENG | F7: 060 | L7: KYC | M7: 130 | N7: F0019
A8: F0007 | B8: BENDIX | C8: BENDI | E8: DRESSTA | F8: 070 | L8: LIVAN | M8: 160 | N8: F0023
A9: F0008 | B9: BORGWARNER ALL MAKES | C9: BORWA | E9: FAW | F9: 080 | L9: ZXAUTO | M9: 260 | N9: F0020
A10: F0009 | B10: BRAKEDRUM | C10: BRAKE | E10: HIDROMEK | F10: 090 | L10: JETOUR | M10: 120 | N10: F9999
A11: F0010 | B11: HYSTER-YALE MAXIMAL FORKLIFT (ZHEJI | C11: MXML | E11: HYSTER | F11: 100 | L11: RIDDARA | M11: 220 | N11: F9999
A12: F0011 | B12: TVH FORKLIFT PARTS NV | C12: TVH | E12: INTERNATIONAL | F12: 110 | L12: DONG FENG (DFCV) | M12: 060 | N12: F0001
A13: F0012 | B13: NMHG INC. PARTS DISTRIBUTION CENTER | C13: HYST | E13: JETOUR | F13: 120 | L13: INTERNATIONAL | M13: 110 | N13: F0006
A14: F0013 | B14: NMHG INC. PARTS DISTRIBUTION CENTER | C14: TREL | E14: KYC | F14: 130 | L14: HYSTER | M14: 100 | N14: F0012
A15: F0014 | B15: HIDROMEK-HIDROLIK VE MEKNANIK LTD. | C15: HMK | E15: LIFAN | F15: 140 | L15: HMK | M15: 090 | N15: F0014
A16: F0015 | B16: Terberg Tractors Americas, Inc | C16: TERB | E16: LIUGONG | F16: 150 | L16: TERBERG | M16: 230 | N16: F0015
... A18: F0017 | B18: Guangxi Liugong Machinery Co., Ltd. | C18: DRSS | E18: LYNK & CO | F18: 170 | L18: LIUGONG | M18: 150 | N18: F0016
A19: F0018 | B19: MOTORPEL CO. LTD. | C19: MTPL | E19: MAXIMAL | F19: 180
A20: F0019 | B20: KYC CHONGQING KUAYUE (GROUP) CO. | C20: KYC | E20: MICHELIN | F20: 190
A21: F0020 | B21: ZXAUTO INTERNATINOAL IMPORT AND EXP | C21: ZXAU | E21: MODASA | F21: 200
A22: F0021 | B22: CHONGQING LIFAN SUZHUI FOREIGN TRAD | C22: LIFM | E22: MUSTANG | F22: 210
A23: F0022 | B23: DONGFENG AUTOBOBILE CO LTD | C23: DFAC | E23: RIDDARA | F23: 220
A24: F0023 | B24: LIVAN AUTO IMP. & EXP. CO., LTD | C24: LIVN | E24: TERBERG | F24: 230
A25: F0024 | B25: CHONGQING LIJU IMP & EXP CO., LTD | C25: LIFA | E25: TRELLEBORG | F25: 240
A26: F0025 | B26: SHANDONG OULING AUTOMOBILE MANUFACT | C26: RIDD | E26: WATTS | F26: 250
A27: F0026 | B27: CHONGQING SHINDARY INDUSTRI | C27: SHIN | E27: ZX | F27: 260
A28: F0027 | B28: LYNK & CO AUTOMOBILE INTERNATIONAL | C28: LYNK | E28: LINHAI | F28: 270
A29: F0028 | B29: CHINA FAW GROUP IMPORT & EXPORT CO. | C29: FAW | E29: OTRAS MARCAS | F29: 280
A30: F0029 | B30: CHERY AUTOMOBILE HENAN CO. LT | C30: JETR | E30: LIFAN AUTO | F30: 290
... A37: F0037 | B37: DANA SPICER | C37: DASPI | E37: JETOUR | F37: 120
A38: F0038 | B38: DELCO REMY | C38: DELRE
A39: F0039 | B39: DONALDSON | C39: DONAL
A40: F0040 | B40: WARREN OIL | C40: WAROI
A41: F0041 | B41: EATON CLUTCH | C41: EACLU
A42: F0042 | B42: EATON ENDURANT | C42: EAEND
A43: F0043 | B43: EATON FULLER | C43: EAFUL
A44: F0044 | B44: FLEETRITE BATTERY (MX) | C44: FLBAT
A45: F0045 | B45: FLEETRITE CHINA | C45: FLCHI
A46: F0046 | B46: FLEETRITE CLUTCH IATCO | C46: FLCLU
A47: F0047 | B47: FLEETRITE | C47: FLEET
...

Sheet Hoja3

Sheet Resumen
A1: Resumen de cobertura por centro (base: hoja cebe / Tabla1)
A2: {="Total de centros distintos: "&ROUND(SUMPRODUCT(1/COUNTIF(Tabla1[CENTRO],Tabla1[CENTRO])),0)&" | Marcas: "&ROUND(SUMPRODUCT(1/COUNTIF(Tabla1[MARCA],Tabla1[MARCA])),0)&" | Fabricantes: "&ROUND(SUMPRODUCT(1/COUNTIF(Tabla1[COD_FABRICANTE],Tabla1[COD_FABRICANTE])),0)&" | Registros CEBE: "&COUNTA(Tabla1[CENTRO])} -> Total de centros distintos: 32 | Marcas: 17 | Fabricantes: 17 | Registros CEBE: 641 | I2: VFLN01QCDC
A3: MARCAS: ¿en cuántos centros está cada marca? | I3: VFLN01QCFW
A4: MARCA | B4: COD_MARCA | C4: N° Centros | D4: N° CEBEs | F4: Centros | I4: VFLN01QCKC
A5: {=_xlfn._xlws.SORT(_xlfn.UNIQUE(Tabla1[MARCA]))} -> DONG FENG (DFAC) | B5: =IFERROR(INDEX(Tabla1[COD_MARCA],MATCH($A5,Tabla1[MARCA],0)),"") -> 060 | C5: {=ROUND(SUMPRODUCT((Tabla1[MARCA]=$A5)/COUNTIFS(Tabla1[MARCA],Tabla1[MARCA],Tabla1[CENTRO],Tabla1[CENTRO])),0)} -> 11 | D5: =COUNTIF(Tabla1[MARCA],$A5) -> 49 | F5: VA00, VA01, VA02, VA03, VA04, VA05, VA06, VF00, VF01, VF04, VF06 | I5: VFLN01QCLF
A6: DONG FENG (DFCV) | B6: =IFERROR(INDEX(Tabla1[COD_MARCA],MATCH($A6,Tabla1[MARCA],0)),"") -> 060 | C6: {=ROUND(SUMPRODUCT((Tabla1[MARCA]=$A6)/COUNTIFS(Tabla1[MARCA],Tabla1[MARCA],Tabla1[CENTRO],Tabla1[CENTRO])),0)} -> 7 | D6: =COUNTIF(Tabla1[MARCA],$A6) -> 42 | F6: VA00, VA01, VA02, VA03, VA04, VA05, VA06 | I6: VFLN01QCLV
A7: FAW | B7: =IFERROR(INDEX(Tabla1[COD_MARCA],MATCH($A7,Tabla1[MARCA],0)),"") -> 080 | C7: {=ROUND(SUMPRODUCT((Tabla1[MARCA]=$A7)/COUNTIFS(Tabla1[MARCA],Tabla1[MARCA],Tabla1[CENTRO],Tabla1[CENTRO])),0)} -> 11 | D7: =COUNTIF(Tabla1[MARCA],$A7) -> 49 | F7: VA00, VA01, VA02, VA03, VA04, VA05, VA06, VF00, VF01, VF04, VF06 | I7: VFLN01QCLC
A8: HMK | B8: =IFERROR(INDEX(Tabla1[COD_MARCA],MATCH($A8,Tabla1[MARCA],0)),"") -> 090 | C8: {=ROUND(SUMPRODUCT((Tabla1[MARCA]=$A8)/COUNTIFS(Tabla1[MARCA],Tabla1[MARCA],Tabla1[CENTRO],Tabla1[CENTRO])),0)} -> 8 | D8: =COUNTIF(Tabla1[MARCA],$A8) -> 40 | F8: VC00, VC01, VC02, VC03, VC04, VC05, VC06, VC07 | I8: VFLN01QCOO
A9: HYSTER | B9: =IFERROR(INDEX(Tabla1[COD_MARCA],MATCH($A9,Tabla1[MARCA],0)),"") -> 100 | C9: {=ROUND(SUMPRODUCT((Tabla1[MARCA]=$A9)/COUNTIFS(Tabla1[MARCA],Tabla1[MARCA],Tabla1[CENTRO],Tabla1[CENTRO])),0)} -> 8 | D9: =COUNTIF(Tabla1[MARCA],$A9) -> 48 | F9: VC00, VC01, VC02, VC03, VC04, VC05, VC06, VC07 | I9: VFLN01QCZX
A10: INTERNATIONAL | B10: =IFERROR(INDEX(Tabla1[COD_MARCA],MATCH($A10,Tabla1[MARCA],0)),"") -> 110 | C10: {=ROUND(SUMPRODUCT((Tabla1[MARCA]=$A10)/COUNTIFS(Tabla1[MARCA],Tabla1[MARCA],Tabla1[CENTRO],Tabla1[CENTRO])),0)} -> 7 | D10: =COUNTIF(Tabla1[MARCA],$A10) -> 35 | F10: VA00, VA01, VA02, VA03, VA04, VA05, VA06 | I10: VALN01QCDV
A11: JETOUR | B11: =IFERROR(INDEX(Tabla1[COD_MARCA],MATCH($A11,Tabla1[MARCA],0)),"") -> 120 | C11: {=ROUND(SUMPRODUCT((Tabla1[MARCA]=$A11)/COUNTIFS(Tabla1[MARCA],Tabla1[MARCA],Tabla1[CENTRO],Tabla1[CENTRO])),0)} -> 2 | D11: =COUNTIF(Tabla1[MARCA],$A11) -> 3 | F11: VF00, VF04 | I11: VALN01QCFW
A12: KYC | B12: =IFERROR(INDEX(Tabla1[COD_MARCA],MATCH($A12,Tabla1[MARCA],0)),"") -> 130 | C12: {=ROUND(SUMPRODUCT((Tabla1[MARCA]=$A12)/COUNTIFS(Tabla1[MARCA],Tabla1[MARCA],Tabla1[CENTRO],Tabla1[CENTRO])),0)} -> 4 | D12: =COUNTIF(Tabla1[MARCA],$A12) -> 7 | F12: VF00, VF01, VF04, VF06 | I12: VALN01QCIN
A13: LIFAN | B13: =IFERROR(INDEX(Tabla1[COD_MARCA],MATCH($A13,Tabla1[MARCA],0)),"") -> 140 | C13: {=ROUND(SUMPRODUCT((Tabla1[MARCA]=$A13)/COUNTIFS(Tabla1[MARCA],Tabla1[MARCA],Tabla1[CENTRO],Tabla1[CENTRO])),0)} -> 3 | D13: =COUNTIF(Tabla1[MARCA],$A13) -> 6 | F13: VF00, VF03, VF04 | I13: VALN01QCDC
A14: LIUGONG | B14: =IFERROR(INDEX(Tabla1[COD_MARCA],MATCH($A14,Tabla1[MARCA],0)),"") -> 150 | C14: {=ROUND(SUMPRODUCT((Tabla1[MARCA]=$A14)/COUNTIFS(Tabla1[MARCA],Tabla1[MARCA],Tabla1[CENTRO],Tabla1[CENTRO])),0)} -> 16 | D14: =COUNTIF(Tabla1[MARCA],$A14) -> 96 | F14: VC00, VC01, VC02, VC03, VC04, VC05, VC06, VC07, VD00, VD01, VD02, VD03, VD04, VD05, VD06, VD07 | I14: VCLN01QCHY
A15: LIVAN | B15: =IFERROR(INDEX(Tabla1[COD_MARCA],MATCH($A15,Tabla1[MARCA],0)),"") -> 160 | C15: {=ROUND(SUMPRODUCT((Tabla1[MARCA]=$A15)/COUNTIFS(Tabla1[MARCA],Tabla1[MARCA],Tabla1[CENTRO],Tabla1[CENTRO])),0)} -> 4 | D15: =COUNTIF(Tabla1[MARCA],$A15) -> 11 | F15: VF00, VF01, VF04, VF06 | I15: VCLN01QCHK
A16: LYNK CO | B16: =IFERROR(INDEX(Tabla1[COD_MARCA],MATCH($A16,Tabla1[MARCA],0)),"") -> 170 | C16: {=ROUND(SUMPRODUCT((Tabla1[MARCA]=$A16)/COUNTIFS(Tabla1[MARCA],Tabla1[MARCA],Tabla1[CENTRO],Tabla1[CENTRO])),0)} -> 6 | D16: =COUNTIF(Tabla1[MARCA],$A16) -> 17 | F16: VF00, VF01, VF04, VF05, VF06, VF07 | I16: VCLN01QCTB
A17: MAXIMAL | B17: =IFERROR(INDEX(Tabla1[COD_MARCA],MATCH($A17,Tabla1[MARCA],0)),"") -> 180 | C17: {=ROUND(SUMPRODUCT((Tabla1[MARCA]=$A17)/COUNTIFS(Tabla1[MARCA],Tabla1[MARCA],Tabla1[CENTRO],Tabla1[CENTRO])),0)} -> 10 | D17: =COUNTIF(Tabla1[MARCA],$A17) -> 90 | F17: VC00, VC01, VC02, VC03, VC04, VC05, VC06, VC07, VE00 | I17: VCLN01QCMA
... A21: ZXAUTO | B21: =IFERROR(INDEX(Tabla1[COD_MARCA],MATCH($A21,Tabla1[MARCA],0)),"") -> 260 | C21: {=ROUND(SUMPRODUCT((Tabla1[MARCA]=$A21)/COUNTIFS(Tabla1[MARCA],Tabla1[MARCA],Tabla1[CENTRO],Tabla1[CENTRO])),0)} -> 4 | D21: =COUNTIF(Tabla1[MARCA],$A21) -> 7 | F21: VF00, VF01, VF04, VF06 | I21: VELN01QCMA
A23: FABRICANTES: ¿en cuántos centros está cada fabricante?
A24: COD_FABRICANTE | B24: Nombre proveedor (hoja MARCAS) | C24: N° Centros | D24: N° Marcas | E24: N° CEBEs | F24: Centros
A25: {=_xlfn._xlws.SORT(_xlfn.UNIQUE(Tabla1[COD_FABRICANTE]))} -> F0001 | B25: =IFERROR(INDEX(MARCAS!$B:$B,MATCH($A25,MARCAS!$A:$A,0)),"(sin nombre en hoja MARCAS)") -> CHINA DONG FENG MOTOR INDUSTRY IMP | C25: {=ROUND(SUMPRODUCT((Tabla1[COD_FABRICANTE]=$A25)/COUNTIFS(Tabla1[COD_FABRICANTE],Tabla1[COD_FABRICANTE],Tabla1[CENTRO],Tabla1[CENTRO])),0)} -> 7 | D25: {=ROUND(SUMPRODUCT((Tabla1[COD_FABRICANTE]=$A25)/COUNTIFS(Tabla1[COD_FABRICANTE],Tabla1[COD_FABRICANTE],Tabla1[MARCA],Tabla1[MARCA])),0)} -> 1 | E25: 42 | F25: {=_xlfn.TEXTJOIN(", ",TRUE,_xlfn._xlws.SORT(_xlfn.UNIQUE(_xlfn._xlws.FILTER(Tabla1[CENTRO],Tabla1[COD_FABRICANTE]=$A25))))} -> VA00, VA01, VA02, VA03, VA04, VA05, VA06
A26: F0006 | B26: =IFERROR(INDEX(MARCAS!$B:$B,MATCH($A26,MARCAS!$A:$A,0)),"(sin nombre en hoja MARCAS)") -> INTERNATIONAL MOTORS, LLC | C26: {=ROUND(SUMPRODUCT((Tabla1[COD_FABRICANTE]=$A26)/COUNTIFS(Tabla1[COD_FABRICANTE],Tabla1[COD_FABRICANTE],Tabla1[CENTRO],Tabla1[CENTRO])),0)} -> 7 | D26: {=ROUND(SUMPRODUCT((Tabla1[COD_FABRICANTE]=$A26)/COUNTIFS(Tabla1[COD_FABRICANTE],Tabla1[COD_FABRICANTE],Tabla1[MARCA],Tabla1[MARCA])),0)} -> 1 | E26: 35 | F26: {=_xlfn.TEXTJOIN(", ",TRUE,_xlfn._xlws.SORT(_xlfn.UNIQUE(_xlfn._xlws.FILTER(Tabla1[CENTRO],Tabla1[COD_FABRICANTE]=$A26))))} -> VA00, VA01, VA02, VA03, VA04, VA05, VA06
A27: F0010 | B27: =IFERROR(INDEX(MARCAS!$B:$B,MATCH($A27,MARCAS!$A:$A,0)),"(sin nombre en hoja MARCAS)") -> HYSTER-YALE MAXIMAL FORKLIFT (ZHEJI | C27: {=ROUND(SUMPRODUCT((Tabla1[COD_FABRICANTE]=$A27)/COUNTIFS(Tabla1[COD_FABRICANTE],Tabla1[COD_FABRICANTE],Tabla1[CENTRO],Tabla1[CENTRO])),0)} -> 10 | D27: {=ROUND(SUMPRODUCT((Tabla1[COD_FABRICANTE]=$A27)/COUNTIFS(Tabla1[COD_FABRICANTE],Tabla1[COD_FABRICANTE],Tabla1[MARCA],Tabla1[MARCA])),0)} -> 1 | E27: 96 | F27: {=_xlfn.TEXTJOIN(", ",TRUE,_xlfn._xlws.SORT(_xlfn.UNIQUE(_xlfn._xlws.FILTER(Tabla1[CENTRO],Tabla1[COD_FABRICANTE]=$A27))))} -> VC00, VC01, VC02, VC03, VC04, VC05, VC06, VC07, VE00, VE01
A28: F0012 | B28: =IFERROR(INDEX(MARCAS!$B:$B,MATCH($A28,MARCAS!$A:$A,0)),"(sin nombre en hoja MARCAS)") -> NMHG INC. PARTS DISTRIBUTION CENTER | C28: {=ROUND(SUMPRODUCT((Tabla1[COD_FABRICANTE]=$A28)/COUNTIFS(Tabla1[COD_FABRICANTE],Tabla1[COD_FABRICANTE],Tabla1[CENTRO],Tabla1[CENTRO])),0)} -> 8 | D28: {=ROUND(SUMPRODUCT((Tabla1[COD_FABRICANTE]=$A28)/COUNTIFS(Tabla1[COD_FABRICANTE],Tabla1[COD_FABRICANTE],Tabla1[MARCA],Tabla1[MARCA])),0)} -> 1 | E28: 48 | F28: {=_xlfn.TEXTJOIN(", ",TRUE,_xlfn._xlws.SORT(_xlfn.UNIQUE(_xlfn._xlws.FILTER(Tabla1[CENTRO],Tabla1[COD_FABRICANTE]=$A28))))} -> VC00, VC01, VC02, VC03, VC04, VC05, VC06, VC07
A29: F0014 | B29: =IFERROR(INDEX(MARCAS!$B:$B,MATCH($A29,MARCAS!$A:$A,0)),"(sin nombre en hoja MARCAS)") -> HIDROMEK-HIDROLIK VE MEKNANIK LTD. | C29: {=ROUND(SUMPRODUCT((Tabla1[COD_FABRICANTE]=$A29)/COUNTIFS(Tabla1[COD_FABRICANTE],Tabla1[COD_FABRICANTE],Tabla1[CENTRO],Tabla1[CENTRO])),0)} -> 8 | D29: {=ROUND(SUMPRODUCT((Tabla1[COD_FABRICANTE]=$A29)/COUNTIFS(Tabla1[COD_FABRICANTE],Tabla1[COD_FABRICANTE],Tabla1[MARCA],Tabla1[MARCA])),0)} -> 1 | E29: 40 | F29: {=_xlfn.TEXTJOIN(", ",TRUE,_xlfn._xlws.SORT(_xlfn.UNIQUE(_xlfn._xlws.FILTER(Tabla1[CENTRO],Tabla1[COD_FABRICANTE]=$A29))))} -> VC00, VC01, VC02, VC03, VC04, VC05, VC06, VC07
A30: F0015 | B30: =IFERROR(INDEX(MARCAS!$B:$B,MATCH($A30,MARCAS!$A:$A,0)),"(sin nombre en hoja MARCAS)") -> Terberg Tractors Americas, Inc | C30: {=ROUND(SUMPRODUCT((Tabla1[COD_FABRICANTE]=$A30)/COUNTIFS(Tabla1[COD_FABRICANTE],Tabla1[COD_FABRICANTE],Tabla1[CENTRO],Tabla1[CENTRO])),0)} -> 8 | D30: {=ROUND(SUMPRODUCT((Tabla1[COD_FABRICANTE]=$A30)/COUNTIFS(Tabla1[COD_FABRICANTE],Tabla1[COD_FABRICANTE],Tabla1[MARCA],Tabla1[MARCA])),0)} -> 1 | E30: 48 | F30: {=_xlfn.TEXTJOIN(", ",TRUE,_xlfn._xlws.SORT(_xlfn.UNIQUE(_xlfn._xlws.FILTER(Tabla1[CENTRO],Tabla1[COD_FABRICANTE]=$A30))))} -> VC00, VC01, VC02, VC03, VC04, VC05, VC06, VC07
A31: F0016 | B31: =IFERROR(INDEX(MARCAS!$B:$B,MATCH($A31,MARCAS!$A:$A,0)),"(sin nombre en hoja MARCAS)") -> Guangxi Liugong Machinery Co., Ltd. | C31: {=ROUND(SUMPRODUCT((Tabla1[COD_FABRICANTE]=$A31)/COUNTIFS(Tabla1[COD_FABRICANTE],Tabla1[COD_FABRICANTE],Tabla1[CENTRO],Tabla1[CENTRO])),0)} -> 16 | D31: {=ROUND(SUMPRODUCT((Tabla1[COD_FABRICANTE]=$A31)/COUNTIFS(Tabla1[COD_FABRICANTE],Tabla1[COD_FABRICANTE],Tabla1[MARCA],Tabla1[MARCA])),0)} -> 1 | E31: 96 | F31: {=_xlfn.TEXTJOIN(", ",TRUE,_xlfn._xlws.SORT(_xlfn.UNIQUE(_xlfn._xlws.FILTER(Tabla1[CENTRO],Tabla1[COD_FABRICANTE]=$A31))))} -> VC00, VC01, VC02, VC03, VC04, VC05, VC06, VC07, VD00, VD01, VD02, VD03, VD04, VD05, VD06, VD07
A32: F0019 | B32: =IFERROR(INDEX(MARCAS!$B:$B,MATCH($A32,MARCAS!$A:$A,0)),"(sin nombre en hoja MARCAS)") -> KYC CHONGQING KUAYUE (GROUP) CO. | C32: {=ROUND(SUMPRODUCT((Tabla1[COD_FABRICANTE]=$A32)/COUNTIFS(Tabla1[COD_FABRICANTE],Tabla1[COD_FABRICANTE],Tabla1[CENTRO],Tabla1[CENTRO])),0)} -> 4 | D32: {=ROUND(SUMPRODUCT((Tabla1[COD_FABRICANTE]=$A32)/COUNTIFS(Tabla1[COD_FABRICANTE],Tabla1[COD_FABRICANTE],Tabla1[MARCA],Tabla1[MARCA])),0)} -> 1 | E32: 7 | F32: {=_xlfn.TEXTJOIN(", ",TRUE,_xlfn._xlws.SORT(_xlfn.UNIQUE(_xlfn._xlws.FILTER(Tabla1[CENTRO],Tabla1[COD_FABRICANTE]=$A32))))} -> VF00, VF01, VF04, VF06
A33: F0020 | B33: =IFERROR(INDEX(MARCAS!$B:$B,MATCH($A33,MARCAS!$A:$A,0)),"(sin nombre en hoja MARCAS)") -> ZXAUTO INTERNATINOAL IMPORT AND EXP | C33: {=ROUND(SUMPRODUCT((Tabla1[COD_FABRICANTE]=$A33)/COUNTIFS(Tabla1[COD_FABRICANTE],Tabla1[COD_FABRICANTE],Tabla1[CENTRO],Tabla1[CENTRO])),0)} -> 4 | D33: {=ROUND(SUMPRODUCT((Tabla1[COD_FABRICANTE]=$A33)/COUNTIFS(Tabla1[COD_FABRICANTE],Tabla1[COD_FABRICANTE],Tabla1[MARCA],Tabla1[MARCA])),0)} -> 1 | E33: 7 | F33: {=_xlfn.TEXTJOIN(", ",TRUE,_xlfn._xlws.SORT(_xlfn.UNIQUE(_xlfn._xlws.FILTER(Tabla1[CENTRO],Tabla1[COD_FABRICANTE]=$A33))))} -> VF00, VF01, VF04, VF06
A34: F0021 | B34: =IFERROR(INDEX(MARCAS!$B:$B,MATCH($A34,MARCAS!$A:$A,0)),"(sin nombre en hoja MARCAS)") -> CHONGQING LIFAN SUZHUI FOREIGN TRAD | C34: {=ROUND(SUMPRODUCT((Tabla1[COD_FABRICANTE]=$A34)/COUNTIFS(Tabla1[COD_FABRICANTE],Tabla1[COD_FABRICANTE],Tabla1[CENTRO],Tabla1[CENTRO])),0)} -> 3 | D34: {=ROUND(SUMPRODUCT((Tabla1[COD_FABRICANTE]=$A34)/COUNTIFS(Tabla1[COD_FABRICANTE],Tabla1[COD_FABRICANTE],Tabla1[MARCA],Tabla1[MARCA])),0)} -> 1 | E34: 6 | F34: {=_xlfn.TEXTJOIN(", ",TRUE,_xlfn._xlws.SORT(_xlfn.UNIQUE(_xlfn._xlws.FILTER(Tabla1[CENTRO],Tabla1[COD_FABRICANTE]=$A34))))} -> VF00, VF03, VF04
A35: F0022 | B35: =IFERROR(INDEX(MARCAS!$B:$B,MATCH($A35,MARCAS!$A:$A,0)),"(sin nombre en hoja MARCAS)") -> DONGFENG AUTOBOBILE CO LTD | C35: {=ROUND(SUMPRODUCT((Tabla1[COD_FABRICANTE]=$A35)/COUNTIFS(Tabla1[COD_FABRICANTE],Tabla1[COD_FABRICANTE],Tabla1[CENTRO],Tabla1[CENTRO])),0)} -> 11 | D35: {=ROUND(SUMPRODUCT((Tabla1[COD_FABRICANTE]=$A35)/COUNTIFS(Tabla1[COD_FABRICANTE],Tabla1[COD_FABRICANTE],Tabla1[MARCA],Tabla1[MARCA])),0)} -> 1 | E35: 49 | F35: {=_xlfn.TEXTJOIN(", ",TRUE,_xlfn._xlws.SORT(_xlfn.UNIQUE(_xlfn._xlws.FILTER(Tabla1[CENTRO],Tabla1[COD_FABRICANTE]=$A35))))} -> VA00, VA01, VA02, VA03, VA04, VA05, VA06, VF00, VF01, VF04, VF06
A36: F0023 | B36: =IFERROR(INDEX(MARCAS!$B:$B,MATCH($A36,MARCAS!$A:$A,0)),"(sin nombre en hoja MARCAS)") -> LIVAN AUTO IMP. & EXP. CO., LTD | C36: {=ROUND(SUMPRODUCT((Tabla1[COD_FABRICANTE]=$A36)/COUNTIFS(Tabla1[COD_FABRICANTE],Tabla1[COD_FABRICANTE],Tabla1[CENTRO],Tabla1[CENTRO])),0)} -> 4 | D36: {=ROUND(SUMPRODUCT((Tabla1[COD_FABRICANTE]=$A36)/COUNTIFS(Tabla1[COD_FABRICANTE],Tabla1[COD_FABRICANTE],Tabla1[MARCA],Tabla1[MARCA])),0)} -> 1 | E36: 11 | F36: {=_xlfn.TEXTJOIN(", ",TRUE,_xlfn._xlws.SORT(_xlfn.UNIQUE(_xlfn._xlws.FILTER(Tabla1[CENTRO],Tabla1[COD_FABRICANTE]=$A36))))} -> VF00, VF01, VF04, VF06
A37: F0025 | B37: =IFERROR(INDEX(MARCAS!$B:$B,MATCH($A37,MARCAS!$A:$A,0)),"(sin nombre en hoja MARCAS)") -> SHANDONG OULING AUTOMOBILE MANUFACT | C37: {=ROUND(SUMPRODUCT((Tabla1[COD_FABRICANTE]=$A37)/COUNTIFS(Tabla1[COD_FABRICANTE],Tabla1[COD_FABRICANTE],Tabla1[CENTRO],Tabla1[CENTRO])),0)} -> 4 | D37: {=ROUND(SUMPRODUCT((Tabla1[COD_FABRICANTE]=$A37)/COUNTIFS(Tabla1[COD_FABRICANTE],Tabla1[COD_FABRICANTE],Tabla1[MARCA],Tabla1[MARCA])),0)} -> 1 | E37: 17 | F37: {=_xlfn.TEXTJOIN(", ",TRUE,_xlfn._xlws.SORT(_xlfn.UNIQUE(_xlfn._xlws.FILTER(Tabla1[CENTRO],Tabla1[COD_FABRICANTE]=$A37))))} -> VF00, VF01, VF04, VF06
... A41: F9999 | B41: =IFERROR(INDEX(MARCAS!$B:$B,MATCH($A41,MARCAS!$A:$A,0)),"(sin nombre en hoja MARCAS)") -> OTRAS MARCAS | C41: {=ROUND(SUMPRODUCT((Tabla1[COD_FABRICANTE]=$A41)/COUNTIFS(Tabla1[COD_FABRICANTE],Tabla1[COD_FABRICANTE],Tabla1[CENTRO],Tabla1[CENTRO])),0)} -> 20 | D41: {=ROUND(SUMPRODUCT((Tabla1[COD_FABRICANTE]=$A41)/COUNTIFS(Tabla1[COD_FABRICANTE],Tabla1[COD_FABRICANTE],Tabla1[MARCA],Tabla1[MARCA])),0)} -> 1 | E41: 96 | F41: {=_xlfn.TEXTJOIN(", ",TRUE,_xlfn._xlws.SORT(_xlfn.UNIQUE(_xlfn._xlws.FILTER(Tabla1[CENTRO],Tabla1[COD_FABRICANTE]=$A41))))} -> VA00, VA01, VA02, VA03, VA04, VA05, VA06, VC00, VC01, VC02, VC03, VC04, VC05, VC06, VC07, VF00, VF01, VF03, VF04, VF06

Sheet repuestos
A1: C/F | B1: Fabricante | C1: F0001 | D1: F0006 | E1: F0007 | F1: F0010 | G1: F0012 | H1: F0013 | I1: F0014 | J1: F0015 | K1: F0016 | L1: F0019 | M1: F0020 | N1: F0021 | O1: F0022 | P1: F0023 | Q1: F0024 | R1: F0025 | S1: F0026 | T1: F0027 | U1: F0028 | V1: F0029 | W1: F0030 | X1: F0035 | Y1: F0036 | Z1: F0042 | AA1: F0043 | AB1: F0058 | AC1: F0069 | AD1: F0071 | AE1: F0072 | AF1: F9999 | AG1: F0002 | AH1: F0003 | AI1: F0004 | AJ1: F0005 | AK1: F0008 | AL1: F0009 | AM1: F0032 | AN1: F0033 | AO1: F0034 | AP1: F0037 | AQ1: F0038 | AR1: F0039 | AS1: F0040 | AT1: F0041 | AU1: F0044 | AV1: F0045 | AW1: F0046 | AX1: F0047 | AY1: F0048 | AZ1: F0049 | BA1: F0050 | BB1: F0051 | BC1: F0052 | BD1: F0053 | BE1: F0054 | BF1: F0055 | BG1: F0056 | BH1: F0057 | BI1: F0059 | BJ1: F0060 | BK1: F0061 | BL1: F0063 | BM1: F0064 | BN1: F0065 | BO1: F0066 | BP1: F0067 | BQ1: F0068 | BR1: F0070 | BS1: F0073 | BT1: F0074
A2: Centro | B2: Descripcion | C2: =_xlfn.XLOOKUP(C1,MARCAS!$A:$A,MARCAS!$C:$C) -> DFCV | D2: =_xlfn.XLOOKUP(D1,MARCAS!$A:$A,MARCAS!$C:$C) -> INT | E2: =_xlfn.XLOOKUP(E1,MARCAS!$A:$A,MARCAS!$C:$C) -> BENDI | F2: =_xlfn.XLOOKUP(F1,MARCAS!$A:$A,MARCAS!$C:$C) -> MXML | G2: =_xlfn.XLOOKUP(G1,MARCAS!$A:$A,MARCAS!$C:$C) -> HYST | H2: =_xlfn.XLOOKUP(H1,MARCAS!$A:$A,MARCAS!$C:$C) -> TREL | I2: =_xlfn.XLOOKUP(I1,MARCAS!$A:$A,MARCAS!$C:$C) -> HMK | J2: =_xlfn.XLOOKUP(J1,MARCAS!$A:$A,MARCAS!$C:$C) -> TERB | ... AF2: =_xlfn.XLOOKUP(AF1,MARCAS!$A:$A,MARCAS!$C:$C) -> OTRO | AG2: ACWHE | AH2: ADQUI | AI2: ALLIA | AJ2: ANKA | AK2: BORWA | AL2: BRAKE | AM2: CONTI | AN2: COPEC | AO2: CRSKF | AP2: DASPI | AQ2: DELRE | AR2: DONAL | AS2: WAROI | AT2: EACLU | AU2: FLBAT | AV2: FLCHI | AW2: FLCLU | AX2: FLEET | AY2: FLGUA | AZ2: FONTA | BA2: GABRI | BB2: HENDR | BC2: HETRU | BD2: HORTO | BE2: MERIT | BF2: MERUS | BG2: MGBRA | BH2: MWM | BI2: NELSO | BJ2: NEWST | BK2: NTN | BL2: SAFHO | BM2: SKF | BN2: SPICE | BO2: STARC | BP2: TAS | BQ2: TIMKE | BR2: VALVO | BS2: CABLI | BT2: PHILL
A3: VA00 | B3: MTT QUILICURA | C3: 1 | D3: 1 | E3: 1 | F3: 0 | G3: 0 | H3: 0 | I3: 0 | J3: 0 | K3: 0 | L3: 0 | M3: 0 | N3: 0 | O3: 1 | P3: 0 | Q3: 0 | R3: 0 | S3: 0 | T3: 0 | U3: 1 | V3: 0 | W3: 0 | X3: 1 | Y3: 1 | Z3: 1 | AA3: 1 | AB3: 1 | AC3: 1 | AD3: 0 | AE3: 0 | AF3: 1 | AG3: 1 | AH3: 1 | AI3: 1 | AJ3: 1 | AK3: 1 | AL3: 1 | AM3: 1 | AN3: 1 | AO3: 1 | AP3: 1 | AQ3: 1 | AR3: 1 | AS3: 1 | AT3: 1 | AU3: 1 | AV3: 1 | AW3: 1 | AX3: 1 | AY3: 1 | AZ3: 1 | BA3: 1 | BB3: 1 | BC3: 1 | BD3: 1 | BE3: 1 | BF3: 1 | BG3: 1 | BH3: 1 | BI3: 1 | BJ3: 1 | BK3: 1 | BL3: 1 | BM3: 1 | BN3: 1 | BO3: 1 | BP3: 1 | BQ3: 1 | BR3: 1 | BS3: 1 | BT3: 1
A4: VA01 | B4: MTT CALAMA | C4: 1 | D4: 1 | E4: 1 | F4: 0 | G4: 0 | H4: 0 | I4: 0 | J4: 0 | K4: 0 | L4: 0 | M4: 0 | N4: 0 | O4: 1 | P4: 0 | Q4: 0 | R4: 0 | S4: 0 | T4: 0 | U4: 1 | V4: 0 | W4: 0 | X4: 1 | Y4: 1 | Z4: 1 | AA4: 1 | AB4: 1 | AC4: 1 | AD4: 0 | AE4: 0 | AF4: 1 | AG4: 1 | AH4: 1 | AI4: 1 | AJ4: 1 | AK4: 1 | AL4: 1 | AM4: 1 | AN4: 1 | AO4: 1 | AP4: 1 | AQ4: 1 | AR4: 1 | AS4: 1 | AT4: 1 | AU4: 1 | AV4: 1 | AW4: 1 | AX4: 1 | AY4: 1 | AZ4: 1 | BA4: 1 | BB4: 1 | BC4: 1 | BD4: 1 | BE4: 1 | BF4: 1 | BG4: 1 | BH4: 1 | BI4: 1 | BJ4: 1 | BK4: 1 | BL4: 1 | BM4: 1 | BN4: 1 | BO4: 1 | BP4: 1 | BQ4: 1 | BR4: 1 | BS4: 1 | BT4: 1
A5: VA02 | B5: MTT ANTOFAGASTA | C5: 1 | D5: 1 | E5: 1 | F5: 0 | G5: 0 | H5: 0 | I5: 0 | J5: 0 | K5: 0 | L5: 0 | M5: 0 | N5: 0 | O5: 1 | P5: 0 | Q5: 0 | R5: 0 | S5: 0 | T5: 0 | U5: 1 | V5: 0 | W5: 0 | X5: 1 | Y5: 1 | Z5: 1 | AA5: 1 | AB5: 1 | AC5: 1 | AD5: 0 | AE5: 0 | AF5: 1 | AG5: 1 | AH5: 1 | AI5: 1 | AJ5: 1 | AK5: 1 | AL5: 1 | AM5: 1 | AN5: 1 | AO5: 1 | AP5: 1 | AQ5: 1 | AR5: 1 | AS5: 1 | AT5: 1 | AU5: 1 | AV5: 1 | AW5: 1 | AX5: 1 | AY5: 1 | AZ5: 1 | BA5: 1 | BB5: 1 | BC5: 1 | BD5: 1 | BE5: 1 | BF5: 1 | BG5: 1 | BH5: 1 | BI5: 1 | BJ5: 1 | BK5: 1 | BL5: 1 | BM5: 1 | BN5: 1 | BO5: 1 | BP5: 1 | BQ5: 1 | BR5: 1 | BS5: 1 | BT5: 1
A6: VA03 | B6: MTT CURICO | C6: 1 | D6: 1 | E6: 1 | F6: 0 | G6: 0 | H6: 0 | I6: 0 | J6: 0 | K6: 0 | L6: 0 | M6: 0 | N6: 0 | O6: 1 | P6: 0 | Q6: 0 | R6: 0 | S6: 0 | T6: 0 | U6: 1 | V6: 0 | W6: 0 | X6: 1 | Y6: 1 | Z6: 1 | AA6: 1 | AB6: 1 | AC6: 1 | AD6: 0 | AE6: 0 | AF6: 1 | AG6: 1 | AH6: 1 | AI6: 1 | AJ6: 1 | AK6: 1 | AL6: 1 | AM6: 1 | AN6: 1 | AO6: 1 | AP6: 1 | AQ6: 1 | AR6: 1 | AS6: 1 | AT6: 1 | AU6: 1 | AV6: 1 | AW6: 1 | AX6: 1 | AY6: 1 | AZ6: 1 | BA6: 1 | BB6: 1 | BC6: 1 | BD6: 1 | BE6: 1 | BF6: 1 | BG6: 1 | BH6: 1 | BI6: 1 | BJ6: 1 | BK6: 1 | BL6: 1 | BM6: 1 | BN6: 1 | BO6: 1 | BP6: 1 | BQ6: 1 | BR6: 1 | BS6: 1 | BT6: 1
A7: VA04 | B7: MTT TALCAHUANO | C7: 1 | D7: 1 | E7: 1 | F7: 0 | G7: 0 | H7: 0 | I7: 0 | J7: 0 | K7: 0 | L7: 0 | M7: 0 | N7: 0 | O7: 1 | P7: 0 | Q7: 0 | R7: 0 | S7: 0 | T7: 0 | U7: 1 | V7: 0 | W7: 0 | X7: 1 | Y7: 1 | Z7: 1 | AA7: 1 | AB7: 1 | AC7: 1 | AD7: 0 | AE7: 0 | AF7: 1 | AG7: 1 | AH7: 1 | AI7: 1 | AJ7: 1 | AK7: 1 | AL7: 1 | AM7: 1 | AN7: 1 | AO7: 1 | AP7: 1 | AQ7: 1 | AR7: 1 | AS7: 1 | AT7: 1 | AU7: 1 | AV7: 1 | AW7: 1 | AX7: 1 | AY7: 1 | AZ7: 1 | BA7: 1 | BB7: 1 | BC7: 1 | BD7: 1 | BE7: 1 | BF7: 1 | BG7: 1 | BH7: 1 | BI7: 1 | BJ7: 1 | BK7: 1 | BL7: 1 | BM7: 1 | BN7: 1 | BO7: 1 | BP7: 1 | BQ7: 1 | BR7: 1 | BS7: 1 | BT7: 1
A8: VA05 | B8: MTT TEMUCO | C8: 1 | D8: 1 | E8: 1 | F8: 0 | G8: 0 | H8: 0 | I8: 0 | J8: 0 | K8: 0 | L8: 0 | M8: 0 | N8: 0 | O8: 1 | P8: 0 | Q8: 0 | R8: 0 | S8: 0 | T8: 0 | U8: 1 | V8: 0 | W8: 0 | X8: 1 | Y8: 1 | Z8: 1 | AA8: 1 | AB8: 1 | AC8: 1 | AD8: 0 | AE8: 0 | AF8: 1 | AG8: 1 | AH8: 1 | AI8: 1 | AJ8: 1 | AK8: 1 | AL8: 1 | AM8: 1 | AN8: 1 | AO8: 1 | AP8: 1 | AQ8: 1 | AR8: 1 | AS8: 1 | AT8: 1 | AU8: 1 | AV8: 1 | AW8: 1 | AX8: 1 | AY8: 1 | AZ8: 1 | BA8: 1 | BB8: 1 | BC8: 1 | BD8: 1 | BE8: 1 | BF8: 1 | BG8: 1 | BH8: 1 | BI8: 1 | BJ8: 1 | BK8: 1 | BL8: 1 | BM8: 1 | BN8: 1 | BO8: 1 | BP8: 1 | BQ8: 1 | BR8: 1 | BS8: 1 | BT8: 1
A9: VA06 | B9: MTT PUERTO MONTT | C9: 1 | D9: 1 | E9: 1 | F9: 0 | G9: 0 | H9: 0 | I9: 0 | J9: 0 | K9: 0 | L9: 0 | M9: 0 | N9: 0 | O9: 1 | P9: 0 | Q9: 0 | R9: 0 | S9: 0 | T9: 0 | U9: 1 | V9: 0 | W9: 0 | X9: 1 | Y9: 1 | Z9: 1 | AA9: 1 | AB9: 1 | AC9: 1 | AD9: 0 | AE9: 0 | AF9: 1 | AG9: 1 | AH9: 1 | AI9: 1 | AJ9: 1 | AK9: 1 | AL9: 1 | AM9: 1 | AN9: 1 | AO9: 1 | AP9: 1 | AQ9: 1 | AR9: 1 | AS9: 1 | AT9: 1 | AU9: 1 | AV9: 1 | AW9: 1 | AX9: 1 | AY9: 1 | AZ9: 1 | BA9: 1 | BB9: 1 | BC9: 1 | BD9: 1 | BE9: 1 | BF9: 1 | BG9: 1 | BH9: 1 | BI9: 1 | BJ9: 1 | BK9: 1 | BL9: 1 | BM9: 1 | BN9: 1 | BO9: 1 | BP9: 1 | BQ9: 1 | BR9: 1 | BS9: 1 | BT9: 1
A10: VA07 | B10: MTT IMPORTACIONES | C10: 0 | D10: 0 | E10: 0 | F10: 0 | G10: 0 | H10: 0 | I10: 0 | J10: 0 | K10: 0 | L10: 0 | M10: 0 | N10: 0 | O10: 0 | P10: 0 | Q10: 0 | R10: 0 | S10: 0 | T10: 0 | U10: 0 | V10: 0 | W10: 0 | X10: 0 | Y10: 0 | Z10: 0 | AA10: 0 | AB10: 0 | AC10: 0 | AD10: 0 | AE10: 0 | AF10: 0 | AG10: 0 | AH10: 0 | AI10: 0 | AJ10: 0 | AK10: 0 | AL10: 0 | AM10: 0 | AN10: 0 | AO10: 0 | AP10: 0 | AQ10: 0 | AR10: 0 | AS10: 0 | AT10: 0 | AU10: 0 | AV10: 0 | AW10: 0 | AX10: 0 | AY10: 0 | AZ10: 0 | BA10: 0 | BB10: 0 | BC10: 0 | BD10: 0 | BE10: 0 | BF10: 0 | BG10: 0 | BH10: 0 | BI10: 0 | BJ10: 0 | BK10: 0 | BL10: 0 | BM10: 0 | BN10: 0 | BO10: 0 | BP10: 0 | BQ10: 0 | BR10: 0 | BS10: 0 | BT10: 0
A11: VC00 | B11: TTM QUILICURA | C11: 0 | D11: 0 | E11: 0 | F11: 1 | G11: 1 | H11: 1 | I11: 1 | J11: 1 | K11: 1 | L11: 0 | M11: 0 | N11: 0 | O11: 0 | P11: 0 | Q11: 0 | R11: 0 | S11: 0 | T11: 0 | U11: 0 | V11: 0 | W11: 0 | X11: 0 | Y11: 0 | Z11: 0 | AA11: 0 | AB11: 1 | AC11: 0 | AD11: 1 | AE11: 1 | AF11: 1 | AG11: 0 | AH11: 0 | AI11: 0 | AJ11: 0 | AK11: 0 | AL11: 0 | AM11: 0 | AN11: 0 | AO11: 0 | AP11: 0 | AQ11: 0 | AR11: 0 | AS11: 0 | AT11: 0 | AU11: 0 | AV11: 0 | AW11: 0 | AX11: 0 | AY11: 0 | AZ11: 0 | BA11: 0 | BB11: 0 | BC11: 0 | BD11: 0 | BE11: 0 | BF11: 0 | BG11: 0 | BH11: 0 | BI11: 0 | BJ11: 0 | BK11: 0 | BL11: 0 | BM11: 0 | BN11: 0 | BO11: 0 | BP11: 0 | BQ11: 0 | BR11: 0 | BS11: 0 | BT11: 0
A12: VC01 | B12: TTM CALAMA | C12: 0 | D12: 0 | E12: 0 | F12: 1 | G12: 1 | H12: 1 | I12: 1 | J12: 1 | K12: 1 | L12: 0 | M12: 0 | N12: 0 | O12: 0 | P12: 0 | Q12: 0 | R12: 0 | S12: 0 | T12: 0 | U12: 0 | V12: 0 | W12: 0 | X12: 0 | Y12: 0 | Z12: 0 | AA12: 0 | AB12: 1 | AC12: 0 | AD12: 1 | AE12: 1 | AF12: 1 | AG12: 0 | AH12: 0 | AI12: 0 | AJ12: 0 | AK12: 0 | AL12: 0 | AM12: 0 | AN12: 0 | AO12: 0 | AP12: 0 | AQ12: 0 | AR12: 0 | AS12: 0 | AT12: 0 | AU12: 0 | AV12: 0 | AW12: 0 | AX12: 0 | AY12: 0 | AZ12: 0 | BA12: 0 | BB12: 0 | BC12: 0 | BD12: 0 | BE12: 0 | BF12: 0 | BG12: 0 | BH12: 0 | BI12: 0 | BJ12: 0 | BK12: 0 | BL12: 0 | BM12: 0 | BN12: 0 | BO12: 0 | BP12: 0 | BQ12: 0 | BR12: 0 | BS12: 0 | BT12: 0
A13: VC02 | B13: TTM ANTOFAGASTA | C13: 0 | D13: 0 | E13: 0 | F13: 1 | G13: 1 | H13: 1 | I13: 1 | J13: 1 | K13: 1 | L13: 0 | M13: 0 | N13: 0 | O13: 0 | P13: 0 | Q13: 0 | R13: 0 | S13: 0 | T13: 0 | U13: 0 | V13: 0 | W13: 0 | X13: 0 | Y13: 0 | Z13: 0 | AA13: 0 | AB13: 1 | AC13: 0 | AD13: 1 | AE13: 1 | AF13: 1 | AG13: 0 | AH13: 0 | AI13: 0 | AJ13: 0 | AK13: 0 | AL13: 0 | AM13: 0 | AN13: 0 | AO13: 0 | AP13: 0 | AQ13: 0 | AR13: 0 | AS13: 0 | AT13: 0 | AU13: 0 | AV13: 0 | AW13: 0 | AX13: 0 | AY13: 0 | AZ13: 0 | BA13: 0 | BB13: 0 | BC13: 0 | BD13: 0 | BE13: 0 | BF13: 0 | BG13: 0 | BH13: 0 | BI13: 0 | BJ13: 0 | BK13: 0 | BL13: 0 | BM13: 0 | BN13: 0 | BO13: 0 | BP13: 0 | BQ13: 0 | BR13: 0 | BS13: 0 | BT13: 0
