Workbook

Sheet INPUT
A1: FILIAL CODIGO | B1: TIPO MATERIAL | C1: TEXTO BREVE CALCULADO (MAX 40) | D1: NPF CALCULADO (MAX 30) | E1: MODELO | F1: VERSION | G1: CILINDRADA | H1: COMBUSTIBLE | I1: TRACCION | J1: TRANSMISION | K1: POTENCIA BATERIA (solo si ELECTRICO) | L1: GRUPO ARTICULO | M1: NOMBRE JERARQUIA | N1: NOMBRE MARCA | O1: NOMBRE FABRICANTE | P1: GRUPO IMPUTACION | Q1: LARGO TEXTO BREVE (máx 40) | R1: LARGO NPF (máx 30)
A2: Maco Tattersall | B2: CAMIONES | C2: =_xlfn.LET(_xlpm.comb,_xlfn.XLOOKUP(H2,NPF!$A$4:$A$10,NPF!$B$4:$B$10,""),_xlpm.trans,_xlfn.XLOOKUP(J2,NPF!$D$4:$D$7,NPF!$E$4:$E$7,""),_xlpm.kwh,IF(AND(ISNUMBER(K2),OR(_xlpm.comb="BEV",_xlpm.comb="PHEV",_xlpm.comb="MHEV")),ROUND(K2,0)&"KWH",""),_xlpm.dec,1,_xlpm.cil,IF(OR(_xlpm.comb="BEV",P2="Motos",P2="Cuatrimotos",G2=""),"",SUBSTITUTE(FIXED(G2/1000,_xlpm.dec,TRUE),",",".")&"L"),IF(E2="","",UPPER(_xlfn.TEXTJOIN(" ",TRUE,E2,F2,_xlpm.cil,_xlpm.kwh,_xlpm.comb,I2,_xlpm.trans)))) -> CHUCHU PLUSS 15.0L DSL 6X2 MT | D2: {=_xlfn.LET(_xlpm.comb,_xlfn.XLOOKUP(H2,NPF!$A$4:$A$10,NPF!$B$4:$B$10,""),_xlpm.trans,_xlfn.XLOOKUP(J2,NPF!$D$4:$D$7,NPF!$E$4:$E$7,""),_xlpm.orig,NPF!$W$4:$W$33,_xlpm.abr,NPF!$X$4:$X$33,_xlpm.txt,_xlfn.REDUCE(UPPER(TRIM(E2&" "&F2)),_xlfn.SEQUENCE(ROWS(_xlpm.orig)),_xlfn.LAMBDA(_xlpm.a,_xlpm.i,IF(INDEX(_xlpm.orig,_xlpm.i)="",_xlpm.a,SUBSTITUTE(_xlpm.a,UPPER(INDEX(_xlpm.orig,_xlpm.i)),INDEX(_xlpm.abr,_xlpm.i))))),_xlpm.mv,SUBSTITUTE(SUBSTITUTE(SUBSTITUTE(_xlpm.txt," ",""),"(",""),")",""),_xlpm.kwh,IF(AND(ISNUMBER(K2),OR(_xlpm.comb="BEV",_xlpm.comb="PHEV",_xlpm.comb="MHEV")),ROUND(K2,0)&"KWH",""),_xlpm.dec,1,_xlpm.cil,IF(OR(_xlpm.comb="BEV",P2="Motos",P2="Cuatrimotos",G2=""),"",SUBSTITUTE(FIXED(G2/1000,_xlpm.dec,TRUE),",",".")&"L"),_xlpm.modelo,_xlpm.mv&_xlpm.kwh,_xlpm.res,IF(B2="CAMIONES",_xlfn.TEXTJOIN("-",TRUE,_xlpm.modelo,_xlpm.cil,_xlpm.comb,UPPER(I2),_xlpm.trans),IF(B2="VEHICULOS",_xlfn.TEXTJOIN("-",TRUE,_xlpm.modelo,_xlpm.comb,_xlpm.cil,LOWER(I2),_xlpm.trans),"Elija TIPO MATERIAL")),IF(E2="","",_xlpm.res))} -> CHUCHUPLUSS-15.0L-DSL-6X2-MT | E2: CHUCHU | F2: PLUSS | G2: 15000 | H2: DIESEL | I2: 6x2 | J2: Mecanica (MT) | L2: CAMIONES | M2: DONGFENG CAM. UNIDADES - DIESEL - MEDIANOS | N2: DONGFENG | O2: DFAC | P2: Unidad Nueva | Q2: =IF(C2="","",LEN(C2)) -> 29 | R2: =IF(D2="","",LEN(D2)) -> 28
C3: =_xlfn.LET(_xlpm.comb,_xlfn.XLOOKUP(H3,NPF!$A$4:$A$10,NPF!$B$4:$B$10,""),_xlpm.trans,_xlfn.XLOOKUP(J3,NPF!$D$4:$D$7,NPF!$E$4:$E$7,""),_xlpm.kwh,IF(AND(ISNUMBER(K3),OR(_xlpm.comb="BEV",_xlpm.comb="PHEV",_xlpm.comb="MHEV")),ROUND(K3,0)&"KWH",""),_xlpm.dec,1,_xlpm.cil,IF(OR(_xlpm.comb="BEV",P3="Motos",P3="Cuatrimotos",G3=""),"",SUBSTITUTE(FIXED(G3/1000,_xlpm.dec,TRUE),",",".")&"L"),IF(E3="","",UPPER(_xlfn.TEXTJOIN(" ",TRUE,E3,F3,_xlpm.cil,_xlpm.kwh,_xlpm.comb,I3,_xlpm.trans)))) | D3: {=_xlfn.LET(_xlpm.comb,_xlfn.XLOOKUP(H3,NPF!$A$4:$A$10,NPF!$B$4:$B$10,""),_xlpm.trans,_xlfn.XLOOKUP(J3,NPF!$D$4:$D$7,NPF!$E$4:$E$7,""),_xlpm.orig,NPF!$W$4:$W$33,_xlpm.abr,NPF!$X$4:$X$33,_xlpm.txt,_xlfn.REDUCE(UPPER(TRIM(E3&" "&F3)),_xlfn.SEQUENCE(ROWS(_xlpm.orig)),_xlfn.LAMBDA(_xlpm.a,_xlpm.i,IF(INDEX(_xlpm.orig,_xlpm.i)="",_xlpm.a,SUBSTITUTE(_xlpm.a,UPPER(INDEX(_xlpm.orig,_xlpm.i)),INDEX(_xlpm.abr,_xlpm.i))))),_xlpm.mv,SUBSTITUTE(SUBSTITUTE(SUBSTITUTE(_xlpm.txt," ",""),"(",""),")",""),_xlpm.kwh,IF(AND(ISNUMBER(K3),OR(_xlpm.comb="BEV",_xlpm.comb="PHEV",_xlpm.comb="MHEV")),ROUND(K3,0)&"KWH",""),_xlpm.dec,1,_xlpm.cil,IF(OR(_xlpm.comb="BEV",P3="Motos",P3="Cuatrimotos",G3=""),"",SUBSTITUTE(FIXED(G3/1000,_xlpm.dec,TRUE),",",".")&"L"),_xlpm.modelo,_xlpm.mv&_xlpm.kwh,_xlpm.res,IF(B3="CAMIONES",_xlfn.TEXTJOIN("-",TRUE,_xlpm.modelo,_xlpm.cil,_xlpm.comb,UPPER(I3),_xlpm.trans),IF(B3="VEHICULOS",_xlfn.TEXTJOIN("-",TRUE,_xlpm.modelo,_xlpm.comb,_xlpm.cil,LOWER(I3),_xlpm.trans),"Elija TIPO MATERIAL")),IF(E3="","",_xlpm.res))} | Q3: =IF(C3="","",LEN(C3)) | R3: =IF(D3="","",LEN(D3))
C4: =_xlfn.LET(_xlpm.comb,_xlfn.XLOOKUP(H4,NPF!$A$4:$A$10,NPF!$B$4:$B$10,""),_xlpm.trans,_xlfn.XLOOKUP(J4,NPF!$D$4:$D$7,NPF!$E$4:$E$7,""),_xlpm.kwh,IF(AND(ISNUMBER(K4),OR(_xlpm.comb="BEV",_xlpm.comb="PHEV",_xlpm.comb="MHEV")),ROUND(K4,0)&"KWH",""),_xlpm.dec,1,_xlpm.cil,IF(OR(_xlpm.comb="BEV",P4="Motos",P4="Cuatrimotos",G4=""),"",SUBSTITUTE(FIXED(G4/1000,_xlpm.dec,TRUE),",",".")&"L"),IF(E4="","",UPPER(_xlfn.TEXTJOIN(" ",TRUE,E4,F4,_xlpm.cil,_xlpm.kwh,_xlpm.comb,I4,_xlpm.trans)))) | D4: {=_xlfn.LET(_xlpm.comb,_xlfn.XLOOKUP(H4,NPF!$A$4:$A$10,NPF!$B$4:$B$10,""),_xlpm.trans,_xlfn.XLOOKUP(J4,NPF!$D$4:$D$7,NPF!$E$4:$E$7,""),_xlpm.orig,NPF!$W$4:$W$33,_xlpm.abr,NPF!$X$4:$X$33,_xlpm.txt,_xlfn.REDUCE(UPPER(TRIM(E4&" "&F4)),_xlfn.SEQUENCE(ROWS(_xlpm.orig)),_xlfn.LAMBDA(_xlpm.a,_xlpm.i,IF(INDEX(_xlpm.orig,_xlpm.i)="",_xlpm.a,SUBSTITUTE(_xlpm.a,UPPER(INDEX(_xlpm.orig,_xlpm.i)),INDEX(_xlpm.abr,_xlpm.i))))),_xlpm.mv,SUBSTITUTE(SUBSTITUTE(SUBSTITUTE(_xlpm.txt," ",""),"(",""),")",""),_xlpm.kwh,IF(AND(ISNUMBER(K4),OR(_xlpm.comb="BEV",_xlpm.comb="PHEV",_xlpm.comb="MHEV")),ROUND(K4,0)&"KWH",""),_xlpm.dec,1,_xlpm.cil,IF(OR(_xlpm.comb="BEV",P4="Motos",P4="Cuatrimotos",G4=""),"",SUBSTITUTE(FIXED(G4/1000,_xlpm.dec,TRUE),",",".")&"L"),_xlpm.modelo,_xlpm.mv&_xlpm.kwh,_xlpm.res,IF(B4="CAMIONES",_xlfn.TEXTJOIN("-",TRUE,_xlpm.modelo,_xlpm.cil,_xlpm.comb,UPPER(I4),_xlpm.trans),IF(B4="VEHICULOS",_xlfn.TEXTJOIN("-",TRUE,_xlpm.modelo,_xlpm.comb,_xlpm.cil,LOWER(I4),_xlpm.trans),"Elija TIPO MATERIAL")),IF(E4="","",_xlpm.res))} | Q4: =IF(C4="","",LEN(C4)) | R4: =IF(D4="","",LEN(D4))
C5: =_xlfn.LET(_xlpm.comb,_xlfn.XLOOKUP(H5,NPF!$A$4:$A$10,NPF!$B$4:$B$10,""),_xlpm.trans,_xlfn.XLOOKUP(J5,NPF!$D$4:$D$7,NPF!$E$4:$E$7,""),_xlpm.kwh,IF(AND(ISNUMBER(K5),OR(_xlpm.comb="BEV",_xlpm.comb="PHEV",_xlpm.comb="MHEV")),ROUND(K5,0)&"KWH",""),_xlpm.dec,1,_xlpm.cil,IF(OR(_xlpm.comb="BEV",P5="Motos",P5="Cuatrimotos",G5=""),"",SUBSTITUTE(FIXED(G5/1000,_xlpm.dec,TRUE),",",".")&"L"),IF(E5="","",UPPER(_xlfn.TEXTJOIN(" ",TRUE,E5,F5,_xlpm.cil,_xlpm.kwh,_xlpm.comb,I5,_xlpm.trans)))) | D5: {=_xlfn.LET(_xlpm.comb,_xlfn.XLOOKUP(H5,NPF!$A$4:$A$10,NPF!$B$4:$B$10,""),_xlpm.trans,_xlfn.XLOOKUP(J5,NPF!$D$4:$D$7,NPF!$E$4:$E$7,""),_xlpm.orig,NPF!$W$4:$W$33,_xlpm.abr,NPF!$X$4:$X$33,_xlpm.txt,_xlfn.REDUCE(UPPER(TRIM(E5&" "&F5)),_xlfn.SEQUENCE(ROWS(_xlpm.orig)),_xlfn.LAMBDA(_xlpm.a,_xlpm.i,IF(INDEX(_xlpm.orig,_xlpm.i)="",_xlpm.a,SUBSTITUTE(_xlpm.a,UPPER(INDEX(_xlpm.orig,_xlpm.i)),INDEX(_xlpm.abr,_xlpm.i))))),_xlpm.mv,SUBSTITUTE(SUBSTITUTE(SUBSTITUTE(_xlpm.txt," ",""),"(",""),")",""),_xlpm.kwh,IF(AND(ISNUMBER(K5),OR(_xlpm.comb="BEV",_xlpm.comb="PHEV",_xlpm.comb="MHEV")),ROUND(K5,0)&"KWH",""),_xlpm.dec,1,_xlpm.cil,IF(OR(_xlpm.comb="BEV",P5="Motos",P5="Cuatrimotos",G5=""),"",SUBSTITUTE(FIXED(G5/1000,_xlpm.dec,TRUE),",",".")&"L"),_xlpm.modelo,_xlpm.mv&_xlpm.kwh,_xlpm.res,IF(B5="CAMIONES",_xlfn.TEXTJOIN("-",TRUE,_xlpm.modelo,_xlpm.cil,_xlpm.comb,UPPER(I5),_xlpm.trans),IF(B5="VEHICULOS",_xlfn.TEXTJOIN("-",TRUE,_xlpm.modelo,_xlpm.comb,_xlpm.cil,LOWER(I5),_xlpm.trans),"Elija TIPO MATERIAL")),IF(E5="","",_xlpm.res))} | Q5: =IF(C5="","",LEN(C5)) | R5: =IF(D5="","",LEN(D5))
C6: =_xlfn.LET(_xlpm.comb,_xlfn.XLOOKUP(H6,NPF!$A$4:$A$10,NPF!$B$4:$B$10,""),_xlpm.trans,_xlfn.XLOOKUP(J6,NPF!$D$4:$D$7,NPF!$E$4:$E$7,""),_xlpm.kwh,IF(AND(ISNUMBER(K6),OR(_xlpm.comb="BEV",_xlpm.comb="PHEV",_xlpm.comb="MHEV")),ROUND(K6,0)&"KWH",""),_xlpm.dec,1,_xlpm.cil,IF(OR(_xlpm.comb="BEV",P6="Motos",P6="Cuatrimotos",G6=""),"",SUBSTITUTE(FIXED(G6/1000,_xlpm.dec,TRUE),",",".")&"L"),IF(E6="","",UPPER(_xlfn.TEXTJOIN(" ",TRUE,E6,F6,_xlpm.cil,_xlpm.kwh,_xlpm.comb,I6,_xlpm.trans)))) | D6: {=_xlfn.LET(_xlpm.comb,_xlfn.XLOOKUP(H6,NPF!$A$4:$A$10,NPF!$B$4:$B$10,""),_xlpm.trans,_xlfn.XLOOKUP(J6,NPF!$D$4:$D$7,NPF!$E$4:$E$7,""),_xlpm.orig,NPF!$W$4:$W$33,_xlpm.abr,NPF!$X$4:$X$33,_xlpm.txt,_xlfn.REDUCE(UPPER(TRIM(E6&" "&F6)),_xlfn.SEQUENCE(ROWS(_xlpm.orig)),_xlfn.LAMBDA(_xlpm.a,_xlpm.i,IF(INDEX(_xlpm.orig,_xlpm.i)="",_xlpm.a,SUBSTITUTE(_xlpm.a,UPPER(INDEX(_xlpm.orig,_xlpm.i)),INDEX(_xlpm.abr,_xlpm.i))))),_xlpm.mv,SUBSTITUTE(SUBSTITUTE(SUBSTITUTE(_xlpm.txt," ",""),"(",""),")",""),_xlpm.kwh,IF(AND(ISNUMBER(K6),OR(_xlpm.comb="BEV",_xlpm.comb="PHEV",_xlpm.comb="MHEV")),ROUND(K6,0)&"KWH",""),_xlpm.dec,1,_xlpm.cil,IF(OR(_xlpm.comb="BEV",P6="Motos",P6="Cuatrimotos",G6=""),"",SUBSTITUTE(FIXED(G6/1000,_xlpm.dec,TRUE),",",".")&"L"),_xlpm.modelo,_xlpm.mv&_xlpm.kwh,_xlpm.res,IF(B6="CAMIONES",_xlfn.TEXTJOIN("-",TRUE,_xlpm.modelo,_xlpm.cil,_xlpm.comb,UPPER(I6),_xlpm.trans),IF(B6="VEHICULOS",_xlfn.TEXTJOIN("-",TRUE,_xlpm.modelo,_xlpm.comb,_xlpm.cil,LOWER(I6),_xlpm.trans),"Elija TIPO MATERIAL")),IF(E6="","",_xlpm.res))} | Q6: =IF(C6="","",LEN(C6)) | R6: =IF(D6="","",LEN(D6))
C7: =_xlfn.LET(_xlpm.comb,_xlfn.XLOOKUP(H7,NPF!$A$4:$A$10,NPF!$B$4:$B$10,""),_xlpm.trans,_xlfn.XLOOKUP(J7,NPF!$D$4:$D$7,NPF!$E$4:$E$7,""),_xlpm.kwh,IF(AND(ISNUMBER(K7),OR(_xlpm.comb="BEV",_xlpm.comb="PHEV",_xlpm.comb="MHEV")),ROUND(K7,0)&"KWH",""),_xlpm.dec,1,_xlpm.cil,IF(OR(_xlpm.comb="BEV",P7="Motos",P7="Cuatrimotos",G7=""),"",SUBSTITUTE(FIXED(G7/1000,_xlpm.dec,TRUE),",",".")&"L"),IF(E7="","",UPPER(_xlfn.TEXTJOIN(" ",TRUE,E7,F7,_xlpm.cil,_xlpm.kwh,_xlpm.comb,I7,_xlpm.trans)))) | D7: {=_xlfn.LET(_xlpm.comb,_xlfn.XLOOKUP(H7,NPF!$A$4:$A$10,NPF!$B$4:$B$10,""),_xlpm.trans,_xlfn.XLOOKUP(J7,NPF!$D$4:$D$7,NPF!$E$4:$E$7,""),_xlpm.orig,NPF!$W$4:$W$33,_xlpm.abr,NPF!$X$4:$X$33,_xlpm.txt,_xlfn.REDUCE(UPPER(TRIM(E7&" "&F7)),_xlfn.SEQUENCE(ROWS(_xlpm.orig)),_xlfn.LAMBDA(_xlpm.a,_xlpm.i,IF(INDEX(_xlpm.orig,_xlpm.i)="",_xlpm.a,SUBSTITUTE(_xlpm.a,UPPER(INDEX(_xlpm.orig,_xlpm.i)),INDEX(_xlpm.abr,_xlpm.i))))),_xlpm.mv,SUBSTITUTE(SUBSTITUTE(SUBSTITUTE(_xlpm.txt," ",""),"(",""),")",""),_xlpm.kwh,IF(AND(ISNUMBER(K7),OR(_xlpm.comb="BEV",_xlpm.comb="PHEV",_xlpm.comb="MHEV")),ROUND(K7,0)&"KWH",""),_xlpm.dec,1,_xlpm.cil,IF(OR(_xlpm.comb="BEV",P7="Motos",P7="Cuatrimotos",G7=""),"",SUBSTITUTE(FIXED(G7/1000,_xlpm.dec,TRUE),",",".")&"L"),_xlpm.modelo,_xlpm.mv&_xlpm.kwh,_xlpm.res,IF(B7="CAMIONES",_xlfn.TEXTJOIN("-",TRUE,_xlpm.modelo,_xlpm.cil,_xlpm.comb,UPPER(I7),_xlpm.trans),IF(B7="VEHICULOS",_xlfn.TEXTJOIN("-",TRUE,_xlpm.modelo,_xlpm.comb,_xlpm.cil,LOWER(I7),_xlpm.trans),"Elija TIPO MATERIAL")),IF(E7="","",_xlpm.res))} | Q7: =IF(C7="","",LEN(C7)) | R7: =IF(D7="","",LEN(D7))
C8: =_xlfn.LET(_xlpm.comb,_xlfn.XLOOKUP(H8,NPF!$A$4:$A$10,NPF!$B$4:$B$10,""),_xlpm.trans,_xlfn.XLOOKUP(J8,NPF!$D$4:$D$7,NPF!$E$4:$E$7,""),_xlpm.kwh,IF(AND(ISNUMBER(K8),OR(_xlpm.comb="BEV",_xlpm.comb="PHEV",_xlpm.comb="MHEV")),ROUND(K8,0)&"KWH",""),_xlpm.dec,1,_xlpm.cil,IF(OR(_xlpm.comb="BEV",P8="Motos",P8="Cuatrimotos",G8=""),"",SUBSTITUTE(FIXED(G8/1000,_xlpm.dec,TRUE),",",".")&"L"),IF(E8="","",UPPER(_xlfn.TEXTJOIN(" ",TRUE,E8,F8,_xlpm.cil,_xlpm.kwh,_xlpm.comb,I8,_xlpm.trans)))) | D8: {=_xlfn.LET(_xlpm.comb,_xlfn.XLOOKUP(H8,NPF!$A$4:$A$10,NPF!$B$4:$B$10,""),_xlpm.trans,_xlfn.XLOOKUP(J8,NPF!$D$4:$D$7,NPF!$E$4:$E$7,""),_xlpm.orig,NPF!$W$4:$W$33,_xlpm.abr,NPF!$X$4:$X$33,_xlpm.txt,_xlfn.REDUCE(UPPER(TRIM(E8&" "&F8)),_xlfn.SEQUENCE(ROWS(_xlpm.orig)),_xlfn.LAMBDA(_xlpm.a,_xlpm.i,IF(INDEX(_xlpm.orig,_xlpm.i)="",_xlpm.a,SUBSTITUTE(_xlpm.a,UPPER(INDEX(_xlpm.orig,_xlpm.i)),INDEX(_xlpm.abr,_xlpm.i))))),_xlpm.mv,SUBSTITUTE(SUBSTITUTE(SUBSTITUTE(_xlpm.txt," ",""),"(",""),")",""),_xlpm.kwh,IF(AND(ISNUMBER(K8),OR(_xlpm.comb="BEV",_xlpm.comb="PHEV",_xlpm.comb="MHEV")),ROUND(K8,0)&"KWH",""),_xlpm.dec,1,_xlpm.cil,IF(OR(_xlpm.comb="BEV",P8="Motos",P8="Cuatrimotos",G8=""),"",SUBSTITUTE(FIXED(G8/1000,_xlpm.dec,TRUE),",",".")&"L"),_xlpm.modelo,_xlpm.mv&_xlpm.kwh,_xlpm.res,IF(B8="CAMIONES",_xlfn.TEXTJOIN("-",TRUE,_xlpm.modelo,_xlpm.cil,_xlpm.comb,UPPER(I8),_xlpm.trans),IF(B8="VEHICULOS",_xlfn.TEXTJOIN("-",TRUE,_xlpm.modelo,_xlpm.comb,_xlpm.cil,LOWER(I8),_xlpm.trans),"Elija TIPO MATERIAL")),IF(E8="","",_xlpm.res))} | Q8: =IF(C8="","",LEN(C8)) | R8: =IF(D8="","",LEN(D8))
C9: =_xlfn.LET(_xlpm.comb,_xlfn.XLOOKUP(H9,NPF!$A$4:$A$10,NPF!$B$4:$B$10,""),_xlpm.trans,_xlfn.XLOOKUP(J9,NPF!$D$4:$D$7,NPF!$E$4:$E$7,""),_xlpm.kwh,IF(AND(ISNUMBER(K9),OR(_xlpm.comb="BEV",_xlpm.comb="PHEV",_xlpm.comb="MHEV")),ROUND(K9,0)&"KWH",""),_xlpm.dec,1,_xlpm.cil,IF(OR(_xlpm.comb="BEV",P9="Motos",P9="Cuatrimotos",G9=""),"",SUBSTITUTE(FIXED(G9/1000,_xlpm.dec,TRUE),",",".")&"L"),IF(E9="","",UPPER(_xlfn.TEXTJOIN(" ",TRUE,E9,F9,_xlpm.cil,_xlpm.kwh,_xlpm.comb,I9,_xlpm.trans)))) | D9: {=_xlfn.LET(_xlpm.comb,_xlfn.XLOOKUP(H9,NPF!$A$4:$A$10,NPF!$B$4:$B$10,""),_xlpm.trans,_xlfn.XLOOKUP(J9,NPF!$D$4:$D$7,NPF!$E$4:$E$7,""),_xlpm.orig,NPF!$W$4:$W$33,_xlpm.abr,NPF!$X$4:$X$33,_xlpm.txt,_xlfn.REDUCE(UPPER(TRIM(E9&" "&F9)),_xlfn.SEQUENCE(ROWS(_xlpm.orig)),_xlfn.LAMBDA(_xlpm.a,_xlpm.i,IF(INDEX(_xlpm.orig,_xlpm.i)="",_xlpm.a,SUBSTITUTE(_xlpm.a,UPPER(INDEX(_xlpm.orig,_xlpm.i)),INDEX(_xlpm.abr,_xlpm.i))))),_xlpm.mv,SUBSTITUTE(SUBSTITUTE(SUBSTITUTE(_xlpm.txt," ",""),"(",""),")",""),_xlpm.kwh,IF(AND(ISNUMBER(K9),OR(_xlpm.comb="BEV",_xlpm.comb="PHEV",_xlpm.comb="MHEV")),ROUND(K9,0)&"KWH",""),_xlpm.dec,1,_xlpm.cil,IF(OR(_xlpm.comb="BEV",P9="Motos",P9="Cuatrimotos",G9=""),"",SUBSTITUTE(FIXED(G9/1000,_xlpm.dec,TRUE),",",".")&"L"),_xlpm.modelo,_xlpm.mv&_xlpm.kwh,_xlpm.res,IF(B9="CAMIONES",_xlfn.TEXTJOIN("-",TRUE,_xlpm.modelo,_xlpm.cil,_xlpm.comb,UPPER(I9),_xlpm.trans),IF(B9="VEHICULOS",_xlfn.TEXTJOIN("-",TRUE,_xlpm.modelo,_xlpm.comb,_xlpm.cil,LOWER(I9),_xlpm.trans),"Elija TIPO MATERIAL")),IF(E9="","",_xlpm.res))} | Q9: =IF(C9="","",LEN(C9)) | R9: =IF(D9="","",LEN(D9))
C10: =_xlfn.LET(_xlpm.comb,_xlfn.XLOOKUP(H10,NPF!$A$4:$A$10,NPF!$B$4:$B$10,""),_xlpm.trans,_xlfn.XLOOKUP(J10,NPF!$D$4:$D$7,NPF!$E$4:$E$7,""),_xlpm.kwh,IF(AND(ISNUMBER(K10),OR(_xlpm.comb="BEV",_xlpm.comb="PHEV",_xlpm.comb="MHEV")),ROUND(K10,0)&"KWH",""),_xlpm.dec,1,_xlpm.cil,IF(OR(_xlpm.comb="BEV",P10="Motos",P10="Cuatrimotos",G10=""),"",SUBSTITUTE(FIXED(G10/1000,_xlpm.dec,TRUE),",",".")&"L"),IF(E10="","",UPPER(_xlfn.TEXTJOIN(" ",TRUE,E10,F10,_xlpm.cil,_xlpm.kwh,_xlpm.comb,I10,_xlpm.trans)))) | D10: {=_xlfn.LET(_xlpm.comb,_xlfn.XLOOKUP(H10,NPF!$A$4:$A$10,NPF!$B$4:$B$10,""),_xlpm.trans,_xlfn.XLOOKUP(J10,NPF!$D$4:$D$7,NPF!$E$4:$E$7,""),_xlpm.orig,NPF!$W$4:$W$33,_xlpm.abr,NPF!$X$4:$X$33,_xlpm.txt,_xlfn.REDUCE(UPPER(TRIM(E10&" "&F10)),_xlfn.SEQUENCE(ROWS(_xlpm.orig)),_xlfn.LAMBDA(_xlpm.a,_xlpm.i,IF(INDEX(_xlpm.orig,_xlpm.i)="",_xlpm.a,SUBSTITUTE(_xlpm.a,UPPER(INDEX(_xlpm.orig,_xlpm.i)),INDEX(_xlpm.abr,_xlpm.i))))),_xlpm.mv,SUBSTITUTE(SUBSTITUTE(SUBSTITUTE(_xlpm.txt," ",""),"(",""),")",""),_xlpm.kwh,IF(AND(ISNUMBER(K10),OR(_xlpm.comb="BEV",_xlpm.comb="PHEV",_xlpm.comb="MHEV")),ROUND(K10,0)&"KWH",""),_xlpm.dec,1,_xlpm.cil,IF(OR(_xlpm.comb="BEV",P10="Motos",P10="Cuatrimotos",G10=""),"",SUBSTITUTE(FIXED(G10/1000,_xlpm.dec,TRUE),",",".")&"L"),_xlpm.modelo,_xlpm.mv&_xlpm.kwh,_xlpm.res,IF(B10="CAMIONES",_xlfn.TEXTJOIN("-",TRUE,_xlpm.modelo,_xlpm.cil,_xlpm.comb,UPPER(I10),_xlpm.trans),IF(B10="VEHICULOS",_xlfn.TEXTJOIN("-",TRUE,_xlpm.modelo,_xlpm.comb,_xlpm.cil,LOWER(I10),_xlpm.trans),"Elija TIPO MATERIAL")),IF(E10="","",_xlpm.res))} | Q10: =IF(C10="","",LEN(C10)) | R10: =IF(D10="","",LEN(D10))
C11: =_xlfn.LET(_xlpm.comb,_xlfn.XLOOKUP(H11,NPF!$A$4:$A$10,NPF!$B$4:$B$10,""),_xlpm.trans,_xlfn.XLOOKUP(J11,NPF!$D$4:$D$7,NPF!$E$4:$E$7,""),_xlpm.kwh,IF(AND(ISNUMBER(K11),OR(_xlpm.comb="BEV",_xlpm.comb="PHEV",_xlpm.comb="MHEV")),ROUND(K11,0)&"KWH",""),_xlpm.dec,1,_xlpm.cil,IF(OR(_xlpm.comb="BEV",P11="Motos",P11="Cuatrimotos",G11=""),"",SUBSTITUTE(FIXED(G11/1000,_xlpm.dec,TRUE),",",".")&"L"),IF(E11="","",UPPER(_xlfn.TEXTJOIN(" ",TRUE,E11,F11,_xlpm.cil,_xlpm.kwh,_xlpm.comb,I11,_xlpm.trans)))) | D11: {=_xlfn.LET(_xlpm.comb,_xlfn.XLOOKUP(H11,NPF!$A$4:$A$10,NPF!$B$4:$B$10,""),_xlpm.trans,_xlfn.XLOOKUP(J11,NPF!$D$4:$D$7,NPF!$E$4:$E$7,""),_xlpm.orig,NPF!$W$4:$W$33,_xlpm.abr,NPF!$X$4:$X$33,_xlpm.txt,_xlfn.REDUCE(UPPER(TRIM(E11&" "&F11)),_xlfn.SEQUENCE(ROWS(_xlpm.orig)),_xlfn.LAMBDA(_xlpm.a,_xlpm.i,IF(INDEX(_xlpm.orig,_xlpm.i)="",_xlpm.a,SUBSTITUTE(_xlpm.a,UPPER(INDEX(_xlpm.orig,_xlpm.i)),INDEX(_xlpm.abr,_xlpm.i))))),_xlpm.mv,SUBSTITUTE(SUBSTITUTE(SUBSTITUTE(_xlpm.txt," ",""),"(",""),")",""),_xlpm.kwh,IF(AND(ISNUMBER(K11),OR(_xlpm.comb="BEV",_xlpm.comb="PHEV",_xlpm.comb="MHEV")),ROUND(K11,0)&"KWH",""),_xlpm.dec,1,_xlpm.cil,IF(OR(_xlpm.comb="BEV",P11="Motos",P11="Cuatrimotos",G11=""),"",SUBSTITUTE(FIXED(G11/1000,_xlpm.dec,TRUE),",",".")&"L"),_xlpm.modelo,_xlpm.mv&_xlpm.kwh,_xlpm.res,IF(B11="CAMIONES",_xlfn.TEXTJOIN("-",TRUE,_xlpm.modelo,_xlpm.cil,_xlpm.comb,UPPER(I11),_xlpm.trans),IF(B11="VEHICULOS",_xlfn.TEXTJOIN("-",TRUE,_xlpm.modelo,_xlpm.comb,_xlpm.cil,LOWER(I11),_xlpm.trans),"Elija TIPO MATERIAL")),IF(E11="","",_xlpm.res))} | Q11: =IF(C11="","",LEN(C11)) | R11: =IF(D11="","",LEN(D11))
C12: =_xlfn.LET(_xlpm.comb,_xlfn.XLOOKUP(H12,NPF!$A$4:$A$10,NPF!$B$4:$B$10,""),_xlpm.trans,_xlfn.XLOOKUP(J12,NPF!$D$4:$D$7,NPF!$E$4:$E$7,""),_xlpm.kwh,IF(AND(ISNUMBER(K12),OR(_xlpm.comb="BEV",_xlpm.comb="PHEV",_xlpm.comb="MHEV")),ROUND(K12,0)&"KWH",""),_xlpm.dec,1,_xlpm.cil,IF(OR(_xlpm.comb="BEV",P12="Motos",P12="Cuatrimotos",G12=""),"",SUBSTITUTE(FIXED(G12/1000,_xlpm.dec,TRUE),",",".")&"L"),IF(E12="","",UPPER(_xlfn.TEXTJOIN(" ",TRUE,E12,F12,_xlpm.cil,_xlpm.kwh,_xlpm.comb,I12,_xlpm.trans)))) | D12: {=_xlfn.LET(_xlpm.comb,_xlfn.XLOOKUP(H12,NPF!$A$4:$A$10,NPF!$B$4:$B$10,""),_xlpm.trans,_xlfn.XLOOKUP(J12,NPF!$D$4:$D$7,NPF!$E$4:$E$7,""),_xlpm.orig,NPF!$W$4:$W$33,_xlpm.abr,NPF!$X$4:$X$33,_xlpm.txt,_xlfn.REDUCE(UPPER(TRIM(E12&" "&F12)),_xlfn.SEQUENCE(ROWS(_xlpm.orig)),_xlfn.LAMBDA(_xlpm.a,_xlpm.i,IF(INDEX(_xlpm.orig,_xlpm.i)="",_xlpm.a,SUBSTITUTE(_xlpm.a,UPPER(INDEX(_xlpm.orig,_xlpm.i)),INDEX(_xlpm.abr,_xlpm.i))))),_xlpm.mv,SUBSTITUTE(SUBSTITUTE(SUBSTITUTE(_xlpm.txt," ",""),"(",""),")",""),_xlpm.kwh,IF(AND(ISNUMBER(K12),OR(_xlpm.comb="BEV",_xlpm.comb="PHEV",_xlpm.comb="MHEV")),ROUND(K12,0)&"KWH",""),_xlpm.dec,1,_xlpm.cil,IF(OR(_xlpm.comb="BEV",P12="Motos",P12="Cuatrimotos",G12=""),"",SUBSTITUTE(FIXED(G12/1000,_xlpm.dec,TRUE),",",".")&"L"),_xlpm.modelo,_xlpm.mv&_xlpm.kwh,_xlpm.res,IF(B12="CAMIONES",_xlfn.TEXTJOIN("-",TRUE,_xlpm.modelo,_xlpm.cil,_xlpm.comb,UPPER(I12),_xlpm.trans),IF(B12="VEHICULOS",_xlfn.TEXTJOIN("-",TRUE,_xlpm.modelo,_xlpm.comb,_xlpm.cil,LOWER(I12),_xlpm.trans),"Elija TIPO MATERIAL")),IF(E12="","",_xlpm.res))} | Q12: =IF(C12="","",LEN(C12)) | R12: =IF(D12="","",LEN(D12))
C13: =_xlfn.LET(_xlpm.comb,_xlfn.XLOOKUP(H13,NPF!$A$4:$A$10,NPF!$B$4:$B$10,""),_xlpm.trans,_xlfn.XLOOKUP(J13,NPF!$D$4:$D$7,NPF!$E$4:$E$7,""),_xlpm.kwh,IF(AND(ISNUMBER(K13),OR(_xlpm.comb="BEV",_xlpm.comb="PHEV",_xlpm.comb="MHEV")),ROUND(K13,0)&"KWH",""),_xlpm.dec,1,_xlpm.cil,IF(OR(_xlpm.comb="BEV",P13="Motos",P13="Cuatrimotos",G13=""),"",SUBSTITUTE(FIXED(G13/1000,_xlpm.dec,TRUE),",",".")&"L"),IF(E13="","",UPPER(_xlfn.TEXTJOIN(" ",TRUE,E13,F13,_xlpm.cil,_xlpm.kwh,_xlpm.comb,I13,_xlpm.trans)))) | D13: {=_xlfn.LET(_xlpm.comb,_xlfn.XLOOKUP(H13,NPF!$A$4:$A$10,NPF!$B$4:$B$10,""),_xlpm.trans,_xlfn.XLOOKUP(J13,NPF!$D$4:$D$7,NPF!$E$4:$E$7,""),_xlpm.orig,NPF!$W$4:$W$33,_xlpm.abr,NPF!$X$4:$X$33,_xlpm.txt,_xlfn.REDUCE(UPPER(TRIM(E13&" "&F13)),_xlfn.SEQUENCE(ROWS(_xlpm.orig)),_xlfn.LAMBDA(_xlpm.a,_xlpm.i,IF(INDEX(_xlpm.orig,_xlpm.i)="",_xlpm.a,SUBSTITUTE(_xlpm.a,UPPER(INDEX(_xlpm.orig,_xlpm.i)),INDEX(_xlpm.abr,_xlpm.i))))),_xlpm.mv,SUBSTITUTE(SUBSTITUTE(SUBSTITUTE(_xlpm.txt," ",""),"(",""),")",""),_xlpm.kwh,IF(AND(ISNUMBER(K13),OR(_xlpm.comb="BEV",_xlpm.comb="PHEV",_xlpm.comb="MHEV")),ROUND(K13,0)&"KWH",""),_xlpm.dec,1,_xlpm.cil,IF(OR(_xlpm.comb="BEV",P13="Motos",P13="Cuatrimotos",G13=""),"",SUBSTITUTE(FIXED(G13/1000,_xlpm.dec,TRUE),",",".")&"L"),_xlpm.modelo,_xlpm.mv&_xlpm.kwh,_xlpm.res,IF(B13="CAMIONES",_xlfn.TEXTJOIN("-",TRUE,_xlpm.modelo,_xlpm.cil,_xlpm.comb,UPPER(I13),_xlpm.trans),IF(B13="VEHICULOS",_xlfn.TEXTJOIN("-",TRUE,_xlpm.modelo,_xlpm.comb,_xlpm.cil,LOWER(I13),_xlpm.trans),"Elija TIPO MATERIAL")),IF(E13="","",_xlpm.res))} | Q13: =IF(C13="","",LEN(C13)) | R13: =IF(D13="","",LEN(D13))
C14: =_xlfn.LET(_xlpm.comb,_xlfn.XLOOKUP(H14,NPF!$A$4:$A$10,NPF!$B$4:$B$10,""),_xlpm.trans,_xlfn.XLOOKUP(J14,NPF!$D$4:$D$7,NPF!$E$4:$E$7,""),_xlpm.kwh,IF(AND(ISNUMBER(K14),OR(_xlpm.comb="BEV",_xlpm.comb="PHEV",_xlpm.comb="MHEV")),ROUND(K14,0)&"KWH",""),_xlpm.dec,1,_xlpm.cil,IF(OR(_xlpm.comb="BEV",P14="Motos",P14="Cuatrimotos",G14=""),"",SUBSTITUTE(FIXED(G14/1000,_xlpm.dec,TRUE),",",".")&"L"),IF(E14="","",UPPER(_xlfn.TEXTJOIN(" ",TRUE,E14,F14,_xlpm.cil,_xlpm.kwh,_xlpm.comb,I14,_xlpm.trans)))) | D14: {=_xlfn.LET(_xlpm.comb,_xlfn.XLOOKUP(H14,NPF!$A$4:$A$10,NPF!$B$4:$B$10,""),_xlpm.trans,_xlfn.XLOOKUP(J14,NPF!$D$4:$D$7,NPF!$E$4:$E$7,""),_xlpm.orig,NPF!$W$4:$W$33,_xlpm.abr,NPF!$X$4:$X$33,_xlpm.txt,_xlfn.REDUCE(UPPER(TRIM(E14&" "&F14)),_xlfn.SEQUENCE(ROWS(_xlpm.orig)),_xlfn.LAMBDA(_xlpm.a,_xlpm.i,IF(INDEX(_xlpm.orig,_xlpm.i)="",_xlpm.a,SUBSTITUTE(_xlpm.a,UPPER(INDEX(_xlpm.orig,_xlpm.i)),INDEX(_xlpm.abr,_xlpm.i))))),_xlpm.mv,SUBSTITUTE(SUBSTITUTE(SUBSTITUTE(_xlpm.txt," ",""),"(",""),")",""),_xlpm.kwh,IF(AND(ISNUMBER(K14),OR(_xlpm.comb="BEV",_xlpm.comb="PHEV",_xlpm.comb="MHEV")),ROUND(K14,0)&"KWH",""),_xlpm.dec,1,_xlpm.cil,IF(OR(_xlpm.comb="BEV",P14="Motos",P14="Cuatrimotos",G14=""),"",SUBSTITUTE(FIXED(G14/1000,_xlpm.dec,TRUE),",",".")&"L"),_xlpm.modelo,_xlpm.mv&_xlpm.kwh,_xlpm.res,IF(B14="CAMIONES",_xlfn.TEXTJOIN("-",TRUE,_xlpm.modelo,_xlpm.cil,_xlpm.comb,UPPER(I14),_xlpm.trans),IF(B14="VEHICULOS",_xlfn.TEXTJOIN("-",TRUE,_xlpm.modelo,_xlpm.comb,_xlpm.cil,LOWER(I14),_xlpm.trans),"Elija TIPO MATERIAL")),IF(E14="","",_xlpm.res))} | Q14: =IF(C14="","",LEN(C14)) | R14: =IF(D14="","",LEN(D14))
... C200: =_xlfn.LET(_xlpm.comb,_xlfn.XLOOKUP(H200,NPF!$A$4:$A$10,NPF!$B$4:$B$10,""),_xlpm.trans,_xlfn.XLOOKUP(J200,NPF!$D$4:$D$7,NPF!$E$4:$E$7,""),_xlpm.kwh,IF(AND(ISNUMBER(K200),OR(_xlpm.comb="BEV",_xlpm.comb="PHEV",_xlpm.comb="MHEV")),ROUND(K200,0)&"KWH",""),_xlpm.dec,1,_xlpm.cil,IF(OR(_xlpm.comb="BEV",P200="Motos",P200="Cuatrimotos",G200=""),"",SUBSTITUTE(FIXED(G200/1000,_xlpm.dec,TRUE),",",".")&"L"),IF(E200="","",UPPER(_xlfn.TEXTJOIN(" ",TRUE,E200,F200,_xlpm.cil,_xlpm.kwh,_xlpm.comb,I200,_xlpm.trans)))) | D200: {=_xlfn.LET(_xlpm.comb,_xlfn.XLOOKUP(H200,NPF!$A$4:$A$10,NPF!$B$4:$B$10,""),_xlpm.trans,_xlfn.XLOOKUP(J200,NPF!$D$4:$D$7,NPF!$E$4:$E$7,""),_xlpm.orig,NPF!$W$4:$W$33,_xlpm.abr,NPF!$X$4:$X$33,_xlpm.txt,_xlfn.REDUCE(UPPER(TRIM(E200&" "&F200)),_xlfn.SEQUENCE(ROWS(_xlpm.orig)),_xlfn.LAMBDA(_xlpm.a,_xlpm.i,IF(INDEX(_xlpm.orig,_xlpm.i)="",_xlpm.a,SUBSTITUTE(_xlpm.a,UPPER(INDEX(_xlpm.orig,_xlpm.i)),INDEX(_xlpm.abr,_xlpm.i))))),_xlpm.mv,SUBSTITUTE(SUBSTITUTE(SUBSTITUTE(_xlpm.txt," ",""),"(",""),")",""),_xlpm.kwh,IF(AND(ISNUMBER(K200),OR(_xlpm.comb="BEV",_xlpm.comb="PHEV",_xlpm.comb="MHEV")),ROUND(K200,0)&"KWH",""),_xlpm.dec,1,_xlpm.cil,IF(OR(_xlpm.comb="BEV",P200="Motos",P200="Cuatrimotos",G200=""),"",SUBSTITUTE(FIXED(G200/1000,_xlpm.dec,TRUE),",",".")&"L"),_xlpm.modelo,_xlpm.mv&_xlpm.kwh,_xlpm.res,IF(B200="CAMIONES",_xlfn.TEXTJOIN("-",TRUE,_xlpm.modelo,_xlpm.cil,_xlpm.comb,UPPER(I200),_xlpm.trans),IF(B200="VEHICULOS",_xlfn.TEXTJOIN("-",TRUE,_xlpm.modelo,_xlpm.comb,_xlpm.cil,LOWER(I200),_xlpm.trans),"Elija TIPO MATERIAL")),IF(E200="","",_xlpm.res))} | Q200: =IF(C200="","",LEN(C200)) | R200: =IF(D200="","",LEN(D200))

Sheet NPF
A1: Tablas de conversión — se pueden ampliar agregando filas al final de cada tabla | W1: Abreviaciones de Modelo / Versión | AA1: Estándar de Nomenclatura NPF — referencia | AF1: Abreviaciones de Marca (Texto breve)
W2: Se aplican en orden de arriba hacia abajo sobre MODELO + VERSIÓN (en mayúsculas), antes de quitar espacios y paréntesis. Las más largas deben ir antes que las cortas (ej: LUX PLUS XL antes que LUX PLUS). Hay 30 filas disponibles. | AA2: Número de Parte del Fabricante — Migración SAP S/4HANA · Proyecto Integra. Límite SAP: 30 caracteres. | AF2: Se usa en el TEXTO BREVE. Si el MODELO ya empieza con la abreviatura (ej: DF-1016), la marca no se repite. Se puede ampliar hasta la fila 40.
A3: Combustible (SAP) | B3: Abrev. NPF | D3: Transmisión (SAP) | E3: Abrev. NPF | G3: Categoría Maquinaria | H3: Abrev. NPF | J3: Tracción | L3: Tipo Material | N3: Tipo Base (solo ZUSA) | Q3: Categorías sin cilindrada (motos/ATV) | S3: Categorías (lista desplegable) | U3: Decimales cilindrada | W3: Texto original | X3: Abrev. | Y3: Ejemplo aplicado | AF3: Marca (SAP) | AG3: Abrev. Texto breve
A4: GASOLINA | B4: GSL | D4: Mecanica (MT) | E4: MT | G4: APILADOR | H4: APIL | J4: 2x1 | L4: ZCAM | N4: ZMAQ | O4: MAQUINARIAS | Q4: Motocicleta | S4: TBC | U4: 1 | W4: HORIZON PRO | X4: HZPRO | Y4: RD6 DC HORIZON PRO → RD6DCHZPRO | AA4: 1. Fórmulas por tipo de material | AF4: DONGFENG | AG4: DF
A5: DIESEL | B5: DSL | D5: Automatica (AT) | E5: AT | G5: BIG TRUCK | H5: BGTRUCK | J5: 4x2 | L5: ZVEH | N5: ZCAM | O5: CAMIONES | Q5: Cuatrimoto | S5: Automovil | U5: 2 | W5: HYPER HALO | X5: HPHALO | Y5: 09 HYPER HALO → 09HPHALO | AA5: Tipo Material | AB5: Fórmula NPF | AC5: Ejemplo | AD5: Nota | AF5: FAW | AG5: FAW
A6: ELECTRICIDAD (BEV) | B6: BEV | D6: Automatizada (AMT) | E6: AMT | G6: CARGADOR FRONTAL | H6: CARG.FR | J6: 4x4 | L6: ZMAQ | N6: ZVEH | O6: VEHICULOS | S6: Camioneta | W6: LUX PLUS XL | X6: LPXL | Y6: DC LUX PLUS XL → DCLPXL | AA6: ZCAM — Camiones | AB6: [MODELO+VERSION]-[CIL]-[COMB]-[TRAC]-[TRANS] | AC6: DF-1823-6.7L-DSL-4X2-AT | AD6: Tracción en mayúscula (4X2). BEV sin cilindrada. | AF6: KYC | AG6: KYC
A7: Gasolina/Electricidad (PHEV) | B7: PHEV | D7: Doble embrague (DCT) | E7: DCT | G7: EXCAVADORA | H7: EXCAV | J7: 6x2 | L7: ZUSA | N7: ZUSA | O7: USADOS | S7: Comerciales | W7: LUX PLUS | X7: LP | Y7: DC LUX PLUS → DCLP | AA7: ZVEH — Vehículos | AB7: [MODELO+VERSION]-[COMB]-[CIL]-[TRAC]-[TRANS] | AC7: X3PROELITE-GSL-1.5L-4x2-AT | AD7: Tracción en minúscula (4x2). | AF7: LIFAN | AG7: LF
A8: Híbrido ligero (MHEV) | B8: MHEV | G8: GRUA | H8: GRUA | J8: 6x4 | S8: Station Wagon | W8: DIGNITY | X8: DIG | Y8: DC DIGNITY → DCDIG | AA8: ZVEH — BEV puro | AB8: [MODELO+VERSION]-EV-[TRAC]-[TRANS] | AC8: RD6DC86KWH-BEV-4x2-AT | AD8: Sin cilindrada, kWh va en modelo. | AF8: LIFAN AUTO | AG8: LFA
A9: GASOLINA / GLP | B9: DUAL | G9: MINIRETROEXCAVADORA | H9: MINIRET | J9: 8x4 | S9: Motocicleta | W9: ULTRA | X9: ULT | Y9: DC ULTRA → DCULT | AA9: ZVEH — PHEV/HEV/MHEV | AB9: [MODELO+VERSION+KWH]-[COMB]-[CIL]-[TRAC]-[TRANS] | AC9: RD6DCULT19KWH-PHEV-1.5L-4x4-AT | AD9: Lleva cilindrada (motor de combustión). | AF9: LINHAI | AG9: LH
A10: GLP | B10: GLP | G10: MOTONIVELADORA | H10: MOTONIV | J10: 10x4 | S10: Cuatrimoto | W10: TRUCK BOX | X10: TBOX | Y10: Truck DC Truck Box → TRKDCTBOX | AA10: ZVEH — Motos/ATV | AB10: [MODELO+VERSION]-[COMB]-[TRAC]-[TRANS] | AC10: LF125T-2VIII-GSL-2x1-MT | AD10: Sin cilindrada. | AF10: BASHAN | AG10: BSH
G11: PLATAFORMA | H11: PLAT | S11: APILADOR | W11: TRUCK | X11: TRK | Y11: Truck DC Truck Box → TRKDCTBOX | AA11: ZMAQ — Maquinaria | AB11: [CAT_ABREV]-[MODELO]-[COMB] | AC11: EXCAV-HMK220LC-DSL | AD11: Fabricante identificado en modelo. | AF11: INTERNATIONAL | AG11: INTL
G12: PORTACONTENEDOR | H12: PORTAC | S12: BIG TRUCK | W12: GRAND LION | X12: GLN | Y12: Grand Lion DC → GLNDC | AA12: ZUSA — Genérico | AB12: USADO-[TIPO] | AC12: USADO-CAM | AD12: Sin especificaciones. | AF12: LIVAN | AG12: LVN
G13: REACHTRUCK | H13: REACHTR | S13: CARGADOR FRONTAL | W13: TERRALORD | X13: TRLD | Y13: TERRALORD DC → TRLDDC | AA13: ZUSA — Específico | AB13: [fórmula del tipo]-U | AC13: DF-1417-3.8L-DSL-4X2-MT-U | AD13: Sufijo -U. | AF13: LYNK & CO | AG13: LYNK
G14: RETROEXCAVADORA | H14: RETROEX | S14: EXCAVADORA | W14: 19.1 KWH | X14: 19KWH | Y14: DC ULTRA 19.1 kWh → DCULT19KWH | AF14: RIDDARA | AG14: RD
G15: RODILLO COMPACTADOR | H15: RODILLO | S15: GRUA | AA15: 2. Cilindrada (cc → litros) | AF15: ZX | AG15: ZX
G16: TRANSPALETA | H16: TRANSP | S16: MINIRETROEXCAVADORA | AA16: • Se expresa en litros con 1 decimal: cc / 1000 redondeado (ej: 1969 → 2.0L, 2378 → 2.4L, 12520 → 12.5L). | AF16: OTRAS MARCAS | AG16: OTRAS
G17: MINIEXCAVADORA | H17: MEXCAV | S17: MOTONIVELADORA | AA17: • Usar 2 decimales (columna J = 2) cuando dos motores del mismo modelo redondearían igual (ej: 6690 → 6.69L vs 6700 → 6.7L).
G18: MINICARGADOR | H18: MCARG.FR | S18: PLATAFORMA | AA18: • Motos/cuatrimotos y BEV puros NO llevan cilindrada. PHEV/HEV/MHEV SÍ llevan.
G19: YARDTRUCK | H19: YARDT | S19: PORTACONTENEDOR
G20: REACHSTACKER | H20: REACHKER | S20: REACHTRUCK | AA20: 3. Reglas generales
G21: ORDER PICKER | H21: ORDERPICKER | S21: RETROEXCAVADORA | AA21: • Límite máximo: 30 caracteres (restricción SAP).
G22: EMPTY CONTAINER | H22: EMPCONTI | S22: RODILLO COMPACTADOR | AA22: • Separador: guión (-) entre cada bloque del NPF.
G23: GENERADOR | H23: GENER | S23: TRANSPALETA | AA23: • Modelo y versión se concatenan sin espacios; se eliminan los paréntesis (LF125T-2V(III) → LF125T-2VIII).
S24: MINIEXCAVADORA | AA24: • Todo en mayúsculas, excepto la L de litros (1.5L) y la tracción de ZVEH (4x2).
S25: MINICARGADOR | AA25: • Versiones largas se abrevian según la hoja Abreviaciones (objetivo: modelo+versión de 12–14 caracteres).
S26: YARDTRUCK | AA26: • Combustible, transmisión y categoría de maquinaria se abrevian según la hoja Tablas.
S27: REACHSTACKER | AA27: • Duplicados: si dos materiales generan el mismo NPF, usar 2 decimales en la cilindrada.
S28: ORDER PICKER
S29: EMPTY CONTAINER | AA29: Proyecto SAP Integra · Tattersall · Datos Maestros VMS
S30: GENERADOR

Sheet Diccionario Jerarquías
A1: Texto | B1: Nivel en la Jerarquía | C1: Nivel 1 | D1: Nivel 2 | E1: Nivel 3 | F1: Texto Jerarquía
A2: DONGFENG AUT. UNIDAD | B2: 1 | C2: 00017 | F2: DONGFENG AUT. UNIDAD
A3: DIESEL | B3: 2 | C3: 00017 | D3: 00003 | F3: DONGFENG AUT. UNIDAD - DIESEL
A4: COMERCIALES | B4: 3 | C4: 00017 | D4: 00003 | E4: 00000004 | F4: DONGFENG AUT. UNIDAD - DIESEL - COMERCIALES
A5: MOTO | B5: 3 | C5: 00017 | D5: 00003 | E5: 00000005 | F5: DONGFENG AUT. UNIDAD - DIESEL - MOTO
A6: PASAJEROS | B6: 3 | C6: 00017 | D6: 00003 | E6: 00000001 | F6: DONGFENG AUT. UNIDAD - DIESEL - PASAJEROS
A7: PICK-UP | B7: 3 | C7: 00017 | D7: 00003 | E7: 00000003 | F7: DONGFENG AUT. UNIDAD - DIESEL - PICK-UP
A8: STATION WAGON | B8: 3 | C8: 00017 | D8: 00003 | E8: 00000006 | F8: DONGFENG AUT. UNIDAD - DIESEL - STATION WAGON
A9: SUV | B9: 3 | C9: 00017 | D9: 00003 | E9: 00000002 | F9: DONGFENG AUT. UNIDAD - DIESEL - SUV
A10: ELECTRICOS | B10: 2 | C10: 00017 | D10: 00001 | F10: DONGFENG AUT. UNIDAD - ELECTRICOS
A11: COMERCIALES | B11: 3 | C11: 00017 | D11: 00001 | E11: 00000004 | F11: DONGFENG AUT. UNIDAD - ELECTRICOS - COMERCIALES
A12: MOTO | B12: 3 | C12: 00017 | D12: 00001 | E12: 00000005 | F12: DONGFENG AUT. UNIDAD - ELECTRICOS - MOTO
A13: PASAJEROS | B13: 3 | C13: 00017 | D13: 00001 | E13: 00000001 | F13: DONGFENG AUT. UNIDAD - ELECTRICOS - PASAJEROS
A14: PICK-UP | B14: 3 | C14: 00017 | D14: 00001 | E14: 00000003 | F14: DONGFENG AUT. UNIDAD - ELECTRICOS - PICK-UP
A15: STATION WAGON | B15: 3 | C15: 00017 | D15: 00001 | E15: 00000006 | F15: DONGFENG AUT. UNIDAD - ELECTRICOS - STATION WAGON
A16: SUV | B16: 3 | C16: 00017 | D16: 00001 | E16: 00000002 | F16: DONGFENG AUT. UNIDAD - ELECTRICOS - SUV
A17: GASOLINA | B17: 2 | C17: 00017 | D17: 00002 | F17: DONGFENG AUT. UNIDAD - GASOLINA
A18: COMERCIALES | B18: 3 | C18: 00017 | D18: 00002 | E18: 00000004 | F18: DONGFENG AUT. UNIDAD - GASOLINA - COMERCIALES
A19: MOTO | B19: 3 | C19: 00017 | D19: 00002 | E19: 00000005 | F19: DONGFENG AUT. UNIDAD - GASOLINA - MOTO
A20: PASAJEROS | B20: 3 | C20: 00017 | D20: 00002 | E20: 00000001 | F20: DONGFENG AUT. UNIDAD - GASOLINA - PASAJEROS
A21: PICK-UP | B21: 3 | C21: 00017 | D21: 00002 | E21: 00000003 | F21: DONGFENG AUT. UNIDAD - GASOLINA - PICK-UP
A22: STATION WAGON | B22: 3 | C22: 00017 | D22: 00002 | E22: 00000006 | F22: DONGFENG AUT. UNIDAD - GASOLINA - STATION WAGON
A23: SUV | B23: 3 | C23: 00017 | D23: 00002 | E23: 00000002 | F23: DONGFENG AUT. UNIDAD - GASOLINA - SUV
A24: HIBRIDO | B24: 2 | C24: 00017 | D24: 00004 | F24: DONGFENG AUT. UNIDAD - HIBRIDO
A25: COMERCIALES | B25: 3 | C25: 00017 | D25: 00004 | E25: 00000004 | F25: DONGFENG AUT. UNIDAD - HIBRIDO - COMERCIALES
A26: PASAJEROS | B26: 3 | C26: 00017 | D26: 00004 | E26: 00000001 | F26: DONGFENG AUT. UNIDAD - HIBRIDO - PASAJEROS
A27: PICK-UP | B27: 3 | C27: 00017 | D27: 00004 | E27: 00000003 | F27: DONGFENG AUT. UNIDAD - HIBRIDO - PICK-UP
A28: STATION WAGON | B28: 3 | C28: 00017 | D28: 00004 | E28: 00000005 | F28: DONGFENG AUT. UNIDAD - HIBRIDO - STATION WAGON
A29: SUV | B29: 3 | C29: 00017 | D29: 00004 | E29: 00000002 | F29: DONGFENG AUT. UNIDAD - HIBRIDO - SUV
A30: DONGFENG CAM. UNIDADES | B30: 1 | C30: 00108 | F30: DONGFENG CAM. UNIDADES
A31: DIESEL | B31: 2 | C31: 00108 | D31: 00002 | F31: DONGFENG CAM. UNIDADES - DIESEL
A32: LIVIANOS | B32: 3 | C32: 00108 | D32: 00002 | E32: 00000001 | F32: DONGFENG CAM. UNIDADES - DIESEL - LIVIANOS
A33: MEDIANOS | B33: 3 | C33: 00108 | D33: 00002 | E33: 00000002 | F33: DONGFENG CAM. UNIDADES - DIESEL - MEDIANOS
A34: PESADOS | B34: 3 | C34: 00108 | D34: 00002 | E34: 00000003 | F34: DONGFENG CAM. UNIDADES - DIESEL - PESADOS
A35: ELECTRICOS | B35: 2 | C35: 00108 | D35: 00001 | F35: DONGFENG CAM. UNIDADES - ELECTRICOS
A36: LIVIANOS | B36: 3 | C36: 00108 | D36: 00001 | E36: 00000001 | F36: DONGFENG CAM. UNIDADES - ELECTRICOS - LIVIANOS
A37: MEDIANOS | B37: 3 | C37: 00108 | D37: 00001 | E37: 00000002 | F37: DONGFENG CAM. UNIDADES - ELECTRICOS - MEDIANOS
A38: PESADOS | B38: 3 | C38: 00108 | D38: 00001 | E38: 00000003 | F38: DONGFENG CAM. UNIDADES - ELECTRICOS - PESADOS
A39: GAS | B39: 2 | C39: 00108 | D39: 00003 | F39: DONGFENG CAM. UNIDADES - GAS
A40: LIVIANOS | B40: 3 | C40: 00108 | D40: 00003 | E40: 00000001 | F40: DONGFENG CAM. UNIDADES - GAS - LIVIANOS
...

Sheet Grupo de Articulos
A1: Grupo Artículo | B1: Descripción | C1: Descripción 2
A2: UNID-001 | B2: AUTOS Y MOTOS | C2: Unidades para autos y motos
A3: UNID-002 | B3: CAMIONES | C3: Unidades para camiones
A4: UNID-003 | B4: MAQ. INDUSTRIAL | C4: Unidades para maquinaria industrial (TTI, TTM, TTMQ)

Sheet Diccionario Filiales
A1: Sociedad/es | B1: Nombre Sociedad
A2: VA00 | B2: Maco Tattersall
A3: VF00 | B3: Tattersall Automotriz
A4: VF00, VA00 | B4: Tattersall Automotriz y Maco Tattersall
A5: VC00 | B5: Tattersall Maquinarias
A6: VD00 | B6: Tattersall Multimaq
A7: VE00, VC00 | B7: Tattersall Industrial y Maquinarias

Sheet Diccionario Fabricantes
A1: Fabricante | B1: Nombre Fabricante | C1: Fabricante externo
A2: F0001 | B2: CHINA DONG FENG MOTOR INDUSTRY IMP | C2: DFCV
A3: F0002 | B3: ACCURIDE WHEEL | C3: ACWHE
A4: F0003 | B4: ADQUIM | C4: ADQUI
A5: F0004 | B5: ALLIANCE | C5: ALLIA
A6: F0005 | B6: ANKA | C6: ANKA
A7: F0006 | B7: INTERNATIONAL MOTORS, LLC | C7: INT
A8: F0007 | B8: BENDIX | C8: BENDI
A9: F0008 | B9: BORGWARNER ALL MAKES | C9: BORWA
A10: F0009 | B10: BRAKEDRUM | C10: BRAKE
A11: F0010 | B11: HYSTER-YALE MAXIMAL FORKLIFT (ZHEJI | C11: MXML
A12: F0011 | B12: TVH FORKLIFT PARTS NV | C12: TVH
... A75: F9999 | B75: OTRAS MARCAS | C75: OTRO

Sheet Diccionario Marcas
A1: Marca | B1: Descripción Marca
A2: 010 | B2: BASHAN
A3: 040 | B3: CUMMINS
A4: 050 | B4: D&P
A5: 060 | B5: DONGFENG
A6: 070 | B6: DRESSTA
A7: 080 | B7: FAW
A8: 110 | B8: INTERNATIONAL
A9: 120 | B9: JETOUR
A10: 130 | B10: KYC
A11: 140 | B11: LIFAN
A12: 160 | B12: LIVAN
... A23: 290 | B23: LIFAN AUTO

Sheet Diccionario GrupoImputacion
A1: codigo | B1: descripcion Grupo
A2: 50 | B2: Motos
A3: 51 | B3: Cuatrimotos
A4: 52 | B4: Unidad Nueva
