Workbook

Sheet INPUT
A1: FILIAL CODIGO | B1: TIPO MATERIAL | C1: TEXTO BREVE CALCULADO (MAX 40) | D1: NPF CALCULADO (MAX 30) | E1: MODELO | F1: CATEGORIA | G1: COMBUSTIBLE | H1: GRUPO ARTICULO | I1: NOMBRE JERARQUIA | J1: NOMBRE MARCA | K1: NOMBRE FABRICANTE | L1: GRUPO IMPUTACION | M1: LARGO TEXTO BREVE (máx 40) | N1: LARGO NPF (máx 30)
C2: {=IF(E2="","",_xlfn.LET(_xlpm.modelo,UPPER(TRIM(E2)),_xlpm.comb,_xlfn.XLOOKUP(UPPER(TRIM(G2)),UPPER(NPF!$A$4:$A$30),NPF!$B$4:$B$30,"¿COMB?"),UPPER(TRIM(F2))&" "&_xlpm.modelo&" "&_xlpm.comb))} | D2: {=IF(E2="","",_xlfn.LET(_xlpm.cat,_xlfn.XLOOKUP(UPPER(TRIM(F2)),UPPER(NPF!$G$4:$G$40),NPF!$H$4:$H$40,"¿CAT?"),_xlpm.comb,_xlfn.XLOOKUP(UPPER(TRIM(G2)),UPPER(NPF!$A$4:$A$30),NPF!$B$4:$B$30,"¿COMB?"),_xlpm.txt,NPF!$V$4:$V$33,_xlpm.abr,NPF!$W$4:$W$33,_xlpm.modAbrev,_xlfn.REDUCE(UPPER(TRIM(E2)),_xlfn.SEQUENCE(ROWS(_xlpm.txt)),_xlfn.LAMBDA(_xlpm.acc,_xlpm.i,IF(INDEX(_xlpm.txt,_xlpm.i)="",_xlpm.acc,SUBSTITUTE(_xlpm.acc,UPPER(INDEX(_xlpm.txt,_xlpm.i)),INDEX(_xlpm.abr,_xlpm.i))))),_xlpm.modelo,SUBSTITUTE(SUBSTITUTE(SUBSTITUTE(_xlpm.modAbrev," ",""),"(",""),")",""),_xlpm.cat&"-"&_xlpm.modelo&"-"&_xlpm.comb&"-U"))} | M2: =IF(C2="","",LEN(C2)) | N2: =IF(D2="","",LEN(D2))
C3: {=IF(E3="","",_xlfn.LET(_xlpm.modelo,UPPER(TRIM(E3)),_xlpm.comb,_xlfn.XLOOKUP(UPPER(TRIM(G3)),UPPER(NPF!$A$4:$A$30),NPF!$B$4:$B$30,"¿COMB?"),UPPER(TRIM(F3))&" "&_xlpm.modelo&" "&_xlpm.comb))} | D3: {=IF(E3="","",_xlfn.LET(_xlpm.cat,_xlfn.XLOOKUP(UPPER(TRIM(F3)),UPPER(NPF!$G$4:$G$40),NPF!$H$4:$H$40,"¿CAT?"),_xlpm.comb,_xlfn.XLOOKUP(UPPER(TRIM(G3)),UPPER(NPF!$A$4:$A$30),NPF!$B$4:$B$30,"¿COMB?"),_xlpm.txt,NPF!$V$4:$V$33,_xlpm.abr,NPF!$W$4:$W$33,_xlpm.modAbrev,_xlfn.REDUCE(UPPER(TRIM(E3)),_xlfn.SEQUENCE(ROWS(_xlpm.txt)),_xlfn.LAMBDA(_xlpm.acc,_xlpm.i,IF(INDEX(_xlpm.txt,_xlpm.i)="",_xlpm.acc,SUBSTITUTE(_xlpm.acc,UPPER(INDEX(_xlpm.txt,_xlpm.i)),INDEX(_xlpm.abr,_xlpm.i))))),_xlpm.modelo,SUBSTITUTE(SUBSTITUTE(SUBSTITUTE(_xlpm.modAbrev," ",""),"(",""),")",""),_xlpm.cat&"-"&_xlpm.modelo&"-"&_xlpm.comb&"-U"))} | M3: =IF(C3="","",LEN(C3)) | N3: =IF(D3="","",LEN(D3))
C4: {=IF(E4="","",_xlfn.LET(_xlpm.modelo,UPPER(TRIM(E4)),_xlpm.comb,_xlfn.XLOOKUP(UPPER(TRIM(G4)),UPPER(NPF!$A$4:$A$30),NPF!$B$4:$B$30,"¿COMB?"),UPPER(TRIM(F4))&" "&_xlpm.modelo&" "&_xlpm.comb))} | D4: {=IF(E4="","",_xlfn.LET(_xlpm.cat,_xlfn.XLOOKUP(UPPER(TRIM(F4)),UPPER(NPF!$G$4:$G$40),NPF!$H$4:$H$40,"¿CAT?"),_xlpm.comb,_xlfn.XLOOKUP(UPPER(TRIM(G4)),UPPER(NPF!$A$4:$A$30),NPF!$B$4:$B$30,"¿COMB?"),_xlpm.txt,NPF!$V$4:$V$33,_xlpm.abr,NPF!$W$4:$W$33,_xlpm.modAbrev,_xlfn.REDUCE(UPPER(TRIM(E4)),_xlfn.SEQUENCE(ROWS(_xlpm.txt)),_xlfn.LAMBDA(_xlpm.acc,_xlpm.i,IF(INDEX(_xlpm.txt,_xlpm.i)="",_xlpm.acc,SUBSTITUTE(_xlpm.acc,UPPER(INDEX(_xlpm.txt,_xlpm.i)),INDEX(_xlpm.abr,_xlpm.i))))),_xlpm.modelo,SUBSTITUTE(SUBSTITUTE(SUBSTITUTE(_xlpm.modAbrev," ",""),"(",""),")",""),_xlpm.cat&"-"&_xlpm.modelo&"-"&_xlpm.comb&"-U"))} | M4: =IF(C4="","",LEN(C4)) | N4: =IF(D4="","",LEN(D4))
C5: {=IF(E5="","",_xlfn.LET(_xlpm.modelo,UPPER(TRIM(E5)),_xlpm.comb,_xlfn.XLOOKUP(UPPER(TRIM(G5)),UPPER(NPF!$A$4:$A$30),NPF!$B$4:$B$30,"¿COMB?"),UPPER(TRIM(F5))&" "&_xlpm.modelo&" "&_xlpm.comb))} | D5: {=IF(E5="","",_xlfn.LET(_xlpm.cat,_xlfn.XLOOKUP(UPPER(TRIM(F5)),UPPER(NPF!$G$4:$G$40),NPF!$H$4:$H$40,"¿CAT?"),_xlpm.comb,_xlfn.XLOOKUP(UPPER(TRIM(G5)),UPPER(NPF!$A$4:$A$30),NPF!$B$4:$B$30,"¿COMB?"),_xlpm.txt,NPF!$V$4:$V$33,_xlpm.abr,NPF!$W$4:$W$33,_xlpm.modAbrev,_xlfn.REDUCE(UPPER(TRIM(E5)),_xlfn.SEQUENCE(ROWS(_xlpm.txt)),_xlfn.LAMBDA(_xlpm.acc,_xlpm.i,IF(INDEX(_xlpm.txt,_xlpm.i)="",_xlpm.acc,SUBSTITUTE(_xlpm.acc,UPPER(INDEX(_xlpm.txt,_xlpm.i)),INDEX(_xlpm.abr,_xlpm.i))))),_xlpm.modelo,SUBSTITUTE(SUBSTITUTE(SUBSTITUTE(_xlpm.modAbrev," ",""),"(",""),")",""),_xlpm.cat&"-"&_xlpm.modelo&"-"&_xlpm.comb&"-U"))} | M5: =IF(C5="","",LEN(C5)) | N5: =IF(D5="","",LEN(D5))
C6: {=IF(E6="","",_xlfn.LET(_xlpm.modelo,UPPER(TRIM(E6)),_xlpm.comb,_xlfn.XLOOKUP(UPPER(TRIM(G6)),UPPER(NPF!$A$4:$A$30),NPF!$B$4:$B$30,"¿COMB?"),UPPER(TRIM(F6))&" "&_xlpm.modelo&" "&_xlpm.comb))} | D6: {=IF(E6="","",_xlfn.LET(_xlpm.cat,_xlfn.XLOOKUP(UPPER(TRIM(F6)),UPPER(NPF!$G$4:$G$40),NPF!$H$4:$H$40,"¿CAT?"),_xlpm.comb,_xlfn.XLOOKUP(UPPER(TRIM(G6)),UPPER(NPF!$A$4:$A$30),NPF!$B$4:$B$30,"¿COMB?"),_xlpm.txt,NPF!$V$4:$V$33,_xlpm.abr,NPF!$W$4:$W$33,_xlpm.modAbrev,_xlfn.REDUCE(UPPER(TRIM(E6)),_xlfn.SEQUENCE(ROWS(_xlpm.txt)),_xlfn.LAMBDA(_xlpm.acc,_xlpm.i,IF(INDEX(_xlpm.txt,_xlpm.i)="",_xlpm.acc,SUBSTITUTE(_xlpm.acc,UPPER(INDEX(_xlpm.txt,_xlpm.i)),INDEX(_xlpm.abr,_xlpm.i))))),_xlpm.modelo,SUBSTITUTE(SUBSTITUTE(SUBSTITUTE(_xlpm.modAbrev," ",""),"(",""),")",""),_xlpm.cat&"-"&_xlpm.modelo&"-"&_xlpm.comb&"-U"))} | M6: =IF(C6="","",LEN(C6)) | N6: =IF(D6="","",LEN(D6))
C7: {=IF(E7="","",_xlfn.LET(_xlpm.modelo,UPPER(TRIM(E7)),_xlpm.comb,_xlfn.XLOOKUP(UPPER(TRIM(G7)),UPPER(NPF!$A$4:$A$30),NPF!$B$4:$B$30,"¿COMB?"),UPPER(TRIM(F7))&" "&_xlpm.modelo&" "&_xlpm.comb))} | D7: {=IF(E7="","",_xlfn.LET(_xlpm.cat,_xlfn.XLOOKUP(UPPER(TRIM(F7)),UPPER(NPF!$G$4:$G$40),NPF!$H$4:$H$40,"¿CAT?"),_xlpm.comb,_xlfn.XLOOKUP(UPPER(TRIM(G7)),UPPER(NPF!$A$4:$A$30),NPF!$B$4:$B$30,"¿COMB?"),_xlpm.txt,NPF!$V$4:$V$33,_xlpm.abr,NPF!$W$4:$W$33,_xlpm.modAbrev,_xlfn.REDUCE(UPPER(TRIM(E7)),_xlfn.SEQUENCE(ROWS(_xlpm.txt)),_xlfn.LAMBDA(_xlpm.acc,_xlpm.i,IF(INDEX(_xlpm.txt,_xlpm.i)="",_xlpm.acc,SUBSTITUTE(_xlpm.acc,UPPER(INDEX(_xlpm.txt,_xlpm.i)),INDEX(_xlpm.abr,_xlpm.i))))),_xlpm.modelo,SUBSTITUTE(SUBSTITUTE(SUBSTITUTE(_xlpm.modAbrev," ",""),"(",""),")",""),_xlpm.cat&"-"&_xlpm.modelo&"-"&_xlpm.comb&"-U"))} | M7: =IF(C7="","",LEN(C7)) | N7: =IF(D7="","",LEN(D7))
C8: {=IF(E8="","",_xlfn.LET(_xlpm.modelo,UPPER(TRIM(E8)),_xlpm.comb,_xlfn.XLOOKUP(UPPER(TRIM(G8)),UPPER(NPF!$A$4:$A$30),NPF!$B$4:$B$30,"¿COMB?"),UPPER(TRIM(F8))&" "&_xlpm.modelo&" "&_xlpm.comb))} | D8: {=IF(E8="","",_xlfn.LET(_xlpm.cat,_xlfn.XLOOKUP(UPPER(TRIM(F8)),UPPER(NPF!$G$4:$G$40),NPF!$H$4:$H$40,"¿CAT?"),_xlpm.comb,_xlfn.XLOOKUP(UPPER(TRIM(G8)),UPPER(NPF!$A$4:$A$30),NPF!$B$4:$B$30,"¿COMB?"),_xlpm.txt,NPF!$V$4:$V$33,_xlpm.abr,NPF!$W$4:$W$33,_xlpm.modAbrev,_xlfn.REDUCE(UPPER(TRIM(E8)),_xlfn.SEQUENCE(ROWS(_xlpm.txt)),_xlfn.LAMBDA(_xlpm.acc,_xlpm.i,IF(INDEX(_xlpm.txt,_xlpm.i)="",_xlpm.acc,SUBSTITUTE(_xlpm.acc,UPPER(INDEX(_xlpm.txt,_xlpm.i)),INDEX(_xlpm.abr,_xlpm.i))))),_xlpm.modelo,SUBSTITUTE(SUBSTITUTE(SUBSTITUTE(_xlpm.modAbrev," ",""),"(",""),")",""),_xlpm.cat&"-"&_xlpm.modelo&"-"&_xlpm.comb&"-U"))} | M8: =IF(C8="","",LEN(C8)) | N8: =IF(D8="","",LEN(D8))
C9: {=IF(E9="","",_xlfn.LET(_xlpm.modelo,UPPER(TRIM(E9)),_xlpm.comb,_xlfn.XLOOKUP(UPPER(TRIM(G9)),UPPER(NPF!$A$4:$A$30),NPF!$B$4:$B$30,"¿COMB?"),UPPER(TRIM(F9))&" "&_xlpm.modelo&" "&_xlpm.comb))} | D9: {=IF(E9="","",_xlfn.LET(_xlpm.cat,_xlfn.XLOOKUP(UPPER(TRIM(F9)),UPPER(NPF!$G$4:$G$40),NPF!$H$4:$H$40,"¿CAT?"),_xlpm.comb,_xlfn.XLOOKUP(UPPER(TRIM(G9)),UPPER(NPF!$A$4:$A$30),NPF!$B$4:$B$30,"¿COMB?"),_xlpm.txt,NPF!$V$4:$V$33,_xlpm.abr,NPF!$W$4:$W$33,_xlpm.modAbrev,_xlfn.REDUCE(UPPER(TRIM(E9)),_xlfn.SEQUENCE(ROWS(_xlpm.txt)),_xlfn.LAMBDA(_xlpm.acc,_xlpm.i,IF(INDEX(_xlpm.txt,_xlpm.i)="",_xlpm.acc,SUBSTITUTE(_xlpm.acc,UPPER(INDEX(_xlpm.txt,_xlpm.i)),INDEX(_xlpm.abr,_xlpm.i))))),_xlpm.modelo,SUBSTITUTE(SUBSTITUTE(SUBSTITUTE(_xlpm.modAbrev," ",""),"(",""),")",""),_xlpm.cat&"-"&_xlpm.modelo&"-"&_xlpm.comb&"-U"))} | M9: =IF(C9="","",LEN(C9)) | N9: =IF(D9="","",LEN(D9))
C10: {=IF(E10="","",_xlfn.LET(_xlpm.modelo,UPPER(TRIM(E10)),_xlpm.comb,_xlfn.XLOOKUP(UPPER(TRIM(G10)),UPPER(NPF!$A$4:$A$30),NPF!$B$4:$B$30,"¿COMB?"),UPPER(TRIM(F10))&" "&_xlpm.modelo&" "&_xlpm.comb))} | D10: {=IF(E10="","",_xlfn.LET(_xlpm.cat,_xlfn.XLOOKUP(UPPER(TRIM(F10)),UPPER(NPF!$G$4:$G$40),NPF!$H$4:$H$40,"¿CAT?"),_xlpm.comb,_xlfn.XLOOKUP(UPPER(TRIM(G10)),UPPER(NPF!$A$4:$A$30),NPF!$B$4:$B$30,"¿COMB?"),_xlpm.txt,NPF!$V$4:$V$33,_xlpm.abr,NPF!$W$4:$W$33,_xlpm.modAbrev,_xlfn.REDUCE(UPPER(TRIM(E10)),_xlfn.SEQUENCE(ROWS(_xlpm.txt)),_xlfn.LAMBDA(_xlpm.acc,_xlpm.i,IF(INDEX(_xlpm.txt,_xlpm.i)="",_xlpm.acc,SUBSTITUTE(_xlpm.acc,UPPER(INDEX(_xlpm.txt,_xlpm.i)),INDEX(_xlpm.abr,_xlpm.i))))),_xlpm.modelo,SUBSTITUTE(SUBSTITUTE(SUBSTITUTE(_xlpm.modAbrev," ",""),"(",""),")",""),_xlpm.cat&"-"&_xlpm.modelo&"-"&_xlpm.comb&"-U"))} | M10: =IF(C10="","",LEN(C10)) | N10: =IF(D10="","",LEN(D10))
C11: {=IF(E11="","",_xlfn.LET(_xlpm.modelo,UPPER(TRIM(E11)),_xlpm.comb,_xlfn.XLOOKUP(UPPER(TRIM(G11)),UPPER(NPF!$A$4:$A$30),NPF!$B$4:$B$30,"¿COMB?"),UPPER(TRIM(F11))&" "&_xlpm.modelo&" "&_xlpm.comb))} | D11: {=IF(E11="","",_xlfn.LET(_xlpm.cat,_xlfn.XLOOKUP(UPPER(TRIM(F11)),UPPER(NPF!$G$4:$G$40),NPF!$H$4:$H$40,"¿CAT?"),_xlpm.comb,_xlfn.XLOOKUP(UPPER(TRIM(G11)),UPPER(NPF!$A$4:$A$30),NPF!$B$4:$B$30,"¿COMB?"),_xlpm.txt,NPF!$V$4:$V$33,_xlpm.abr,NPF!$W$4:$W$33,_xlpm.modAbrev,_xlfn.REDUCE(UPPER(TRIM(E11)),_xlfn.SEQUENCE(ROWS(_xlpm.txt)),_xlfn.LAMBDA(_xlpm.acc,_xlpm.i,IF(INDEX(_xlpm.txt,_xlpm.i)="",_xlpm.acc,SUBSTITUTE(_xlpm.acc,UPPER(INDEX(_xlpm.txt,_xlpm.i)),INDEX(_xlpm.abr,_xlpm.i))))),_xlpm.modelo,SUBSTITUTE(SUBSTITUTE(SUBSTITUTE(_xlpm.modAbrev," ",""),"(",""),")",""),_xlpm.cat&"-"&_xlpm.modelo&"-"&_xlpm.comb&"-U"))} | M11: =IF(C11="","",LEN(C11)) | N11: =IF(D11="","",LEN(D11))
C12: {=IF(E12="","",_xlfn.LET(_xlpm.modelo,UPPER(TRIM(E12)),_xlpm.comb,_xlfn.XLOOKUP(UPPER(TRIM(G12)),UPPER(NPF!$A$4:$A$30),NPF!$B$4:$B$30,"¿COMB?"),UPPER(TRIM(F12))&" "&_xlpm.modelo&" "&_xlpm.comb))} | D12: {=IF(E12="","",_xlfn.LET(_xlpm.cat,_xlfn.XLOOKUP(UPPER(TRIM(F12)),UPPER(NPF!$G$4:$G$40),NPF!$H$4:$H$40,"¿CAT?"),_xlpm.comb,_xlfn.XLOOKUP(UPPER(TRIM(G12)),UPPER(NPF!$A$4:$A$30),NPF!$B$4:$B$30,"¿COMB?"),_xlpm.txt,NPF!$V$4:$V$33,_xlpm.abr,NPF!$W$4:$W$33,_xlpm.modAbrev,_xlfn.REDUCE(UPPER(TRIM(E12)),_xlfn.SEQUENCE(ROWS(_xlpm.txt)),_xlfn.LAMBDA(_xlpm.acc,_xlpm.i,IF(INDEX(_xlpm.txt,_xlpm.i)="",_xlpm.acc,SUBSTITUTE(_xlpm.acc,UPPER(INDEX(_xlpm.txt,_xlpm.i)),INDEX(_xlpm.abr,_xlpm.i))))),_xlpm.modelo,SUBSTITUTE(SUBSTITUTE(SUBSTITUTE(_xlpm.modAbrev," ",""),"(",""),")",""),_xlpm.cat&"-"&_xlpm.modelo&"-"&_xlpm.comb&"-U"))} | M12: =IF(C12="","",LEN(C12)) | N12: =IF(D12="","",LEN(D12))
C13: {=IF(E13="","",_xlfn.LET(_xlpm.modelo,UPPER(TRIM(E13)),_xlpm.comb,_xlfn.XLOOKUP(UPPER(TRIM(G13)),UPPER(NPF!$A$4:$A$30),NPF!$B$4:$B$30,"¿COMB?"),UPPER(TRIM(F13))&" "&_xlpm.modelo&" "&_xlpm.comb))} | D13: {=IF(E13="","",_xlfn.LET(_xlpm.cat,_xlfn.XLOOKUP(UPPER(TRIM(F13)),UPPER(NPF!$G$4:$G$40),NPF!$H$4:$H$40,"¿CAT?"),_xlpm.comb,_xlfn.XLOOKUP(UPPER(TRIM(G13)),UPPER(NPF!$A$4:$A$30),NPF!$B$4:$B$30,"¿COMB?"),_xlpm.txt,NPF!$V$4:$V$33,_xlpm.abr,NPF!$W$4:$W$33,_xlpm.modAbrev,_xlfn.REDUCE(UPPER(TRIM(E13)),_xlfn.SEQUENCE(ROWS(_xlpm.txt)),_xlfn.LAMBDA(_xlpm.acc,_xlpm.i,IF(INDEX(_xlpm.txt,_xlpm.i)="",_xlpm.acc,SUBSTITUTE(_xlpm.acc,UPPER(INDEX(_xlpm.txt,_xlpm.i)),INDEX(_xlpm.abr,_xlpm.i))))),_xlpm.modelo,SUBSTITUTE(SUBSTITUTE(SUBSTITUTE(_xlpm.modAbrev," ",""),"(",""),")",""),_xlpm.cat&"-"&_xlpm.modelo&"-"&_xlpm.comb&"-U"))} | M13: =IF(C13="","",LEN(C13)) | N13: =IF(D13="","",LEN(D13))
... C199: {=IF(E199="","",_xlfn.LET(_xlpm.modelo,UPPER(TRIM(E199)),_xlpm.comb,_xlfn.XLOOKUP(UPPER(TRIM(G199)),UPPER(NPF!$A$4:$A$30),NPF!$B$4:$B$30,"¿COMB?"),UPPER(TRIM(F199))&" "&_xlpm.modelo&" "&_xlpm.comb))} | D199: {=IF(E199="","",_xlfn.LET(_xlpm.cat,_xlfn.XLOOKUP(UPPER(TRIM(F199)),UPPER(NPF!$G$4:$G$40),NPF!$H$4:$H$40,"¿CAT?"),_xlpm.comb,_xlfn.XLOOKUP(UPPER(TRIM(G199)),UPPER(NPF!$A$4:$A$30),NPF!$B$4:$B$30,"¿COMB?"),_xlpm.txt,NPF!$V$4:$V$33,_xlpm.abr,NPF!$W$4:$W$33,_xlpm.modAbrev,_xlfn.REDUCE(UPPER(TRIM(E199)),_xlfn.SEQUENCE(ROWS(_xlpm.txt)),_xlfn.LAMBDA(_xlpm.acc,_xlpm.i,IF(INDEX(_xlpm.txt,_xlpm.i)="",_xlpm.acc,SUBSTITUTE(_xlpm.acc,UPPER(INDEX(_xlpm.txt,_xlpm.i)),INDEX(_xlpm.abr,_xlpm.i))))),_xlpm.modelo,SUBSTITUTE(SUBSTITUTE(SUBSTITUTE(_xlpm.modAbrev," ",""),"(",""),")",""),_xlpm.cat&"-"&_xlpm.modelo&"-"&_xlpm.comb&"-U"))} | M199: =IF(C199="","",LEN(C199)) | N199: =IF(D199="","",LEN(D199))

Sheet NPF
A1: Tablas de conversión — se pueden ampliar agregando filas al final de cada tabla | V1: Abreviaciones de Modelo / Versión | Z1: Estándar de Nomenclatura NPF — referencia | AE1: Abreviaciones de Marca (Texto breve)
V2: Se aplican en orden de arriba hacia abajo sobre MODELO + VERSIÓN (en mayúsculas), antes de quitar espacios y paréntesis. Las más largas deben ir antes que las cortas (ej: LUX PLUS XL antes que LUX PLUS). Hay 30 filas disponibles. | Z2: Número de Parte del Fabricante — Migración SAP S/4HANA · Proyecto Integra. Límite SAP: 30 caracteres. | AE2: Se usa en el TEXTO BREVE. Si el MODELO ya empieza con la abreviatura (ej: DF-1016), la marca no se repite. Se puede ampliar hasta la fila 40.
A3: Combustible (SAP) | B3: Abrev. NPF | D3: Transmisión (SAP) | E3: Abrev. NPF | G3: Categoría Maquinaria | H3: Abrev. NPF | J3: Tracción | L3: Tipo Material | N3: Tipo Base (solo ZUSA) | Q3: Categorías sin cilindrada (motos/ATV) | S3: Categorías (lista desplegable) | V3: Texto original | W3: Abrev. | X3: Ejemplo aplicado | AE3: Marca (SAP) | AF3: Abrev. Texto breve
A4: GASOLINA | B4: GSL | D4: Mecanica (MT) | E4: MT | G4: APILADOR | H4: APIL | J4: 2x1 | L4: ZCAM | N4: ZMAQ | O4: MAQUINARIAS | Q4: Motocicleta | S4: APILADOR | V4: HORIZON PRO | W4: HZPRO | X4: RD6 DC HORIZON PRO → RD6DCHZPRO | Z4: 1. Fórmulas por tipo de material | AE4: DONGFENG | AF4: DF
A5: DIESEL | B5: DSL | D5: Automatica (AT) | E5: AT | G5: BIG TRUCK | H5: BGTRUCK | J5: 4x2 | L5: ZVEH | N5: ZCAM | O5: CAMIONES | Q5: Cuatrimoto | S5: TRANSPALETA | V5: HYPER HALO | W5: HPHALO | X5: 09 HYPER HALO → 09HPHALO | Z5: Tipo Material | AA5: Fórmula NPF | AB5: Ejemplo | AC5: Nota | AE5: FAW | AF5: FAW
A6: ELECTRICIDAD (BEV) | B6: BEV | D6: Automatizada (AMT) | E6: AMT | G6: CARGADOR FRONTAL | H6: CARG.FR | J6: 4x4 | L6: ZMAQ | N6: ZVEH | O6: VEHICULOS | S6: CARGADOR FRONTAL | V6: LUX PLUS XL | W6: LPXL | X6: DC LUX PLUS XL → DCLPXL | Z6: ZCAM — Camiones | AA6: [MODELO+VERSION]-[CIL]-[COMB]-[TRAC]-[TRANS] | AB6: DF-1823-6.7L-DSL-4X2-AT | AC6: Tracción en mayúscula (4X2). BEV sin cilindrada. | AE6: KYC | AF6: KYC
A7: Gasolina/Electricidad (PHEV) | B7: PHEV | D7: Doble embrague (DCT) | E7: DCT | G7: EXCAVADORA | H7: EXCAV | J7: 6x2 | L7: ZUSA | N7: ZUSA | O7: USADOS | S7: PLATAFORMA | V7: LUX PLUS | W7: LP | X7: DC LUX PLUS → DCLP | Z7: ZVEH — Vehículos | AA7: [MODELO+VERSION]-[COMB]-[CIL]-[TRAC]-[TRANS] | AB7: X3PROELITE-GSL-1.5L-4x2-AT | AC7: Tracción en minúscula (4x2). | AE7: LIFAN | AF7: LF
A8: Híbrido ligero (MHEV) | B8: MHEV | G8: GRUA | H8: GRUA | J8: 6x4 | S8: RETROEXCAVADORA | V8: DIGNITY | W8: DIG | X8: DC DIGNITY → DCDIG | Z8: ZVEH — BEV puro | AA8: [MODELO+VERSION]-EV-[TRAC]-[TRANS] | AB8: RD6DC86KWH-BEV-4x2-AT | AC8: Sin cilindrada, kWh va en modelo. | AE8: LIFAN AUTO | AF8: LFA
A9: GASOLINA / GLP | B9: GSL/GLP | G9: MOTONIVELADORA | H9: MOTONIV | J9: 8x4 | S9: EXCAVADORA | V9: ULTRA | W9: ULT | X9: DC ULTRA → DCULT | Z9: ZVEH — PHEV/HEV/MHEV | AA9: [MODELO+VERSION+KWH]-[COMB]-[CIL]-[TRAC]-[TRANS] | AB9: RD6DCULT19KWH-PHEV-1.5L-4x4-AT | AC9: Lleva cilindrada (motor de combustión). | AE9: LINHAI | AF9: LH
A10: GLP | B10: GLP | G10: PLATAFORMA | H10: PLAT | J10: 10x4 | S10: GRUA | V10: TRUCK BOX | W10: TBOX | X10: Truck DC Truck Box → TRKDCTBOX | Z10: ZVEH — Motos/ATV | AA10: [MODELO+VERSION]-[COMB]-[TRAC]-[TRANS] | AB10: LF125T-2VIII-GSL-2x1-MT | AC10: Sin cilindrada. | AE10: BASHAN | AF10: BSH
G11: PORTACONTENEDOR | H11: PORTAC | S11: RODILLO COMPACTADOR | V11: TRUCK | W11: TRK | X11: Truck DC Truck Box → TRKDCTBOX | Z11: ZMAQ — Maquinaria | AA11: [CAT_ABREV]-[MODELO]-[COMB] | AB11: EXCAV-HMK220LC-DSL | AC11: Fabricante identificado en modelo. | AE11: INTERNATIONAL | AF11: INTL
G12: REACHTRUCK | H12: REACHTR | S12: MOTONIVELADORA | V12: GRAND LION | W12: GLN | X12: Grand Lion DC → GLNDC | Z12: ZUSA — Genérico | AA12: USADO-[TIPO] | AB12: USADO-CAM | AC12: Sin especificaciones. | AE12: LIVAN | AF12: LVN
G13: RETROEXCAVADORA | H13: RETROEX | S13: MANIPULADOR TELESCOPICO | V13: TERRALORD | W13: TRLD | X13: TERRALORD DC → TRLDDC | Z13: ZUSA — Específico | AA13: [fórmula del tipo]-U | AB13: DF-1417-3.8L-DSL-4X2-MT-U | AC13: Sufijo -U. | AE13: LYNK & CO | AF13: LYNK
G14: RODILLO COMPACTADOR | H14: RODILLO | S14: PORTACONTENEDOR | V14: 19.1 KWH | W14: 19KWH | X14: DC ULTRA 19.1 kWh → DCULT19KWH | AE14: RIDDARA | AF14: RD
G15: TRANSPALETA | H15: TRANSP | S15: BIG TRUCK | Z15: 2. Cilindrada (cc → litros) | AE15: ZX | AF15: ZX
G16: YARDTRUCK | H16: YARDT | S16: GRUA PORTACONTENEDOR | Z16: • Se expresa en litros con 1 decimal: cc / 1000 redondeado (ej: 1969 → 2.0L, 2378 → 2.4L, 12520 → 12.5L). | AE16: OTRAS MARCAS | AF16: OTRAS
G17: REACHSTACKER | H17: REACHKER | S17: MINIEXCAVADORA | Z17: • Usar 2 decimales (columna J = 2) cuando dos motores del mismo modelo redondearían igual (ej: 6690 → 6.69L vs 6700 → 6.7L).
G18: ORDER PICKER | H18: ORDERPICKER | S18: MINICARGADOR | Z18: • Motos/cuatrimotos y BEV puros NO llevan cilindrada. PHEV/HEV/MHEV SÍ llevan.
G19: EMPTY CONTAINER | H19: EMPCONTI | S19: MINIRETROEXCAVADORA
G20: GENERADOR | H20: GENER | S20: GENERADOR | Z20: 3. Reglas generales
G21: GRUA HORQUILLA | H21: GRUA HOR | S21: GRUA HORQUILLA | Z21: • Límite máximo: 30 caracteres (restricción SAP).
G22: MINIRETROEXCAVADORA | H22: MINIRET | S22: MAQUINA INDUSTRIAL TRACTOR | Z22: • Separador: guión (-) entre cada bloque del NPF.
G23: MINIEXCAVADORA | H23: MEXCAV | Z23: • Modelo y versión se concatenan sin espacios; se eliminan los paréntesis (LF125T-2V(III) → LF125T-2VIII).
G24: MINICARGADOR | H24: MCARG.FR | Z24: • Todo en mayúsculas, excepto la L de litros (1.5L) y la tracción de ZVEH (4x2).
G25: GRUA PORTACONTENEDOR | H25: GRUA PORT | Z25: • Versiones largas se abrevian según la hoja Abreviaciones (objetivo: modelo+versión de 12–14 caracteres).
G26: MAQUINA INDUSTRIAL TRACTOR | H26: MAINDTRAC | Z26: • Combustible, transmisión y categoría de maquinaria se abrevian según la hoja Tablas.
G27: MANIPULADOR TELESCOPICO | H27: MANTELESC | Z27: • Duplicados: si dos materiales generan el mismo NPF, usar 2 decimales en la cilindrada.
Z29: Proyecto SAP Integra · Tattersall · Datos Maestros VMS

Sheet Diccionario Jerarquías
A1: Texto | B1: Nivel en la Jerarquía | C1: Nivel 1 | D1: Nivel 2 | E1: Nivel 3 | F1: Texto Categoría
A2: HIDROMEK UNIDAD | B2: 1 | C2: 00201 | F2: HIDROMEK UNIDAD
A3: DIESEL | B3: 2 | C3: 00201 | D3: 00001 | F3: HIDROMEK UNIDAD - DIESEL
A4: CARGADOR FRONTAL | B4: 3 | C4: 00201 | D4: 00001 | E4: 00000001 | F4: HIDROMEK UNIDAD - DIESEL - CARGADOR FRONTAL
A5: EXCAVADORA | B5: 3 | C5: 00201 | D5: 00001 | E5: 00000002 | F5: HIDROMEK UNIDAD - DIESEL - EXCAVADORA
A6: MOTONIVELADORA | B6: 3 | C6: 00201 | D6: 00001 | E6: 00000003 | F6: HIDROMEK UNIDAD - DIESEL - MOTONIVELADORA
A7: RETROEXCAVADORA | B7: 3 | C7: 00201 | D7: 00001 | E7: 00000004 | F7: HIDROMEK UNIDAD - DIESEL - RETROEXCAVADORA
A8: RODILLO COMPACTADOR | B8: 3 | C8: 00201 | D8: 00001 | E8: 00000005 | F8: HIDROMEK UNIDAD - DIESEL - RODILLO COMPACTADOR
A9: MINIRETROEXCAVADORA | B9: 3 | C9: 00201 | D9: 00001 | E9: 00000006 | F9: HIDROMEK UNIDAD - DIESEL - MINIRETROEXCAVADORA
A10: HYSTER UNIDAD | B10: 1 | C10: 00203 | F10: HYSTER UNIDAD
A11: ELECTRICOS | B11: 2 | C11: 00203 | D11: 00001 | F11: HYSTER UNIDAD - ELECTRICOS
A12: GRUAS | B12: 3 | C12: 00203 | D12: 00001 | E12: 00000001 | F12: HYSTER UNIDAD - ELECTRICOS - GRUA
A13: APILADOR | B13: 3 | C13: 00203 | D13: 00001 | E13: 00000002 | F13: HYSTER UNIDAD - ELECTRICOS - APILADOR
A14: TRANSPALETA | B14: 3 | C14: 00203 | D14: 00001 | E14: 00000003 | F14: HYSTER UNIDAD - ELECTRICOS - TRANSPALETA
A15: REACHTRUCK | B15: 3 | C15: 00203 | D15: 00001 | E15: 00000004 | F15: HYSTER UNIDAD - ELECTRICOS - REACHTRUCK
A16: ORDER PICKER | B16: 3 | C16: 00203 | D16: 00001 | E16: 00000005 | F16: HYSTER UNIDAD - ELECTRICOS - ORDER PICKER
A17: DIESEL | B17: 2 | C17: 00203 | D17: 00002 | F17: HYSTER UNIDAD - DIESEL
A18: GRUAS | B18: 3 | C18: 00203 | D18: 00002 | E18: 00000001 | F18: HYSTER UNIDAD - DIESEL - GRUA
A19: APILADOR | B19: 3 | C19: 00203 | D19: 00002 | E19: 00000002 | F19: HYSTER UNIDAD - DIESEL - APILADOR
A20: TRANSPALETA | B20: 3 | C20: 00203 | D20: 00002 | E20: 00000003 | F20: HYSTER UNIDAD - DIESEL - TRANSPALETA
A21: PORTACONTENEDOR | B21: 3 | C21: 00203 | D21: 00002 | E21: 00000004 | F21: HYSTER UNIDAD - DIESEL - PORTACONTENEDOR
A22: BIG TRUCK | B22: 3 | C22: 00203 | D22: 00002 | E22: 00000005 | F22: HYSTER UNIDAD - DIESEL - BIG TRUCK
A23: REACHSTACKER | B23: 3 | C23: 00203 | D23: 00002 | E23: 00000006 | F23: HYSTER UNIDAD - DIESEL - REACHSTACKER
A24: EMPTY CONTAINER | B24: 3 | C24: 00203 | D24: 00002 | E24: 00000007 | F24: HYSTER UNIDAD - DIESEL - EMPTY CONTAINER
A25: GLP | B25: 2 | C25: 00203 | D25: 00003 | F25: HYSTER UNIDAD - GLP
A26: GRUAS | B26: 3 | C26: 00203 | D26: 00003 | E26: 00000001 | F26: HYSTER UNIDAD - GLP - GRUA
A27: APILADOR | B27: 3 | C27: 00203 | D27: 00003 | E27: 00000002 | F27: HYSTER UNIDAD - GLP - APILADOR
A28: TRANSPALETA | B28: 3 | C28: 00203 | D28: 00003 | E28: 00000003 | F28: HYSTER UNIDAD - GLP - TRANSPALETA
A29: GLP DUAL | B29: 2 | C29: 00203 | D29: 00004 | F29: HYSTER UNIDAD - GLP DUAL
A30: GRUAS | B30: 3 | C30: 00203 | D30: 00004 | E30: 00000001 | F30: HYSTER UNIDAD - GLP DUAL - GRUA
A31: APILADOR | B31: 3 | C31: 00203 | D31: 00004 | E31: 00000002 | F31: HYSTER UNIDAD - GLP DUAL - APILADOR
A32: TRANSPALETA | B32: 3 | C32: 00203 | D32: 00004 | E32: 00000003 | F32: HYSTER UNIDAD - GLP DUAL - TRANSPALETA
A33: LIUGONG UNIDAD | B33: 1 | C33: 00205 | F33: LIUGONG UNIDAD
A34: ELECTRICOS | B34: 2 | C34: 00205 | D34: 00001 | F34: LIUGONG UNIDAD - ELECTRICOS
A35: BULLDOZER | B35: 3 | C35: 00205 | D35: 00001 | E35: 00000001 | F35: LIUGONG UNIDAD - ELECTRICOS - BULLDOZER
A36: CARGADOR FRONTAL | B36: 3 | C36: 00205 | D36: 00001 | E36: 00000002 | F36: LIUGONG UNIDAD - ELECTRICOS - CARGADOR FRONTAL
A37: EXCAVADORA | B37: 3 | C37: 00205 | D37: 00001 | E37: 00000003 | F37: LIUGONG UNIDAD - ELECTRICOS - EXCAVADORA
A38: MOTONIVELADORA | B38: 3 | C38: 00205 | D38: 00001 | E38: 00000004 | F38: LIUGONG UNIDAD - ELECTRICOS - MOTONIVELADORA
A39: PLATAFORMA | B39: 3 | C39: 00205 | D39: 00001 | E39: 00000005 | F39: LIUGONG UNIDAD - ELECTRICOS - PLATAFORMA
A40: RETROEXCAVADORA | B40: 3 | C40: 00205 | D40: 00001 | E40: 00000006 | F40: LIUGONG UNIDAD - ELECTRICOS - RETROEXCAVADORA
...

Sheet Grupo de Articulos
A1: Grupo Artículo | B1: Descripción | C1: Descripción 2
A2: UNID-003 | B2: MAQ. INDUSTRIAL | C2: Unidades para maquinaria industrial (TTI, TTM, TTMQ)

Sheet Diccionario Fabricantes
A1: Fabricante | B1: Nombre Fabricante | C1: Fabricante externo
A2: F0001 | B2: CHINA DONG FENG MOTOR INDUSTRY IMP | C2: DFCV
A3: F0002 | B3: ACCURIDE WHEEL | C3: ACWHE
A4: F0003 | B4: ADQUIM | C4: ADQUI
A5: F0004 | B5: ALLIANCE | C5: ALLIA
A6: F0005 | B6: ANKA | C6: ANKA
A7: F0006 | B7: INTERNATIONAL MOTORS, LLC | C7: INT
A8: F0007 | B8: BENDIX | C8: BENDI
A9: F0008 | B9: BORGWARNER ALL MAKES | C9: BORWA
A10: F0009 | B10: BRAKEDRUM | C10: BRAKE
A11: F0010 | B11: HYSTER-YALE MAXIMAL FORKLIFT (ZHEJI | C11: MXML
A12: F0011 | B12: TVH FORKLIFT PARTS NV | C12: TVH
... A75: F9999 | B75: OTRAS MARCAS | C75: OTRO

Sheet Diccionario Filiales
A1: Sociedad/es | B1: Nombre Sociedad
A2: VC00 | B2: Tattersall Maquinarias
A3: VD00 | B3: Tattersall Multimaq
A4: VE00, VC00 | B4: Tattersall Industrial y Maquinarias

Sheet Diccionario Marcas
A1: Marca | B1: Descripción Marca
A2: 010 | B2: BASHAN
A3: 020 | B3: ASILE MASTER
A4: 030 | B4: COMBILIFT
A5: 040 | B5: CUMMINS
A6: 050 | B6: D&P
A7: 060 | B7: DONGFENG
A8: 070 | B8: DRESSTA
A9: 080 | B9: FAW
A10: 090 | B10: HIDROMEK
A11: 100 | B11: HYSTER
A12: 110 | B12: INTERNATIONAL
... A30: 290 | B30: LIFAN AUTO

Sheet Diccionario GrupoImputacion
A1: codigo | B1: descripcion Grupo
A2: 53 | B2: Unidad Usada
